#VRML_SIM R2023b utf8

EXTERNPROTO "https://raw.githubusercontent.com/cyberbotics/webots/R2023b/projects/objects/backgrounds/protos/TexturedBackground.proto"
EXTERNPROTO "https://raw.githubusercontent.com/cyberbotics/webots/R2023b/projects/objects/backgrounds/protos/TexturedBackgroundLight.proto"
EXTERNPROTO "https://raw.githubusercontent.com/cyberbotics/webots/R2023b/projects/objects/robotstadium/protos/RobotstadiumSoccerField.proto"

WorldInfo {
}
Viewpoint {
  orientation -0.23780874464832374 0.3832213746890174 0.8925179992304064 1.2151171594889238
  position -1.0551905516851936 -2.853848452504879 2.312124577271217
}
TexturedBackground {
}
TexturedBackgroundLight {
}
RobotstadiumSoccerField {
}
Robot {
  translation 0 0 0.53
  rotation 0 0 1 -1.5707953071795862
  children [
    Shape {
      appearance DEF peito_material PBRAppearance {
        baseColor 0.68388 0.701788 0.706749
        roughness 1
        metalness 0
      }
      geometry DEF peito_visual Mesh {
        url [
          "/home/llagoeiro/Desktop/IC/IC-Prometheus-Webots/webots_prometheus/protos/peito_visual.stl"
        ]
      }
    }
    HingeJoint {
      jointParameters HingeJointParameters {
        position 2.0384630186792005e-06
        anchor -0.083213 0.070969 0.149205
      }
      device [
        RotationalMotor {
          name "ombro_direito_3"
          maxVelocity 6
        }
        PositionSensor {
          name "ombro_direito_3_sensor"
        }
      ]
      endPoint Solid {
        translation -0.083213 0.070969 0.149205
        rotation 0.5773506614916631 0.5773494845848208 0.5773506614915935 2.0943961769075723
        children [
          Shape {
            appearance DEF ombro_material PBRAppearance {
              baseColor 0.596078 0.666667 0.686275
              roughness 1
              metalness 0
            }
            geometry DEF ombro_visual Mesh {
              url [
                "/home/llagoeiro/Desktop/IC/IC-Prometheus-Webots/webots_prometheus/protos/ombro_visual.stl"
              ]
            }
          }
          HingeJoint {
            jointParameters HingeJointParameters {
              position 1.1427359191153157e-06
              axis -1 0 0
              anchor -0.02475 0 -0.042
            }
            device [
              RotationalMotor {
                name "ombro_direito_1"
                maxVelocity 6
              }
              PositionSensor {
                name "ombro_direito_1_sensor"
              }
            ]
            endPoint Solid {
              translation -0.02475 0 -0.042
              rotation -5.713681462776971e-07 -0.9999999999996734 5.713679595575334e-07 1.5707960000003263
              children [
                Shape {
                  appearance DEF braco_material PBRAppearance {
                    baseColor 0.593536 0.669368 0.676264
                    roughness 1
                    metalness 0
                  }
                  geometry DEF braco_visual Mesh {
                    url [
                      "/home/llagoeiro/Desktop/IC/IC-Prometheus-Webots/webots_prometheus/protos/braco_visual.stl"
                    ]
                  }
                }
                HingeJoint {
                  jointParameters HingeJointParameters {
                    position -5.59753423041915e-07
                    axis -1 0 0
                    anchor -0.0245 -0.141 -0.0245
                  }
                  device [
                    RotationalMotor {
                      name "cotovelo_direito_5"
                      maxVelocity 6
                    }
                    PositionSensor {
                      name "cotovelo_direito_5_sensor"
                    }
                  ]
                  endPoint Solid {
                    translation -0.0245 -0.141 -0.0245
                    rotation 2.798768029832389e-07 -0.9999999999999216 -2.7987671152094297e-07 1.5707960000000782
                    children [
                      Shape {
                        appearance DEF mao_material PBRAppearance {
                          baseColor 0.611617 0.675033 0.692649
                          roughness 1
                          metalness 0
                        }
                        geometry DEF mao_visual Mesh {
                          url [
                            "/home/llagoeiro/Desktop/IC/IC-Prometheus-Webots/webots_prometheus/protos/mao_visual.stl"
                          ]
                        }
                      }
                    ]
                    name "mao"
                    boundingObject Group {
                      children [
                        Pose {
                          translation 0.022 -0.052 -0.0435
                          rotation -0.7071067811865476 0.7071067811865476 0 3.141593
                          children [
                            DEF mao Mesh {
                              url [
                                "/home/llagoeiro/Desktop/IC/IC-Prometheus-Webots/webots_prometheus/protos/mao.stl"
                              ]
                            }
                          ]
                        }
                        Pose {
                          translation -0.01875 -0.001 -0.0115
                          rotation 0 0 -1 1.570796
                          children [
                            DEF apoio_mao Mesh {
                              url [
                                "/home/llagoeiro/Desktop/IC/IC-Prometheus-Webots/webots_prometheus/protos/apoio_mao.stl"
                              ]
                            }
                          ]
                        }
                        Pose {
                          translation 0 0 -0.0245
                          children [
                            DEF xm_540 Mesh {
                              url [
                                "/home/llagoeiro/Desktop/IC/IC-Prometheus-Webots/webots_prometheus/protos/xm_540.stl"
                              ]
                            }
                          ]
                        }
                        Pose {
                          translation 0.01675 -0.001 -0.0115
                          rotation 0 0 -1 1.570796
                          children [
                            USE apoio_mao
                          ]
                        }
                      ]
                    }
                    physics Physics {
                      density -1
                      mass 0.73912
                      centerOfMass [
                        0 -0.024983 -0.023852
                      ]
                      inertiaMatrix [
                        0.001162408 0.0002045212 0.001129553
                        -1.064272e-12 2.598116e-12 -5.966537e-06
                      ]
                    }
                    linearVelocity 3.4939984144494284e-06 -1.8853479460636999e-06 -9.256939663050988e-07
                    angularVelocity -1.139236343396526e-05 -2.5879236935774874e-05 1.880757418904122e-10
                  }
                }
              ]
              name "braco"
              boundingObject Group {
                children [
                  Pose {
                    translation 0.0245 -0.041 -0.0365
                    rotation 0 -1 0 1.570796
                    children [
                      DEF junta_ombro Mesh {
                        url [
                          "/home/llagoeiro/Desktop/IC/IC-Prometheus-Webots/webots_prometheus/protos/junta_ombro.stl"
                        ]
                      }
                    ]
                  }
                  Pose {
                    translation 0.0265 -0.156 -0.0245
                    rotation 0 -1 0 1.570796
                    children [
                      DEF braco Mesh {
                        url [
                          "/home/llagoeiro/Desktop/IC/IC-Prometheus-Webots/webots_prometheus/protos/braco.stl"
                        ]
                      }
                    ]
                  }
                  Pose {
                    translation -0.0265 -0.156 -0.0245
                    rotation 0 1 0 1.570796
                    children [
                      USE braco
                    ]
                  }
                  Pose {
                    translation -0.01675 -0.041 -0.0365
                    rotation 0 -1 0 1.570796
                    children [
                      USE junta_ombro
                    ]
                  }
                  Pose {
                    translation 0 0 -0.0245
                    children [
                      USE xm_540
                    ]
                  }
                ]
              }
              physics Physics {
                density -1
                mass 0.744906
                centerOfMass [
                  0 -0.01797 -0.023652
                ]
                inertiaMatrix [
                  0.000479899 0.0002159248 0.0004641409
                  9.2006e-14 6.52732e-11 -1.882433e-06
                ]
              }
              linearVelocity 3.5646510547806385e-07 -2.0052551451330455e-07 -7.564473723924854e-07
              angularVelocity -1.1396704904094147e-05 -2.0276125289487905e-05 2.603182994041893e-10
            }
          }
        ]
        name "ombro"
        boundingObject Pose {
          rotation 0.5773502691896258 0.5773502691896258 -0.5773502691896258 2.094395
          children [
            DEF ombro Mesh {
              url [
                "/home/llagoeiro/Desktop/IC/IC-Prometheus-Webots/webots_prometheus/protos/ombro.stl"
              ]
            }
          ]
        }
        physics Physics {
          density -1
          mass 0.059819
          centerOfMass [
            0 0 -0.013873
          ]
          inertiaMatrix [
            1.606092e-05 4.170447e-05 3.516622e-05
            -1.30586e-41 8.830912e-37 -2.825173e-10
          ]
        }
        linearVelocity -3.94735527117863e-09 2.136185935017838e-09 -3.741249785439328e-07
        angularVelocity -1.5046800296399653e-08 -2.028541126674193e-05 2.0759616941820697e-10
      }
    }
    HingeJoint {
      jointParameters HingeJointParameters {
        position 2.0336411503457032e-06
        axis -1 0 0
        anchor 0.087787 0.070969 0.149205
      }
      device [
        RotationalMotor {
          name "ombro_esquerdo_4"
          maxVelocity 6
        }
        PositionSensor {
          name "ombro_esquerdo_4_sensor"
        }
      ]
      endPoint Solid {
        translation 0.087787 0.070969 0.149205
        rotation -0.577350660563696 -0.5773494864407589 0.5773506605636265 2.0943961741236636
        children [
          Shape {
            appearance DEF ombro_2_material PBRAppearance {
              baseColor 0.596078 0.666667 0.686275
              roughness 1
              metalness 0
            }
            geometry DEF ombro_2_visual Mesh {
              url [
                "/home/llagoeiro/Desktop/IC/IC-Prometheus-Webots/webots_prometheus/protos/ombro_2_visual.stl"
              ]
            }
          }
          HingeJoint {
            jointParameters HingeJointParameters {
              position -1.1427229598126587e-06
              axis -1 0 0
              anchor -0.02675 0 -0.042
            }
            device [
              RotationalMotor {
                name "ombro_esquerdo_2"
                maxVelocity 6
              }
              PositionSensor {
                name "ombro_esquerdo_2_sensor"
              }
            ]
            endPoint Solid {
              translation -0.02675 0 -0.042
              rotation -0.7071067811865394 -4.0401357695052945e-07 0.7071067811864404 3.141592191972846
              children [
                Shape {
                  appearance DEF braco_2_material PBRAppearance {
                    baseColor 0.593536 0.669368 0.676264
                    roughness 1
                    metalness 0
                  }
                  geometry DEF braco_2_visual Mesh {
                    url [
                      "/home/llagoeiro/Desktop/IC/IC-Prometheus-Webots/webots_prometheus/protos/braco_2_visual.stl"
                    ]
                  }
                }
                HingeJoint {
                  jointParameters HingeJointParameters {
                    position 5.597538553454543e-07
                    anchor 0.0245 -0.141 -0.0245
                  }
                  device [
                    RotationalMotor {
                      name "cotovelo_esquerdo_6"
                      maxVelocity 6
                    }
                    PositionSensor {
                      name "cotovelo_esquerdo_6_sensor"
                    }
                  ]
                  endPoint Solid {
                    translation 0.0245 -0.141 -0.0245
                    rotation 2.798770191350791e-07 0.9999999999999216 2.798769276727125e-07 1.5707960000000782
                    children [
                      Shape {
                        appearance DEF mao_2_material PBRAppearance {
                          baseColor 0.611617 0.675033 0.692649
                          roughness 1
                          metalness 0
                        }
                        geometry DEF mao_2_visual Mesh {
                          url [
                            "/home/llagoeiro/Desktop/IC/IC-Prometheus-Webots/webots_prometheus/protos/mao_2_visual.stl"
                          ]
                        }
                      }
                    ]
                    name "mao_2"
                    boundingObject Group {
                      children [
                        Pose {
                          translation -0.01875 -0.001 -0.0115
                          rotation 0 0 -1 1.570796
                          children [
                            USE apoio_mao
                          ]
                        }
                        Pose {
                          translation 0 0 -0.0245
                          children [
                            USE xm_540
                          ]
                        }
                        Pose {
                          translation 0.022 -0.052 -0.0435
                          rotation 0.7071067811865476 -0.7071067811865476 0 3.141593
                          children [
                            USE mao
                          ]
                        }
                        Pose {
                          translation 0.01675 -0.001 -0.0115
                          rotation 0 0 -1 1.570796
                          children [
                            USE apoio_mao
                          ]
                        }
                      ]
                    }
                    physics Physics {
                      density -1
                      mass 0.73912
                      centerOfMass [
                        0 -0.024983 -0.023852
                      ]
                      inertiaMatrix [
                        0.001162408 0.0002045212 0.001129553
                        -1.064268e-12 2.598116e-12 -5.966537e-06
                      ]
                    }
                    linearVelocity -3.054342987123179e-06 1.8853753097268634e-06 -8.774894267351031e-07
                    angularVelocity 1.1392539979550134e-05 1.3706206427560372e-05 6.419053332989543e-11
                  }
                }
              ]
              name "braco_2"
              boundingObject Group {
                children [
                  Pose {
                    translation 0.0245 -0.041 -0.0365
                    rotation 0 -1 0 1.570796
                    children [
                      USE junta_ombro
                    ]
                  }
                  Pose {
                    translation 0 0 -0.0245
                    children [
                      USE xm_540
                    ]
                  }
                  Pose {
                    translation -0.01675 -0.041 -0.0365
                    rotation 0 -1 0 1.570796
                    children [
                      USE junta_ombro
                    ]
                  }
                  Pose {
                    translation 0.0265 -0.156 -0.0245
                    rotation 0 -1 0 1.570796
                    children [
                      USE braco
                    ]
                  }
                  Pose {
                    translation -0.0265 -0.156 -0.0245
                    rotation 0 1 0 1.570796
                    children [
                      USE braco
                    ]
                  }
                ]
              }
              physics Physics {
                density -1
                mass 0.744906
                centerOfMass [
                  0 -0.01797 -0.023652
                ]
                inertiaMatrix [
                  0.000479899 0.0002159248 0.0004641409
                  9.200554e-14 6.52732e-11 -1.882433e-06
                ]
              }
              linearVelocity -3.3959470946374405e-07 2.0052779500716778e-07 -6.746286792612309e-07
              angularVelocity 1.1396870095593115e-05 1.9309532497447196e-05 1.5324650985771214e-10
            }
          }
        ]
        name "ombro_2"
        boundingObject Pose {
          rotation 0.5773502691896258 0.5773502691896258 -0.5773502691896258 2.094395
          children [
            USE ombro
          ]
        }
        physics Physics {
          density -1
          mass 0.059819
          centerOfMass [
            0 0 -0.013873
          ]
          inertiaMatrix [
            1.606092e-05 4.170447e-05 3.516622e-05
            1.828204e-41 -1.236328e-36 -2.825173e-10
          ]
        }
        linearVelocity 3.6978048156408274e-09 -2.1361862942605133e-09 -3.74265216510298e-07
        angularVelocity 1.505397135714585e-08 1.930145340905583e-05 2.0073114207794462e-10
      }
    }
    HingeJoint {
      jointParameters HingeJointParameters {
        position 7.179681891803513e-08
        axis 0 0 -1
        anchor 0.002498 0.048469 0.167955
      }
      device [
        RotationalMotor {
          name "pescoço_19"
          maxVelocity 6
        }
        PositionSensor {
          name "pescoço_19_sensor"
        }
      ]
      endPoint Solid {
        translation 0.002498 0.048469 0.167955
        rotation -0.7071067558025383 0.7071068065705559 6.2177877190031165e-15 3.141593
        children [
          Shape {
            appearance DEF pescoco_material PBRAppearance {
              baseColor 0.144352 0.144352 0.144352
              roughness 1
              metalness 0
            }
            geometry DEF pescoco_visual Mesh {
              url [
                "/home/llagoeiro/Desktop/IC/IC-Prometheus-Webots/webots_prometheus/protos/pescoco_visual.stl"
              ]
            }
          }
          HingeJoint {
            jointParameters HingeJointParameters {
              position -2.6059790148025286e-07
              axis 0 1 0
              anchor -0.00075 0.019 -0.06075
            }
            device [
              RotationalMotor {
                name "pescoço_20"
                maxVelocity 6
              }
              PositionSensor {
                name "pescoço_20_sensor"
              }
            ]
            endPoint Solid {
              translation -0.00075 0.019 -0.06075
              rotation -0.999999999999983 -1.3029899332116405e-07 -1.3029895074012495e-07 1.570796000000017
              children [
                Shape {
                  appearance DEF capacete_material PBRAppearance {
                    baseColor 0.787536 0.812047 0.913591
                    roughness 1
                    metalness 0
                  }
                  geometry DEF capacete_visual Mesh {
                    url [
                      "/home/llagoeiro/Desktop/IC/IC-Prometheus-Webots/webots_prometheus/protos/capacete_visual.stl"
                    ]
                  }
                }
              ]
              name "capacete"
              boundingObject Group {
                children [
                  Pose {
                    translation 0.019657 0.027657 -0.0695
                    rotation 0 -1 0 1.570796
                    children [
                      DEF webcam Mesh {
                        url [
                          "/home/llagoeiro/Desktop/IC/IC-Prometheus-Webots/webots_prometheus/protos/webcam.stl"
                        ]
                      }
                    ]
                  }
                  Pose {
                    translation 0.006657 0.005657 -0.0005
                    children [
                      DEF capacete Mesh {
                        url [
                          "/home/llagoeiro/Desktop/IC/IC-Prometheus-Webots/webots_prometheus/protos/capacete.stl"
                        ]
                      }
                    ]
                  }
                  Pose {
                    translation 0.029657 0.057657 -0.0405
                    rotation -1 0 0 3.141593
                    children [
                      DEF tampa_capacete Mesh {
                        url [
                          "/home/llagoeiro/Desktop/IC/IC-Prometheus-Webots/webots_prometheus/protos/tampa_capacete.stl"
                        ]
                      }
                    ]
                  }
                ]
              }
              physics Physics {
                density -1
                mass 0.413474
                centerOfMass [
                  0.006937 0.041371 -0.019493
                ]
                inertiaMatrix [
                  0.0002893456 0.0002819696 5.738237e-05
                  4.382665e-07 5.023613e-08 1.739618e-08
                ]
              }
              linearVelocity -1.2919173760928828e-07 4.3618530184565194e-09 -3.181162383061707e-07
              angularVelocity 1.9486542881386333e-09 -3.116235787181979e-06 -7.187031025623257e-07
            }
          }
        ]
        name "pescoco"
        boundingObject Group {
          children [
            Pose {
              translation -0.00075 0 -0.06075
              rotation -1 0 0 1.570796
              children [
                DEF xm_430 Mesh {
                  url [
                    "/home/llagoeiro/Desktop/IC/IC-Prometheus-Webots/webots_prometheus/protos/xm_430.stl"
                  ]
                }
              ]
            }
            Pose {
              translation -0.015 0.019 0
              rotation -1 0 0 1.570796
              children [
                DEF pescoco Mesh {
                  url [
                    "/home/llagoeiro/Desktop/IC/IC-Prometheus-Webots/webots_prometheus/protos/pescoco.stl"
                  ]
                }
              ]
            }
          ]
        }
        physics Physics {
          density -1
          mass 0.394812
          centerOfMass [
            -0.000753 0.000625 -0.045915
          ]
          inertiaMatrix [
            0.000160923 0.000138921 7.366453e-05
            -6.590875e-10 4.735301e-08 8.18567e-07
          ]
        }
        linearVelocity 4.828198720890692e-10 -5.42948238469784e-10 -1.9614514875159896e-07
        angularVelocity -1.0130032299358021e-11 -5.42080728618378e-10 -7.18703896915762e-07
      }
    }
    HingeJoint {
      jointParameters HingeJointParameters {
        position -3.114791478930502e-06
        axis 0 0 1
        anchor -0.040713 0.057719 -0.046045
      }
      device [
        RotationalMotor {
          name "junta_peito_pernaD_7"
          maxVelocity 6
        }
        PositionSensor {
          name "junta_peito_pernaD_7_sensor"
        }
      ]
      endPoint Solid {
        translation -0.040713 0.057719 -0.046045
        rotation 0 0 1 1.5707928852085211
        children [
          Shape {
            appearance DEF conector_calcanhar_material PBRAppearance {
              baseColor 0.6 0.6 0.6
              roughness 1
              metalness 0
            }
            geometry DEF conector_calcanhar_visual Mesh {
              url [
                "/home/llagoeiro/Desktop/IC/IC-Prometheus-Webots/webots_prometheus/protos/conector_calcanhar_visual.stl"
              ]
            }
          }
          HingeJoint {
            jointParameters HingeJointParameters {
              position -7.916080816262733e-06
              anchor 0.0787 0 -0.033
            }
            device [
              RotationalMotor {
                name "perna_direita_9"
                maxVelocity 6
              }
              PositionSensor {
                name "perna_direita_9_sensor"
              }
            ]
            endPoint Solid {
              translation 0.0787 0 -0.033
              rotation 0.5773487457329524 0.5773533160906427 0.5773487457332226 2.0943904296546396
              children [
                Shape {
                  appearance DEF motores_duplos_material PBRAppearance {
                    baseColor 0.64258 0.703747 0.720738
                    roughness 1
                    metalness 0
                  }
                  geometry DEF motores_duplos_visual Mesh {
                    url [
                      "/home/llagoeiro/Desktop/IC/IC-Prometheus-Webots/webots_prometheus/protos/motores_duplos_visual.stl"
                    ]
                  }
                }
                HingeJoint {
                  jointParameters HingeJointParameters {
                    position -2.239000349154185e-06
                    axis -1 0 0
                    anchor 0.025 -0.031 -0.0741
                  }
                  device [
                    RotationalMotor {
                      name "coxa_direita_11"
                      maxVelocity 6
                    }
                    PositionSensor {
                      name "coxa_direita_11_sensor"
                    }
                  ]
                  endPoint Solid {
                    translation 0.025 -0.031 -0.0741
                    rotation 1.1195005404231608e-06 -0.9999999999987468 -1.1195001745761571e-06 1.5707960000012533
                    children [
                      Shape {
                        appearance DEF joelho_material PBRAppearance {
                          baseColor 0.596078 0.666667 0.686275
                          roughness 1
                          metalness 0
                        }
                        geometry DEF joelho_visual Mesh {
                          url [
                            "/home/llagoeiro/Desktop/IC/IC-Prometheus-Webots/webots_prometheus/protos/joelho_visual.stl"
                          ]
                        }
                      }
                      HingeJoint {
                        jointParameters HingeJointParameters {
                          position -1.693871542585157e-06
                          axis 0 0 1
                          anchor 0 -0.1305 0.0005
                        }
                        device [
                          RotationalMotor {
                            name "joelho_direito_13"
                            maxVelocity 6
                          }
                          PositionSensor {
                            name "joelho_direito_13_sensor"
                          }
                        ]
                        endPoint Solid {
                          translation 0 -0.1305 0.0005
                          rotation 0 0 -0.9999999999999999 1.6937580392817553e-06
                          children [
                            Shape {
                              appearance DEF canela_material PBRAppearance {
                                baseColor 0.596078 0.666667 0.686275
                                roughness 1
                                metalness 0
                              }
                              geometry DEF canela_visual Mesh {
                                url [
                                  "/home/llagoeiro/Desktop/IC/IC-Prometheus-Webots/webots_prometheus/protos/canela_visual.stl"
                                ]
                              }
                            }
                            HingeJoint {
                              jointParameters HingeJointParameters {
                                position -1.4375673379336088e-06
                                axis 0 0 1
                                anchor 0 -0.13 0.05
                              }
                              device [
                                RotationalMotor {
                                  name "pe_direito_15"
                                  maxVelocity 6
                                }
                                PositionSensor {
                                  name "pe_direito_15_sensor"
                                }
                              ]
                              endPoint Solid {
                                translation 0 -0.13 0.05
                                rotation 0 0 -0.9999999999999999 1.4376338833800073e-06
                                children [
                                  Shape {
                                    appearance DEF motores_duplos_2_material PBRAppearance {
                                      baseColor 0.64258 0.703747 0.720738
                                      roughness 1
                                      metalness 0
                                    }
                                    geometry DEF motores_duplos_2_visual Mesh {
                                      url [
                                        "/home/llagoeiro/Desktop/IC/IC-Prometheus-Webots/webots_prometheus/protos/motores_duplos_2_visual.stl"
                                      ]
                                    }
                                  }
                                  HingeJoint {
                                    jointParameters HingeJointParameters {
                                      position -5.597861250095093e-07
                                      axis -1 0 0
                                      anchor 0.0741 -0.031 -0.025
                                    }
                                    device [
                                      RotationalMotor {
                                        name "pe_direito_17"
                                        maxVelocity 6
                                      }
                                      PositionSensor {
                                        name "pe_direito_17_sensor"
                                      }
                                    ]
                                    endPoint Solid {
                                      translation 0.0741 -0.031 -0.025
                                      rotation -0.5773501614586929 -0.5773504846514121 0.577350161458712 2.0943946768073602
                                      children [
                                        Shape {
                                          appearance DEF pe_direito_material PBRAppearance {
                                            baseColor 0.598579 0.624151 0.631254
                                            roughness 1
                                            metalness 0
                                          }
                                          geometry DEF pe_direito_visual Mesh {
                                            url [
                                              "/home/llagoeiro/Desktop/IC/IC-Prometheus-Webots/webots_prometheus/protos/pe_direito_visual.stl"
                                            ]
                                          }
                                        }
                                      ]
                                      name "pe_direito"
                                      boundingObject Group {
                                        children [
                                          Pose {
                                            translation -0.033 -0.0202 0.0575
                                            rotation 0.5773502691896258 0.5773502691896258 -0.5773502691896258 2.094395
                                            children [
                                              DEF conector_calcanhar Mesh {
                                                url [
                                                  "/home/llagoeiro/Desktop/IC/IC-Prometheus-Webots/webots_prometheus/protos/conector_calcanhar.stl"
                                                ]
                                              }
                                            ]
                                          }
                                          Pose {
                                            translation -0.033 0.0638 0.201
                                            rotation -0.7071067811865476 0 0.7071067811865476 3.141593
                                            children [
                                              DEF pe Mesh {
                                                url [
                                                  "/home/llagoeiro/Desktop/IC/IC-Prometheus-Webots/webots_prometheus/protos/pe.stl"
                                                ]
                                              }
                                            ]
                                          }
                                        ]
                                      }
                                      physics Physics {
                                        density -1
                                        mass 0.239194
                                        centerOfMass [
                                          -0.029588 0.003976 0.071403
                                        ]
                                        inertiaMatrix [
                                          0.0008333298 0.0007303742 0.0001321754
                                          4.672117e-06 2.009087e-05 -3.23004e-05
                                        ]
                                      }
                                      linearVelocity 1.29127449198845e-06 -2.7541463808388037e-05 -4.032360510268695e-06
                                      angularVelocity -7.39287117699164e-05 -1.0472270399043587e-06 -3.1177187827428154e-05
                                    }
                                  }
                                ]
                                name "motores_duplos_2"
                                boundingObject Group {
                                  children [
                                    Pose {
                                      translation 0 0 -0.0245
                                      children [
                                        USE xm_540
                                      ]
                                    }
                                    Pose {
                                      translation -0.035 -0.031 -0.02443
                                      rotation -0.5773502691896258 0.5773502691896258 0.5773502691896258 2.094395
                                      children [
                                        DEF rolamento Mesh {
                                          url [
                                            "/home/llagoeiro/Desktop/IC/IC-Prometheus-Webots/webots_prometheus/protos/rolamento.stl"
                                          ]
                                        }
                                      ]
                                    }
                                    Pose {
                                      translation -0.035 -0.031 -0.02443
                                      rotation -0.5773502691896258 0.5773502691896258 0.5773502691896258 2.094395
                                      children [
                                        DEF peca_rolamento Mesh {
                                          url [
                                            "/home/llagoeiro/Desktop/IC/IC-Prometheus-Webots/webots_prometheus/protos/peca_rolamento.stl"
                                          ]
                                        }
                                      ]
                                    }
                                    Pose {
                                      translation 0.0496 -0.031 -0.025
                                      rotation -0.7071067811865476 0 -0.7071067811865476 3.141593
                                      children [
                                        USE xm_540
                                      ]
                                    }
                                    Pose {
                                      translation -0.0297 0.0098 0
                                      rotation -0.5773502691896258 0.5773502691896258 0.5773502691896258 2.094395
                                      children [
                                        DEF rolamento_motor Mesh {
                                          url [
                                            "/home/llagoeiro/Desktop/IC/IC-Prometheus-Webots/webots_prometheus/protos/rolamento_motor.stl"
                                          ]
                                        }
                                      ]
                                    }
                                    Pose {
                                      translation 0.01675 -0.04475 -0.0025
                                      rotation 0 1 0 1.570796
                                      children [
                                        DEF junta_motores Mesh {
                                          url [
                                            "/home/llagoeiro/Desktop/IC/IC-Prometheus-Webots/webots_prometheus/protos/junta_motores.stl"
                                          ]
                                        }
                                      ]
                                    }
                                  ]
                                }
                                physics Physics {
                                  density -1
                                  mass 1.532598
                                  centerOfMass [
                                    0.024014 -0.015763 -0.024413
                                  ]
                                  inertiaMatrix [
                                    0.0006473235 0.001393334 0.001610811
                                    -9.715833e-06 2.01501e-05 -1.585238e-06
                                  ]
                                }
                                linearVelocity 1.104034892307422e-06 -2.4822673267846104e-05 -3.6121857088692444e-06
                                angularVelocity -7.909741525240514e-05 -1.0432315672404297e-06 -3.117659431675849e-05
                              }
                            }
                          ]
                          name "canela"
                          boundingObject Pose {
                            translation -0.01675 -0.1465 -0.002
                            rotation -0.5773502691896258 -0.5773502691896258 -0.5773502691896258 2.094395
                            children [
                              DEF canela Mesh {
                                url [
                                  "/home/llagoeiro/Desktop/IC/IC-Prometheus-Webots/webots_prometheus/protos/canela.stl"
                                ]
                              }
                            ]
                          }
                          physics Physics {
                            density -1
                            mass 0.192578
                            centerOfMass [
                              0 -0.065 0.025
                            ]
                            inertiaMatrix [
                              0.0004464264 0.0001319352 0.0003451714
                              4.235297e-27 1.095901e-13 -1.739556e-11
                            ]
                          }
                          linearVelocity 1.5603613620897403e-06 -1.7748431706562364e-05 -3.2572158622022495e-06
                          angularVelocity -7.908821973533054e-05 6.814246056610003e-06 -3.117822601812848e-05
                        }
                      }
                    ]
                    name "joelho"
                    boundingObject Group {
                      children [
                        Pose {
                          translation 0 -0.1305 0.025
                          rotation -1 0 0 3.141593
                          children [
                            USE xm_540
                          ]
                        }
                        Pose {
                          translation -0.01675 -0.08575 0.052
                          rotation -1 0 0 1.570796
                          children [
                            DEF coxa Mesh {
                              url [
                                "/home/llagoeiro/Desktop/IC/IC-Prometheus-Webots/webots_prometheus/protos/coxa.stl"
                              ]
                            }
                          ]
                        }
                      ]
                    }
                    physics Physics {
                      density -1
                      mass 0.866918
                      centerOfMass [
                        0 -0.098997 0.024478
                      ]
                      inertiaMatrix [
                        0.001311283 0.0002860721 0.001180637
                        2.13929e-12 -2.577287e-12 -8.727699e-06
                      ]
                    }
                    linearVelocity 1.5461893139845939e-06 -1.0182214228317188e-05 -2.865047495517102e-06
                    angularVelocity -7.910979492105393e-05 -1.5915851611301744e-05 -3.1179383314669327e-05
                  }
                }
              ]
              name "motores_duplos"
              boundingObject Group {
                children [
                  Pose {
                    translation 0 0 -0.0245
                    children [
                      USE xm_540
                    ]
                  }
                  Pose {
                    translation 0.00057 0 -0.1091
                    rotation 0 0.7071067811865476 -0.7071067811865476 3.141593
                    children [
                      USE peca_rolamento
                    ]
                  }
                  Pose {
                    translation 0.025 -0.0408 -0.1038
                    rotation 0 0.7071067811865476 -0.7071067811865476 3.141593
                    children [
                      USE rolamento_motor
                    ]
                  }
                  Pose {
                    translation 0.00057 0 -0.1091
                    rotation 0 0.7071067811865476 -0.7071067811865476 3.141593
                    children [
                      USE rolamento
                    ]
                  }
                  Pose {
                    translation 0.0225 0.01375 -0.05735
                    rotation 0 0 -1 3.141593
                    children [
                      USE junta_motores
                    ]
                  }
                  Pose {
                    translation 0.0005 -0.031 -0.0741
                    rotation -0.7071067811865476 0 -0.7071067811865476 3.141593
                    children [
                      USE xm_540
                    ]
                  }
                ]
              }
              physics Physics {
                density -1
                mass 1.532598
                centerOfMass [
                  0.000586 -0.015237 -0.050086
                ]
                inertiaMatrix [
                  0.001610811 0.001393334 0.0006473235
                  1.585238e-06 2.01501e-05 9.715833e-06
                ]
              }
              linearVelocity -1.2656540686594092e-08 -1.9307051914516505e-06 -2.187610451969085e-06
              angularVelocity -7.914673130518597e-05 -2.7310753606454768e-08 -3.118038630745168e-05
            }
          }
        ]
        name "conector_calcanhar"
        boundingObject Pose {
          translation 0.0212 0.0202 0
          rotation -1 0 0 1.570796
          children [
            USE conector_calcanhar
          ]
        }
        physics Physics {
          density -1
          mass 0.152543
          centerOfMass [
            0.024705 0 -0.006202
          ]
          inertiaMatrix [
            3.117182e-05 0.0002757415 0.0002843804
            3.806312e-13 -3.620273e-07 -2.157674e-13
          ]
        }
        linearVelocity -1.5377540584997488e-08 -6.868233713642469e-07 -1.087972861678033e-06
        angularVelocity 2.4868632703223334e-08 2.8410833616542377e-08 -3.117610268687528e-05
      }
    }
    HingeJoint {
      jointParameters HingeJointParameters {
        position -3.1148745633566036e-06
        axis 0 0 1
        anchor 0.045287 0.057719 -0.046045
      }
      device [
        RotationalMotor {
          name "junta_peito_pernaE_8"
          maxVelocity 6
        }
        PositionSensor {
          name "junta_peito_pernaE_8_sensor"
        }
      ]
      endPoint Solid {
        translation 0.045287 0.057719 -0.046045
        rotation 0 0 1 1.5707928851254365
        children [
          Shape {
            appearance DEF conector_calcanhar_2_material PBRAppearance {
              baseColor 0.6 0.6 0.6
              roughness 1
              metalness 0
            }
            geometry DEF conector_calcanhar_2_visual Mesh {
              url [
                "/home/llagoeiro/Desktop/IC/IC-Prometheus-Webots/webots_prometheus/protos/conector_calcanhar_2_visual.stl"
              ]
            }
          }
          HingeJoint {
            jointParameters HingeJointParameters {
              position 7.916019522125482e-06
              anchor 0.0787 0 -0.033
            }
            device [
              RotationalMotor {
                name "perna_esquerda_10"
                maxVelocity 6
              }
              PositionSensor {
                name "perna_esquerda_10_sensor"
              }
            ]
            endPoint Solid {
              translation 0.0787 0 -0.033
              rotation 0.5773517926224433 0.5773472223122009 0.5773517926221732 2.094399570322032
              children [
                Shape {
                  appearance DEF motores_duplos_3_material PBRAppearance {
                    baseColor 0.64258 0.703747 0.720738
                    roughness 1
                    metalness 0
                  }
                  geometry DEF motores_duplos_3_visual Mesh {
                    url [
                      "/home/llagoeiro/Desktop/IC/IC-Prometheus-Webots/webots_prometheus/protos/motores_duplos_3_visual.stl"
                    ]
                  }
                }
                HingeJoint {
                  jointParameters HingeJointParameters {
                    position -2.2628511141385186e-06
                    axis -1 0 0
                    anchor 0.025 -0.031 -0.0741
                  }
                  device [
                    RotationalMotor {
                      name "coxa_esquerda_12"
                      maxVelocity 6
                    }
                    PositionSensor {
                      name "coxa_esquerda_12_sensor"
                    }
                  ]
                  endPoint Solid {
                    translation 0.025 -0.031 -0.0741
                    rotation 0.7071067811862234 8.000386838116365e-07 -0.7071067811864193 3.1415946000773673
                    children [
                      Shape {
                        appearance DEF joelho_2_material PBRAppearance {
                          baseColor 0.596078 0.666667 0.686275
                          roughness 1
                          metalness 0
                        }
                        geometry DEF joelho_2_visual Mesh {
                          url [
                            "/home/llagoeiro/Desktop/IC/IC-Prometheus-Webots/webots_prometheus/protos/joelho_2_visual.stl"
                          ]
                        }
                      }
                      HingeJoint {
                        jointParameters HingeJointParameters {
                          position -1.482374150237795e-06
                          axis 0 0 -1
                          anchor 0 0.1305 0.0495
                        }
                        device [
                          RotationalMotor {
                            name "joelho_esquerdo_14"
                            maxVelocity 6
                          }
                          PositionSensor {
                            name "joelho_esquerdo_14_sensor"
                          }
                        ]
                        endPoint Solid {
                          translation 0 0.1305 0.0495
                          rotation 7.411870751188297e-07 -0.9999999999997254 -1.2837738391777272e-13 3.141593
                          children [
                            Shape {
                              appearance DEF canela_2_material PBRAppearance {
                                baseColor 0.596078 0.666667 0.686275
                                roughness 1
                                metalness 0
                              }
                              geometry DEF canela_2_visual Mesh {
                                url [
                                  "/home/llagoeiro/Desktop/IC/IC-Prometheus-Webots/webots_prometheus/protos/canela_2_visual.stl"
                                ]
                              }
                            }
                            HingeJoint {
                              jointParameters HingeJointParameters {
                                position 1.3437812714959794e-06
                                axis 0 0 -1
                                anchor 0 0.13 0
                              }
                              device [
                                RotationalMotor {
                                  name "pe_esquerdo_16"
                                  maxVelocity 6
                                }
                                PositionSensor {
                                  name "pe_esquerdo_16_sensor"
                                }
                              ]
                              endPoint Solid {
                                translation 0 0.13 0
                                rotation -0.9999999999997744 6.718906357479393e-07 1.1637488697754313e-13 3.141593
                                children [
                                  Shape {
                                    appearance DEF motores_duplos_4_material PBRAppearance {
                                      baseColor 0.64258 0.703747 0.720738
                                      roughness 1
                                      metalness 0
                                    }
                                    geometry DEF motores_duplos_4_visual Mesh {
                                      url [
                                        "/home/llagoeiro/Desktop/IC/IC-Prometheus-Webots/webots_prometheus/protos/motores_duplos_4_visual.stl"
                                      ]
                                    }
                                  }
                                  HingeJoint {
                                    jointParameters HingeJointParameters {
                                      position 5.59785476065363e-07
                                      axis -1 0 0
                                      anchor 0.0741 -0.031 -0.025
                                    }
                                    device [
                                      RotationalMotor {
                                        name "pe_esquerdo_18"
                                        maxVelocity 6
                                      }
                                      PositionSensor {
                                        name "pe_esquerdo_18_sensor"
                                      }
                                    ]
                                    endPoint Solid {
                                      translation 0.0741 -0.031 -0.025
                                      rotation -0.5773503769203735 -0.5773500537280892 0.5773503769203544 2.0943953231923254
                                      children [
                                        Shape {
                                          appearance DEF pe_esquerdo_material PBRAppearance {
                                            baseColor 0.598579 0.624151 0.631254
                                            roughness 1
                                            metalness 0
                                          }
                                          geometry DEF pe_esquerdo_visual Mesh {
                                            url [
                                              "/home/llagoeiro/Desktop/IC/IC-Prometheus-Webots/webots_prometheus/protos/pe_esquerdo_visual.stl"
                                            ]
                                          }
                                        }
                                      ]
                                      name "pe_esquerdo"
                                      boundingObject Group {
                                        children [
                                          Pose {
                                            translation -0.036 -0.0638 0.201
                                            rotation 0 1 0 1.570796
                                            children [
                                              USE pe
                                            ]
                                          }
                                          Pose {
                                            translation -0.033 -0.0202 0.0575
                                            rotation 0.5773502691896258 0.5773502691896258 -0.5773502691896258 2.094395
                                            children [
                                              USE conector_calcanhar
                                            ]
                                          }
                                        ]
                                      }
                                      physics Physics {
                                        density -1
                                        mass 0.239194
                                        centerOfMass [
                                          -0.029588 -0.003976 0.071403
                                        ]
                                        inertiaMatrix [
                                          0.0008333298 0.0007303742 0.0001321754
                                          -4.672117e-06 2.009087e-05 3.23004e-05
                                        ]
                                      }
                                      linearVelocity 6.776643308450475e-06 2.712618131426647e-05 -3.953025244103197e-06
                                      angularVelocity 7.39470630015028e-05 -2.9681277094961738e-05 -3.117714119058257e-05
                                    }
                                  }
                                ]
                                name "motores_duplos_4"
                                boundingObject Group {
                                  children [
                                    Pose {
                                      translation 0.0496 -0.031 -0.025
                                      rotation -0.7071067811865476 0 -0.7071067811865476 3.141593
                                      children [
                                        USE xm_540
                                      ]
                                    }
                                    Pose {
                                      translation -0.035 -0.031 -0.02443
                                      rotation -0.5773502691896258 0.5773502691896258 0.5773502691896258 2.094395
                                      children [
                                        USE rolamento
                                      ]
                                    }
                                    Pose {
                                      translation 0 0 -0.0245
                                      children [
                                        USE xm_540
                                      ]
                                    }
                                    Pose {
                                      translation -0.0297 0.0098 0
                                      rotation -0.5773502691896258 0.5773502691896258 0.5773502691896258 2.094395
                                      children [
                                        USE rolamento_motor
                                      ]
                                    }
                                    Pose {
                                      translation 0.01675 -0.04475 -0.0025
                                      rotation 0 1 0 1.570796
                                      children [
                                        USE junta_motores
                                      ]
                                    }
                                    Pose {
                                      translation -0.035 -0.031 -0.02443
                                      rotation -0.5773502691896258 0.5773502691896258 0.5773502691896258 2.094395
                                      children [
                                        USE peca_rolamento
                                      ]
                                    }
                                  ]
                                }
                                physics Physics {
                                  density -1
                                  mass 1.532598
                                  centerOfMass [
                                    0.024014 -0.015763 -0.024413
                                  ]
                                  inertiaMatrix [
                                    0.0006473235 0.001393334 0.001610811
                                    -9.715833e-06 2.01501e-05 -1.585238e-06
                                  ]
                                }
                                linearVelocity 5.554297193363224e-06 2.3077236312132598e-05 -3.0152627866185827e-06
                                angularVelocity 7.911574984454325e-05 -2.967727356949107e-05 -3.117779166787325e-05
                              }
                            }
                          ]
                          name "canela_2"
                          boundingObject Pose {
                            translation -0.01675 0.1465 0.052
                            rotation 0.5773502691896258 0.5773502691896258 -0.5773502691896258 2.094395
                            children [
                              USE canela
                            ]
                          }
                          physics Physics {
                            density -1
                            mass 0.192578
                            centerOfMass [
                              0 0.065 0.025
                            ]
                            inertiaMatrix [
                              0.0004464264 0.0001319352 0.0003451714
                              2.345912e-49 -1.095901e-13 -1.739556e-11
                            ]
                          }
                          linearVelocity 3.579026121138085e-06 1.7493700708467845e-05 -3.255305692740464e-06
                          angularVelocity 7.91273421087465e-05 -2.371746745803174e-05 -3.117708767332099e-05
                        }
                      }
                    ]
                    name "joelho_2"
                    boundingObject Group {
                      children [
                        Pose {
                          translation -0.01675 0.08575 -0.002
                          rotation 1 0 0 1.570796
                          children [
                            USE coxa
                          ]
                        }
                        Pose {
                          translation 0 0.1305 0.025
                          children [
                            USE xm_540
                          ]
                        }
                      ]
                    }
                    physics Physics {
                      density -1
                      mass 0.866918
                      centerOfMass [
                        0 0.098997 0.025522
                      ]
                      inertiaMatrix [
                        0.001311283 0.0002860721 0.001180637
                        -2.13929e-12 2.577287e-12 -8.727699e-06
                      ]
                    }
                    linearVelocity 1.5159757910089908e-06 9.919835306392124e-06 -2.863529375642695e-06
                    angularVelocity 7.914793250349335e-05 -1.608197951726494e-05 -3.1176411470660795e-05
                  }
                }
              ]
              name "motores_duplos_3"
              boundingObject Group {
                children [
                  Pose {
                    translation 0.0225 0.01375 -0.05735
                    rotation 0 0 -1 3.141593
                    children [
                      USE junta_motores
                    ]
                  }
                  Pose {
                    translation 0.025 -0.0408 -0.1038
                    rotation 0 0.7071067811865476 -0.7071067811865476 3.141593
                    children [
                      USE rolamento_motor
                    ]
                  }
                  Pose {
                    translation 0 0 -0.0245
                    children [
                      USE xm_540
                    ]
                  }
                  Pose {
                    translation 0.00057 0 -0.1091
                    rotation 0 0.7071067811865476 -0.7071067811865476 3.141593
                    children [
                      USE peca_rolamento
                    ]
                  }
                  Pose {
                    translation 0.0005 -0.031 -0.0741
                    rotation -0.7071067811865476 0 -0.7071067811865476 3.141593
                    children [
                      USE xm_540
                    ]
                  }
                  Pose {
                    translation 0.00057 0 -0.1091
                    rotation 0 0.7071067811865476 -0.7071067811865476 3.141593
                    children [
                      USE rolamento
                    ]
                  }
                ]
              }
              physics Physics {
                density -1
                mass 1.532598
                centerOfMass [
                  0.000586 -0.015237 -0.050086
                ]
                inertiaMatrix [
                  0.001610811 0.001393334 0.0006473235
                  1.585238e-06 2.01501e-05 9.715833e-06
                ]
              }
              linearVelocity -2.2028509586839074e-08 1.628978222878686e-07 -2.0946555038939256e-06
              angularVelocity 7.914925530212143e-05 -2.4219663998891704e-08 -3.117485116418359e-05
            }
          }
        ]
        name "conector_calcanhar_2"
        boundingObject Pose {
          translation 0.0212 0.0202 0
          rotation -1 0 0 1.570796
          children [
            USE conector_calcanhar
          ]
        }
        physics Physics {
          density -1
          mass 0.152543
          centerOfMass [
            0.024705 0 -0.006202
          ]
          inertiaMatrix [
            3.117182e-05 0.0002757415 0.0002843804
            3.806312e-13 -3.620273e-07 -2.157674e-13
          ]
        }
        linearVelocity -2.002246486025843e-08 -8.453218780523183e-07 -1.0879280615680368e-06
        angularVelocity -2.3517215393543482e-08 2.997324389830709e-08 -3.11790579446193e-05
      }
    }
  ]
  name "Onshape"
  boundingObject Group {
    children [
      Pose {
        translation -0.058713 0.070969 0.149205
        rotation -0.7071067811865476 0 0.7071067811865476 3.141593
        children [
          USE xm_540
        ]
      }
      Pose {
        translation 0.087287 0.013219 0.000455
        rotation 0 -1 0 3.141593
        children [
          DEF tampa_peito Mesh {
            url [
              "/home/llagoeiro/Desktop/IC/IC-Prometheus-Webots/webots_prometheus/protos/tampa_peito.stl"
            ]
          }
        ]
      }
      Pose {
        translation -0.040713 0.057719 -0.021545
        rotation 1 0 0 3.141593
        children [
          USE xm_540
        ]
      }
      Pose {
        translation 0.045287 0.057719 -0.021545
        rotation 1 0 0 3.141593
        children [
          USE xm_540
        ]
      }
      Pose {
        translation 0.053752 0.1765 -0.003545
        rotation -0.5773502691896258 0.5773502691896258 -0.5773502691896258 2.094395
        children [
          DEF tampa_bateria Mesh {
            url [
              "/home/llagoeiro/Desktop/IC/IC-Prometheus-Webots/webots_prometheus/protos/tampa_bateria.stl"
            ]
          }
        ]
      }
      Pose {
        translation -0.052713 0.087219 0.067455
        children [
          DEF peito_esquerda Mesh {
            url [
              "/home/llagoeiro/Desktop/IC/IC-Prometheus-Webots/webots_prometheus/protos/peito_esquerda.stl"
            ]
          }
        ]
      }
      Pose {
        translation -0.009713 0.097219 0.002455
        rotation 0 0 1 3.141593
        children [
          DEF peito_base Mesh {
            url [
              "/home/llagoeiro/Desktop/IC/IC-Prometheus-Webots/webots_prometheus/protos/peito_base.stl"
            ]
          }
        ]
      }
      Pose {
        translation 0.063287 0.070969 0.149205
        rotation 0.7071067811865476 0 0.7071067811865476 3.141593
        children [
          USE xm_540
        ]
      }
      Pose {
        translation -0.047213 0.102776 0.103955
        rotation 0.5773502691896258 -0.5773502691896258 -0.5773502691896258 2.094395
        children [
          DEF hub Mesh {
            url [
              "/home/llagoeiro/Desktop/IC/IC-Prometheus-Webots/webots_prometheus/protos/hub.stl"
            ]
          }
        ]
      }
      Pose {
        translation -0.082713 0.087219 0.067455
        children [
          DEF peito_direita Mesh {
            url [
              "/home/llagoeiro/Desktop/IC/IC-Prometheus-Webots/webots_prometheus/protos/peito_direita.stl"
            ]
          }
        ]
      }
      Pose {
        translation 0.067287 0.150219 0.007455
        rotation 0 0.7071067811865476 0.7071067811865476 3.141593
        children [
          DEF placa_eletrica Mesh {
            url [
              "/home/llagoeiro/Desktop/IC/IC-Prometheus-Webots/webots_prometheus/protos/placa_eletrica.stl"
            ]
          }
        ]
      }
      Pose {
        translation 0.002498 0.048469 0.148955
        rotation 0 0 1 3.141593
        children [
          USE xm_430
        ]
      }
      Pose {
        translation 0.027752 0 0.000455
        rotation -0.5773502691896258 -0.5773502691896258 0.5773502691896258 2.094395
        children [
          DEF bateria1 Mesh {
            url [
              "/home/llagoeiro/Desktop/IC/IC-Prometheus-Webots/webots_prometheus/protos/bateria1.stl"
            ]
          }
        ]
      }
      Pose {
        translation 0.064787 0.152219 0.002455
        rotation 0 0.7071067811865476 0.7071067811865476 3.141593
        children [
          DEF suporte_interno Mesh {
            url [
              "/home/llagoeiro/Desktop/IC/IC-Prometheus-Webots/webots_prometheus/protos/suporte_interno.stl"
            ]
          }
        ]
      }
      Pose {
        translation 0.040252 0.169 -0.012545
        rotation 0 -0.7071067811865476 0.7071067811865476 3.141593
        children [
          DEF bateria2 Mesh {
            url [
              "/home/llagoeiro/Desktop/IC/IC-Prometheus-Webots/webots_prometheus/protos/bateria2.stl"
            ]
          }
        ]
      }
      Pose {
        translation 0.002498 0.090969 0.168455
        rotation -1 0 0 3.141593
        children [
          DEF porta_botao Mesh {
            url [
              "/home/llagoeiro/Desktop/IC/IC-Prometheus-Webots/webots_prometheus/protos/porta_botao.stl"
            ]
          }
        ]
      }
      Pose {
        translation 0.002287 0.029 -0.045545
        children [
          DEF base_baterias Mesh {
            url [
              "/home/llagoeiro/Desktop/IC/IC-Prometheus-Webots/webots_prometheus/protos/base_baterias.stl"
            ]
          }
        ]
      }
      Pose {
        translation -0.054213 0.140219 0.102455
        rotation -1 0 0 1.570796
        children [
          DEF nuc Mesh {
            url [
              "/home/llagoeiro/Desktop/IC/IC-Prometheus-Webots/webots_prometheus/protos/nuc.stl"
            ]
          }
        ]
      }
      Pose {
        translation -0.011713 0.034319 0.121455
        rotation 1 0 0 1.570796
        children [
          DEF imu Mesh {
            url [
              "/home/llagoeiro/Desktop/IC/IC-Prometheus-Webots/webots_prometheus/protos/imu.stl"
            ]
          }
        ]
      }
      Pose {
        translation -0.082713 0.161219 0.000455
        rotation 1 0 0 3.141593
        children [
          USE tampa_peito
        ]
      }
    ]
  }
}
