#VRML_SIM R2023b utf8

EXTERNPROTO "https://raw.githubusercontent.com/cyberbotics/webots/R2022b/projects/objects/backgrounds/protos/TexturedBackground.proto"
EXTERNPROTO "https://raw.githubusercontent.com/cyberbotics/webots/R2022b/projects/objects/backgrounds/protos/TexturedBackgroundLight.proto"
EXTERNPROTO "https://raw.githubusercontent.com/cyberbotics/webots/R2022b/projects/objects/floors/protos/RectangleArena.proto"

WorldInfo {
}
Viewpoint {
  orientation 0.07227373365129088 0.06700070207532703 -0.995131857265918 1.651346777469154
  position 0.051319895811849744 1.8971030049840005 3.14856414659251
}
TexturedBackground {
}
TexturedBackgroundLight {
}
RectangleArena {
  floorSize 5 5
}
Robot {
  translation 0 0 2.97
  rotation 0 0 1 3.14159
  children [
    Shape {
      appearance DEF peito_material PBRAppearance {
        baseColor 0.68388 0.701788 0.706749
        roughness 1
        metalness 0
      }
      geometry DEF peito_visual Mesh {
        url [
          "/home/lucas/Desktop/RoboFEI/IC/webots_prometheus/protos/peito_visual.stl"
        ]
      }
    }
    HingeJoint {
      jointParameters HingeJointParameters {
        position 1.0192297932419119e-06
        anchor -0.083213 0.070969 0.149205
      }
      device [
        RotationalMotor {
          name "ombro_direito_3"
          maxVelocity 6
        }
        PositionSensor {
          name "ombro_direito_3_sensor"
        }
      ]
      endPoint Solid {
        translation -0.083213 0.070969 0.149205
        rotation 0.5773504653404141 0.5773498768878839 0.5773504653403795 2.0943955884526955
        children [
          Shape {
            appearance DEF ombro_material PBRAppearance {
              baseColor 0.596078 0.666667 0.686275
              roughness 1
              metalness 0
            }
            geometry DEF ombro_visual Mesh {
              url [
                "/home/lucas/Desktop/RoboFEI/IC/webots_prometheus/protos/ombro_visual.stl"
              ]
            }
          }
          HingeJoint {
            jointParameters HingeJointParameters {
              position 5.713681982919026e-07
              axis -1 0 0
              anchor -0.02475 0 -0.042
            }
            device [
              RotationalMotor {
                name "ombro_direito_1"
                maxVelocity 6
              }
              PositionSensor {
                name "ombro_direito_1_sensor"
              }
            ]
            endPoint Solid {
              translation -0.02475 0 -0.042
              rotation -2.8568419250605667e-07 -0.9999999999999183 2.856840991459358e-07 1.5707960000000816
              children [
                Shape {
                  appearance DEF braco_material PBRAppearance {
                    baseColor 0.593536 0.669368 0.676264
                    roughness 1
                    metalness 0
                  }
                  geometry DEF braco_visual Mesh {
                    url [
                      "/home/lucas/Desktop/RoboFEI/IC/webots_prometheus/protos/braco_visual.stl"
                    ]
                  }
                }
                HingeJoint {
                  jointParameters HingeJointParameters {
                    position -2.798754610214505e-07
                    axis -1 0 0
                    anchor -0.0245 -0.141 -0.0245
                  }
                  device [
                    RotationalMotor {
                      name "cotovelo_direito_5"
                      maxVelocity 6
                    }
                    PositionSensor {
                      name "cotovelo_direito_5_sensor"
                    }
                  ]
                  endPoint Solid {
                    translation -0.0245 -0.141 -0.0245
                    rotation 1.399377762416671e-07 -0.9999999999999805 -1.3993773051072346e-07 1.5707960000000194
                    children [
                      Shape {
                        appearance DEF mao_material PBRAppearance {
                          baseColor 0.611617 0.675033 0.692649
                          roughness 1
                          metalness 0
                        }
                        geometry DEF mao_visual Mesh {
                          url [
                            "/home/lucas/Desktop/RoboFEI/IC/webots_prometheus/protos/mao_visual.stl"
                          ]
                        }
                      }
                    ]
                    name "mao"
                    boundingObject Group {
                      children [
                        Pose {
                          translation 0.022 -0.052 -0.0435
                          rotation -0.7071067811865476 0.7071067811865476 0 3.141593
                          children [
                            DEF mao Mesh {
                              url [
                                "/home/lucas/Desktop/RoboFEI/IC/webots_prometheus/protos/mao.stl"
                              ]
                            }
                          ]
                        }
                        Pose {
                          translation -0.01875 -0.001 -0.0115
                          rotation 0 0 -1 1.570796
                          children [
                            DEF apoio_mao Mesh {
                              url [
                                "/home/lucas/Desktop/RoboFEI/IC/webots_prometheus/protos/apoio_mao.stl"
                              ]
                            }
                          ]
                        }
                        Pose {
                          translation 0 0 -0.0245
                          children [
                            DEF xm_540 Mesh {
                              url [
                                "/home/lucas/Desktop/RoboFEI/IC/webots_prometheus/protos/xm_540.stl"
                              ]
                            }
                          ]
                        }
                        Pose {
                          translation 0.01675 -0.001 -0.0115
                          rotation 0 0 -1 1.570796
                          children [
                            USE apoio_mao
                          ]
                        }
                      ]
                    }
                    physics Physics {
                      density -1
                      mass 0.73912
                      centerOfMass [
                        0 -0.024983 -0.023852
                      ]
                      inertiaMatrix [
                        0.001162408 0.0002045212 0.001129553
                        -1.064272e-12 2.598116e-12 -5.966537e-06
                      ]
                    }
                    linearVelocity -9.44261052540054e-07 -1.7499093562499844e-06 -4.6351391910609726e-07
                    angularVelocity -1.2939927920068112e-05 5.696442095379432e-06 4.73764802194344e-11
                  }
                }
              ]
              name "braco"
              boundingObject Group {
                children [
                  Pose {
                    translation 0.0245 -0.041 -0.0365
                    rotation 0 -1 0 1.570796
                    children [
                      DEF junta_ombro Mesh {
                        url [
                          "/home/lucas/Desktop/RoboFEI/IC/webots_prometheus/protos/junta_ombro.stl"
                        ]
                      }
                    ]
                  }
                  Pose {
                    translation 0.0265 -0.156 -0.0245
                    rotation 0 -1 0 1.570796
                    children [
                      DEF braco Mesh {
                        url [
                          "/home/lucas/Desktop/RoboFEI/IC/webots_prometheus/protos/braco.stl"
                        ]
                      }
                    ]
                  }
                  Pose {
                    translation -0.0265 -0.156 -0.0245
                    rotation 0 1 0 1.570796
                    children [
                      USE braco
                    ]
                  }
                  Pose {
                    translation -0.01675 -0.041 -0.0365
                    rotation 0 -1 0 1.570796
                    children [
                      USE junta_ombro
                    ]
                  }
                  Pose {
                    translation 0 0 -0.0245
                    children [
                      USE xm_540
                    ]
                  }
                ]
              }
              physics Physics {
                density -1
                mass 0.744906
                centerOfMass [
                  0 -0.01797 -0.023652
                ]
                inertiaMatrix [
                  0.000479899 0.0002159248 0.0004641409
                  9.200601e-14 6.52732e-11 -1.882433e-06
                ]
              }
              linearVelocity -1.0133258443478106e-07 -1.802067946608351e-07 -3.787491092682447e-07
              angularVelocity -1.013834574139947e-05 5.698589481500305e-06 6.539016112132956e-11
            }
          }
        ]
        name "ombro"
        boundingObject Pose {
          rotation 0.5773502691896258 0.5773502691896258 -0.5773502691896258 2.094395
          children [
            DEF ombro Mesh {
              url [
                "/home/lucas/Desktop/RoboFEI/IC/webots_prometheus/protos/ombro.stl"
              ]
            }
          ]
        }
        physics Physics {
          density -1
          mass 0.059819
          centerOfMass [
            0 0 -0.013873
          ]
          inertiaMatrix [
            1.606092e-05 4.170447e-05 3.516622e-05
            -1.30586e-41 8.830912e-37 -2.825173e-10
          ]
        }
        linearVelocity 5.354322815680631e-10 9.893914030410624e-10 -1.873285498963437e-07
        angularVelocity -1.0142855024790192e-05 7.657812972922555e-09 5.200589917729541e-11
      }
    }
    HingeJoint {
      jointParameters HingeJointParameters {
        position 1.0168253161788253e-06
        axis -1 0 0
        anchor 0.087787 0.070969 0.149205
      }
      device [
        RotationalMotor {
          name "ombro_esquerdo_4"
          maxVelocity 6
        }
        PositionSensor {
          name "ombro_esquerdo_4_sensor"
        }
      ]
      endPoint Solid {
        translation 0.087787 0.070969 0.149205
        rotation -0.5773504648776727 -0.5773498778133674 0.577350464877638 2.0943955870644695
        children [
          Shape {
            appearance DEF ombro_2_material PBRAppearance {
              baseColor 0.596078 0.666667 0.686275
              roughness 1
              metalness 0
            }
            geometry DEF ombro_2_visual Mesh {
              url [
                "/home/lucas/Desktop/RoboFEI/IC/webots_prometheus/protos/ombro_2_visual.stl"
              ]
            }
          }
          HingeJoint {
            jointParameters HingeJointParameters {
              position -5.713649224716193e-07
              axis -1 0 0
              anchor -0.02675 0 -0.042
            }
            device [
              RotationalMotor {
                name "ombro_esquerdo_2"
                maxVelocity 6
              }
              PositionSensor {
                name "ombro_esquerdo_2_sensor"
              }
            ]
            endPoint Solid {
              translation -0.02675 0 -0.042
              rotation -0.7071067811865579 -2.020080056058983e-07 0.7071067811865084 3.1415925959839885
              children [
                Shape {
                  appearance DEF braco_2_material PBRAppearance {
                    baseColor 0.593536 0.669368 0.676264
                    roughness 1
                    metalness 0
                  }
                  geometry DEF braco_2_visual Mesh {
                    url [
                      "/home/lucas/Desktop/RoboFEI/IC/webots_prometheus/protos/braco_2_visual.stl"
                    ]
                  }
                }
                HingeJoint {
                  jointParameters HingeJointParameters {
                    position 2.7987554250498936e-07
                    anchor 0.0245 -0.141 -0.0245
                  }
                  device [
                    RotationalMotor {
                      name "cotovelo_esquerdo_6"
                      maxVelocity 6
                    }
                    PositionSensor {
                      name "cotovelo_esquerdo_6_sensor"
                    }
                  ]
                  endPoint Solid {
                    translation 0.0245 -0.141 -0.0245
                    rotation 1.3993781698344981e-07 0.9999999999999805 1.3993777125249285e-07 1.5707960000000194
                    children [
                      Shape {
                        appearance DEF mao_2_material PBRAppearance {
                          baseColor 0.611617 0.675033 0.692649
                          roughness 1
                          metalness 0
                        }
                        geometry DEF mao_2_visual Mesh {
                          url [
                            "/home/lucas/Desktop/RoboFEI/IC/webots_prometheus/protos/mao_2_visual.stl"
                          ]
                        }
                      }
                    ]
                    name "mao_2"
                    boundingObject Group {
                      children [
                        Pose {
                          translation -0.01875 -0.001 -0.0115
                          rotation 0 0 -1 1.570796
                          children [
                            USE apoio_mao
                          ]
                        }
                        Pose {
                          translation 0 0 -0.0245
                          children [
                            USE xm_540
                          ]
                        }
                        Pose {
                          translation 0.022 -0.052 -0.0435
                          rotation 0.7071067811865476 -0.7071067811865476 0 3.141593
                          children [
                            USE mao
                          ]
                        }
                        Pose {
                          translation 0.01675 -0.001 -0.0115
                          rotation 0 0 -1 1.570796
                          children [
                            USE apoio_mao
                          ]
                        }
                      ]
                    }
                    physics Physics {
                      density -1
                      mass 0.73912
                      centerOfMass [
                        0 -0.024983 -0.023852
                      ]
                      inertiaMatrix [
                        0.001162408 0.0002045212 0.001129553
                        -1.064268e-12 2.598116e-12 -5.966537e-06
                      ]
                    }
                    linearVelocity 9.442670189969205e-07 1.5298873592464527e-06 -4.393377307466584e-07
                    angularVelocity 6.853374150173705e-06 -5.696466047960093e-06 1.6513246790275125e-11
                  }
                }
              ]
              name "braco_2"
              boundingObject Group {
                children [
                  Pose {
                    translation 0.0245 -0.041 -0.0365
                    rotation 0 -1 0 1.570796
                    children [
                      USE junta_ombro
                    ]
                  }
                  Pose {
                    translation 0 0 -0.0245
                    children [
                      USE xm_540
                    ]
                  }
                  Pose {
                    translation -0.01675 -0.041 -0.0365
                    rotation 0 -1 0 1.570796
                    children [
                      USE junta_ombro
                    ]
                  }
                  Pose {
                    translation 0.0265 -0.156 -0.0245
                    rotation 0 -1 0 1.570796
                    children [
                      USE braco
                    ]
                  }
                  Pose {
                    translation -0.0265 -0.156 -0.0245
                    rotation 0 1 0 1.570796
                    children [
                      USE braco
                    ]
                  }
                ]
              }
              physics Physics {
                density -1
                mass 0.744906
                centerOfMass [
                  0 -0.01797 -0.023652
                ]
                inertiaMatrix [
                  0.000479899 0.0002159248 0.0004641409
                  9.200554e-14 6.52732e-11 -1.882433e-06
                ]
              }
              linearVelocity 1.0133312201541324e-07 1.7164647192629796e-07 -3.377767003822563e-07
              angularVelocity 9.655009655560678e-06 -5.698628024016471e-06 3.854959242862386e-11
            }
          }
        ]
        name "ombro_2"
        boundingObject Pose {
          rotation 0.5773502691896258 0.5773502691896258 -0.5773502691896258 2.094395
          children [
            USE ombro
          ]
        }
        physics Physics {
          density -1
          mass 0.059819
          centerOfMass [
            0 0 -0.013873
          ]
          inertiaMatrix [
            1.606092e-05 4.170447e-05 3.516622e-05
            1.828204e-41 -1.236328e-36 -2.825173e-10
          ]
        }
        linearVelocity -5.354321333876641e-10 -9.268129326886524e-10 -1.8736367804399556e-07
        angularVelocity 9.65083888876896e-06 -7.657631104616563e-09 5.028349437386595e-11
      }
    }
    HingeJoint {
      jointParameters HingeJointParameters {
        position 3.589836511390523e-08
        axis 0 0 -1
        anchor 0.002498 0.048469 0.167955
      }
      device [
        RotationalMotor {
          name "pescoço_19"
          maxVelocity 6
        }
        PositionSensor {
          name "pescoço_19_sensor"
        }
      ]
      endPoint Solid {
        translation 0.002498 0.048469 0.167955
        rotation -0.7071067684945588 0.7071067938785361 3.1088900191016767e-15 3.141593
        children [
          Shape {
            appearance DEF pescoco_material PBRAppearance {
              baseColor 0.68388 0.701788 0.706749
              roughness 1
              metalness 0
            }
            geometry DEF pescoco_visual Mesh {
              url [
                "/home/lucas/Desktop/RoboFEI/IC/webots_prometheus/protos/pescoco_visual.stl"
              ]
            }
          }
          HingeJoint {
            jointParameters HingeJointParameters {
              position -1.3029862445569693e-07
              axis 0 1 0
              anchor -0.00075 0.019 -0.06075
            }
            device [
              RotationalMotor {
                name "pescoço_20"
                maxVelocity 6
              }
              PositionSensor {
                name "pescoço_20_sensor"
              }
            ]
            endPoint Solid {
              translation -0.00075 0.019 -0.06075
              rotation -0.9999999999999958 -6.514933351831452e-08 -6.514931222784828e-08 1.570796000000004
              children [
                Shape {
                  appearance DEF capacete_material PBRAppearance {
                    baseColor 0.787536 0.812047 0.913591
                    roughness 1
                    metalness 0
                  }
                  geometry DEF capacete_visual Mesh {
                    url [
                      "/home/lucas/Desktop/RoboFEI/IC/webots_prometheus/protos/capacete_visual.stl"
                    ]
                  }
                }
              ]
              name "capacete"
              boundingObject Group {
                children [
                  Pose {
                    translation 0.019657 0.027657 -0.0695
                    rotation 0 -1 0 1.570796
                    children [
                      DEF webcam Mesh {
                        url [
                          "/home/lucas/Desktop/RoboFEI/IC/webots_prometheus/protos/webcam.stl"
                        ]
                      }
                    ]
                  }
                  Pose {
                    translation 0.006657 0.005657 -0.0005
                    children [
                      DEF capacete Mesh {
                        url [
                          "/home/lucas/Desktop/RoboFEI/IC/webots_prometheus/protos/capacete.stl"
                        ]
                      }
                    ]
                  }
                  Pose {
                    translation 0.029657 0.057657 -0.0405
                    rotation -1 0 0 3.141593
                    children [
                      DEF tampa_capacete Mesh {
                        url [
                          "/home/lucas/Desktop/RoboFEI/IC/webots_prometheus/protos/tampa_capacete.stl"
                        ]
                      }
                    ]
                  }
                ]
              }
              physics Physics {
                density -1
                mass 0.413474
                centerOfMass [
                  0.006937 0.041371 -0.019493
                ]
                inertiaMatrix [
                  0.0002893456 0.0002819696 5.738237e-05
                  4.382665e-07 5.023613e-08 1.739618e-08
                ]
              }
              linearVelocity 2.1823340931092645e-09 6.462539333284547e-08 -1.5912927127634087e-07
              angularVelocity -1.558120274549471e-06 -9.690347272807394e-10 -3.5935139096404357e-07
            }
          }
        ]
        name "pescoco"
        boundingObject Group {
          children [
            Pose {
              translation -0.00075 0 -0.06075
              rotation -1 0 0 1.570796
              children [
                DEF xm_430 Mesh {
                  url [
                    "/home/lucas/Desktop/RoboFEI/IC/webots_prometheus/protos/xm_430.stl"
                  ]
                }
              ]
            }
            Pose {
              translation -0.015 0.019 0
              rotation -1 0 0 1.570796
              children [
                DEF pescoco Mesh {
                  url [
                    "/home/lucas/Desktop/RoboFEI/IC/webots_prometheus/protos/pescoco.stl"
                  ]
                }
              ]
            }
          ]
        }
        physics Physics {
          density -1
          mass 0.394812
          centerOfMass [
            -0.000753 0.000625 -0.045915
          ]
          inertiaMatrix [
            0.000160923 0.000138921 7.366453e-05
            -6.590875e-10 4.735301e-08 8.18567e-07
          ]
        }
        linearVelocity -2.7091642871881314e-10 -2.2670063791123243e-10 -9.811608719068136e-08
        angularVelocity -2.728044465349581e-10 5.1355973640232456e-12 -3.593513994014166e-07
      }
    }
    HingeJoint {
      jointParameters HingeJointParameters {
        position -1.557353065235139e-06
        axis 0 0 1
        anchor -0.040713 0.057719 -0.046045
      }
      device [
        RotationalMotor {
          name "junta_peito_pernaD_7"
          maxVelocity 6
        }
        PositionSensor {
          name "junta_peito_pernaD_7_sensor"
        }
      ]
      endPoint Solid {
        translation -0.040713 0.057719 -0.046045
        rotation 0 0 1 1.570794442646935
        children [
          Shape {
            appearance DEF conector_calcanhar_material PBRAppearance {
              baseColor 0.6 0.6 0.6
              roughness 1
              metalness 0
            }
            geometry DEF conector_calcanhar_visual Mesh {
              url [
                "/home/lucas/Desktop/RoboFEI/IC/webots_prometheus/protos/conector_calcanhar_visual.stl"
              ]
            }
          }
          HingeJoint {
            jointParameters HingeJointParameters {
              position -3.9580304356736246e-06
              anchor 0.0787 0 -0.033
            }
            device [
              RotationalMotor {
                name "perna_direita_9"
                maxVelocity 6
              }
              PositionSensor {
                name "perna_direita_9_sensor"
              }
            ]
            endPoint Solid {
              translation 0.0787 0 -0.033
              rotation 0.5773495074647157 0.5773517926362958 0.5773495074648508 2.09439271483157
              children [
                Shape {
                  appearance DEF motores_duplos_material PBRAppearance {
                    baseColor 0.64258 0.703747 0.720738
                    roughness 1
                    metalness 0
                  }
                  geometry DEF motores_duplos_visual Mesh {
                    url [
                      "/home/lucas/Desktop/RoboFEI/IC/webots_prometheus/protos/motores_duplos_visual.stl"
                    ]
                  }
                }
                HingeJoint {
                  jointParameters HingeJointParameters {
                    position -1.1194159321907825e-06
                    axis -1 0 0
                    anchor 0.025 -0.031 -0.0741
                  }
                  device [
                    RotationalMotor {
                      name "coxa_direita_11"
                      maxVelocity 6
                    }
                    PositionSensor {
                      name "coxa_direita_11_sensor"
                    }
                  ]
                  endPoint Solid {
                    translation 0.025 -0.031 -0.0741
                    rotation 5.597081490050111e-07 -0.9999999999996866 -5.597079660952743e-07 1.5707960000003134
                    children [
                      Shape {
                        appearance DEF joelho_material PBRAppearance {
                          baseColor 0.596078 0.666667 0.686275
                          roughness 1
                          metalness 0
                        }
                        geometry DEF joelho_visual Mesh {
                          url [
                            "/home/lucas/Desktop/RoboFEI/IC/webots_prometheus/protos/joelho_visual.stl"
                          ]
                        }
                      }
                      HingeJoint {
                        jointParameters HingeJointParameters {
                          position -8.468646578938244e-07
                          axis 0 0 1
                          anchor 0 -0.1305 0.0005
                        }
                        device [
                          RotationalMotor {
                            name "joelho_direito_13"
                            maxVelocity 6
                          }
                          PositionSensor {
                            name "joelho_direito_13_sensor"
                          }
                        ]
                        endPoint Solid {
                          translation 0 -0.1305 0.0005
                          rotation 0 0 -0.9999999999999999 8.466167873943983e-07
                          children [
                            Shape {
                              appearance DEF canela_material PBRAppearance {
                                baseColor 0.596078 0.666667 0.686275
                                roughness 1
                                metalness 0
                              }
                              geometry DEF canela_visual Mesh {
                                url [
                                  "/home/lucas/Desktop/RoboFEI/IC/webots_prometheus/protos/canela_visual.stl"
                                ]
                              }
                            }
                            HingeJoint {
                              jointParameters HingeJointParameters {
                                position -7.187798336830431e-07
                                axis 0 0 1
                                anchor 0 -0.13 0.05
                              }
                              device [
                                RotationalMotor {
                                  name "pe_direito_15"
                                  maxVelocity 6
                                }
                                PositionSensor {
                                  name "pe_direito_15_sensor"
                                }
                              ]
                              endPoint Solid {
                                translation 0 -0.13 0.05
                                rotation 0 0 -1 7.189713765272429e-07
                                children [
                                  Shape {
                                    appearance DEF motores_duplos_2_material PBRAppearance {
                                      baseColor 0.64258 0.703747 0.720738
                                      roughness 1
                                      metalness 0
                                    }
                                    geometry DEF motores_duplos_2_visual Mesh {
                                      url [
                                        "/home/lucas/Desktop/RoboFEI/IC/webots_prometheus/protos/motores_duplos_2_visual.stl"
                                      ]
                                    }
                                  }
                                  HingeJoint {
                                    jointParameters HingeJointParameters {
                                      position -2.7989465531382936e-07
                                      axis -1 0 0
                                      anchor 0.0741 -0.031 -0.025
                                    }
                                    device [
                                      RotationalMotor {
                                        name "pe_direito_17"
                                        maxVelocity 6
                                      }
                                      PositionSensor {
                                        name "pe_direito_17_sensor"
                                      }
                                    ]
                                    endPoint Solid {
                                      translation 0.0741 -0.031 -0.025
                                      rotation -0.5773502153238603 -0.5773503769211319 0.5773502153238699 2.094394838402753
                                      children [
                                        Shape {
                                          appearance DEF pe_direito_material PBRAppearance {
                                            baseColor 0.598579 0.624151 0.631254
                                            roughness 1
                                            metalness 0
                                          }
                                          geometry DEF pe_direito_visual Mesh {
                                            url [
                                              "/home/lucas/Desktop/RoboFEI/IC/webots_prometheus/protos/pe_direito_visual.stl"
                                            ]
                                          }
                                        }
                                      ]
                                      name "pe_direito"
                                      boundingObject Group {
                                        children [
                                          Pose {
                                            translation -0.033 -0.0202 0.0575
                                            rotation 0.5773502691896258 0.5773502691896258 -0.5773502691896258 2.094395
                                            children [
                                              DEF conector_calcanhar Mesh {
                                                url [
                                                  "/home/lucas/Desktop/RoboFEI/IC/webots_prometheus/protos/conector_calcanhar.stl"
                                                ]
                                              }
                                            ]
                                          }
                                          Pose {
                                            translation -0.033 0.0638 0.201
                                            rotation -0.7071067811865476 0 0.7071067811865476 3.141593
                                            children [
                                              DEF pe Mesh {
                                                url [
                                                  "/home/lucas/Desktop/RoboFEI/IC/webots_prometheus/protos/pe.stl"
                                                ]
                                              }
                                            ]
                                          }
                                        ]
                                      }
                                      physics Physics {
                                        density -1
                                        mass 0.239194
                                        centerOfMass [
                                          -0.029588 0.003976 0.071403
                                        ]
                                        inertiaMatrix [
                                          0.0008333298 0.0007303742 0.0001321754
                                          4.672117e-06 2.009087e-05 -3.23004e-05
                                        ]
                                      }
                                      linearVelocity -1.3871920253044088e-05 -6.645584000256857e-07 -2.025055343605349e-06
                                      angularVelocity -5.271183393248169e-07 3.6983281720674914e-05 -1.558882093168561e-05
                                    }
                                  }
                                ]
                                name "motores_duplos_2"
                                boundingObject Group {
                                  children [
                                    Pose {
                                      translation 0 0 -0.0245
                                      children [
                                        USE xm_540
                                      ]
                                    }
                                    Pose {
                                      translation -0.035 -0.031 -0.02443
                                      rotation -0.5773502691896258 0.5773502691896258 0.5773502691896258 2.094395
                                      children [
                                        DEF rolamento Mesh {
                                          url [
                                            "/home/lucas/Desktop/RoboFEI/IC/webots_prometheus/protos/rolamento.stl"
                                          ]
                                        }
                                      ]
                                    }
                                    Pose {
                                      translation -0.035 -0.031 -0.02443
                                      rotation -0.5773502691896258 0.5773502691896258 0.5773502691896258 2.094395
                                      children [
                                        DEF peca_rolamento Mesh {
                                          url [
                                            "/home/lucas/Desktop/RoboFEI/IC/webots_prometheus/protos/peca_rolamento.stl"
                                          ]
                                        }
                                      ]
                                    }
                                    Pose {
                                      translation 0.0496 -0.031 -0.025
                                      rotation -0.7071067811865476 0 -0.7071067811865476 3.141593
                                      children [
                                        USE xm_540
                                      ]
                                    }
                                    Pose {
                                      translation -0.0297 0.0098 0
                                      rotation -0.5773502691896258 0.5773502691896258 0.5773502691896258 2.094395
                                      children [
                                        DEF rolamento_motor Mesh {
                                          url [
                                            "/home/lucas/Desktop/RoboFEI/IC/webots_prometheus/protos/rolamento_motor.stl"
                                          ]
                                        }
                                      ]
                                    }
                                    Pose {
                                      translation 0.01675 -0.04475 -0.0025
                                      rotation 0 1 0 1.570796
                                      children [
                                        DEF junta_motores Mesh {
                                          url [
                                            "/home/lucas/Desktop/RoboFEI/IC/webots_prometheus/protos/junta_motores.stl"
                                          ]
                                        }
                                      ]
                                    }
                                  ]
                                }
                                physics Physics {
                                  density -1
                                  mass 1.532598
                                  centerOfMass [
                                    0.024014 -0.015763 -0.024413
                                  ]
                                  inertiaMatrix [
                                    0.0006473235 0.001393334 0.001610811
                                    -9.715833e-06 2.01501e-05 -1.585238e-06
                                  ]
                                }
                                linearVelocity -1.2509395744383375e-05 -5.703080795644857e-07 -1.8145982977111407e-06
                                angularVelocity -5.250742558165658e-07 3.956754022643032e-05 -1.5588671441790975e-05
                              }
                            }
                          ]
                          name "canela"
                          boundingObject Pose {
                            translation -0.01675 -0.1465 -0.002
                            rotation -0.5773502691896258 -0.5773502691896258 -0.5773502691896258 2.094395
                            children [
                              DEF canela Mesh {
                                url [
                                  "/home/lucas/Desktop/RoboFEI/IC/webots_prometheus/protos/canela.stl"
                                ]
                              }
                            ]
                          }
                          physics Physics {
                            density -1
                            mass 0.192578
                            centerOfMass [
                              0 -0.065 0.025
                            ]
                            inertiaMatrix [
                              0.0004464264 0.0001319352 0.0003451714
                              4.235297e-27 1.095901e-13 -1.739556e-11
                            ]
                          }
                          linearVelocity -8.955397496687272e-06 -7.953276672236708e-07 -1.6361692743723426e-06
                          angularVelocity 3.40356856474263e-06 3.95625386715066e-05 -1.5589082697564687e-05
                        }
                      }
                    ]
                    name "joelho"
                    boundingObject Group {
                      children [
                        Pose {
                          translation 0 -0.1305 0.025
                          rotation -1 0 0 3.141593
                          children [
                            USE xm_540
                          ]
                        }
                        Pose {
                          translation -0.01675 -0.08575 0.052
                          rotation -1 0 0 1.570796
                          children [
                            DEF coxa Mesh {
                              url [
                                "/home/lucas/Desktop/RoboFEI/IC/webots_prometheus/protos/coxa.stl"
                              ]
                            }
                          ]
                        }
                      ]
                    }
                    physics Physics {
                      density -1
                      mass 0.866918
                      centerOfMass [
                        0 -0.098997 0.024478
                      ]
                      inertiaMatrix [
                        0.001311283 0.0002860721 0.001180637
                        2.13929e-12 -2.577287e-12 -8.727699e-06
                      ]
                    }
                    linearVelocity -5.1540385863416144e-06 -7.84820365137715e-07 -1.4390004660904406e-06
                    angularVelocity -7.961426572871328e-06 3.9570966792214606e-05 -1.5589373521267575e-05
                  }
                }
              ]
              name "motores_duplos"
              boundingObject Group {
                children [
                  Pose {
                    translation 0 0 -0.0245
                    children [
                      USE xm_540
                    ]
                  }
                  Pose {
                    translation 0.00057 0 -0.1091
                    rotation 0 0.7071067811865476 -0.7071067811865476 3.141593
                    children [
                      USE peca_rolamento
                    ]
                  }
                  Pose {
                    translation 0.025 -0.0408 -0.1038
                    rotation 0 0.7071067811865476 -0.7071067811865476 3.141593
                    children [
                      USE rolamento_motor
                    ]
                  }
                  Pose {
                    translation 0.00057 0 -0.1091
                    rotation 0 0.7071067811865476 -0.7071067811865476 3.141593
                    children [
                      USE rolamento
                    ]
                  }
                  Pose {
                    translation 0.0225 0.01375 -0.05735
                    rotation 0 0 -1 3.141593
                    children [
                      USE junta_motores
                    ]
                  }
                  Pose {
                    translation 0.0005 -0.031 -0.0741
                    rotation -0.7071067811865476 0 -0.7071067811865476 3.141593
                    children [
                      USE xm_540
                    ]
                  }
                ]
              }
              physics Physics {
                density -1
                mass 1.532598
                centerOfMass [
                  0.000586 -0.015237 -0.050086
                ]
                inertiaMatrix [
                  0.001610811 0.001393334 0.0006473235
                  1.585238e-06 2.01501e-05 9.715833e-06
                ]
              }
              linearVelocity -1.00693646188572e-06 -1.249365292631564e-09 -1.0986603787523817e-06
              angularVelocity -1.584430090986055e-08 3.95845414205695e-05 -1.558962610692566e-05
            }
          }
        ]
        name "conector_calcanhar"
        boundingObject Pose {
          translation 0.0212 0.0202 0
          rotation -1 0 0 1.570796
          children [
            USE conector_calcanhar
          ]
        }
        physics Physics {
          density -1
          mass 0.152543
          centerOfMass [
            0.024705 0 -0.006202
          ]
          inertiaMatrix [
            3.117182e-05 0.0002757415 0.0002843804
            3.806312e-13 -3.620273e-07 -2.157674e-13
          ]
        }
        linearVelocity -3.640527798891389e-07 3.929444580735526e-09 -5.46386097450979e-07
        angularVelocity 1.307068139126781e-08 -6.244855963928964e-09 -1.558854292725936e-05
      }
    }
    HingeJoint {
      jointParameters HingeJointParameters {
        position -1.557372527793125e-06
        axis 0 0 1
        anchor 0.045287 0.057719 -0.046045
      }
      device [
        RotationalMotor {
          name "junta_peito_pernaE_8"
          maxVelocity 6
        }
        PositionSensor {
          name "junta_peito_pernaE_8_sensor"
        }
      ]
      endPoint Solid {
        translation 0.045287 0.057719 -0.046045
        rotation 0 0 1 1.5707944426274723
        children [
          Shape {
            appearance DEF conector_calcanhar_2_material PBRAppearance {
              baseColor 0.6 0.6 0.6
              roughness 1
              metalness 0
            }
            geometry DEF conector_calcanhar_2_visual Mesh {
              url [
                "/home/lucas/Desktop/RoboFEI/IC/webots_prometheus/protos/conector_calcanhar_2_visual.stl"
              ]
            }
          }
          HingeJoint {
            jointParameters HingeJointParameters {
              position 3.958029616239498e-06
              anchor 0.0787 0 -0.033
            }
            device [
              RotationalMotor {
                name "perna_esquerda_10"
                maxVelocity 6
              }
              PositionSensor {
                name "perna_esquerda_10_sensor"
              }
            ]
            endPoint Solid {
              translation 0.0787 0 -0.033
              rotation 0.5773510309113632 0.5773487457432711 0.577351030911228 2.0943972851709716
              children [
                Shape {
                  appearance DEF motores_duplos_3_material PBRAppearance {
                    baseColor 0.64258 0.703747 0.720738
                    roughness 1
                    metalness 0
                  }
                  geometry DEF motores_duplos_3_visual Mesh {
                    url [
                      "/home/lucas/Desktop/RoboFEI/IC/webots_prometheus/protos/motores_duplos_3_visual.stl"
                    ]
                  }
                }
                HingeJoint {
                  jointParameters HingeJointParameters {
                    position -1.1314933366684734e-06
                    axis -1 0 0
                    anchor 0.025 -0.031 -0.0741
                  }
                  device [
                    RotationalMotor {
                      name "coxa_esquerda_12"
                      maxVelocity 6
                    }
                    PositionSensor {
                      name "coxa_esquerda_12_sensor"
                    }
                  ]
                  endPoint Solid {
                    translation 0.025 -0.031 -0.0741
                    rotation 0.7071067811864421 4.0004330561287386e-07 -0.7071067811865401 3.141593800086611
                    children [
                      Shape {
                        appearance DEF joelho_2_material PBRAppearance {
                          baseColor 0.596078 0.666667 0.686275
                          roughness 1
                          metalness 0
                        }
                        geometry DEF joelho_2_visual Mesh {
                          url [
                            "/home/lucas/Desktop/RoboFEI/IC/webots_prometheus/protos/joelho_2_visual.stl"
                          ]
                        }
                      }
                      HingeJoint {
                        jointParameters HingeJointParameters {
                          position -7.411431628085029e-07
                          axis 0 0 -1
                          anchor 0 0.1305 0.0495
                        }
                        device [
                          RotationalMotor {
                            name "joelho_esquerdo_14"
                            maxVelocity 6
                          }
                          PositionSensor {
                            name "joelho_esquerdo_14_sensor"
                          }
                        ]
                        endPoint Solid {
                          translation 0 0.1305 0.0495
                          rotation 3.70571581404243e-07 -0.9999999999999315 -6.418488904076152e-14 3.141593
                          children [
                            Shape {
                              appearance DEF canela_2_material PBRAppearance {
                                baseColor 0.596078 0.666667 0.686275
                                roughness 1
                                metalness 0
                              }
                              geometry DEF canela_2_visual Mesh {
                                url [
                                  "/home/lucas/Desktop/RoboFEI/IC/webots_prometheus/protos/canela_2_visual.stl"
                                ]
                              }
                            }
                            HingeJoint {
                              jointParameters HingeJointParameters {
                                position 6.718820820108721e-07
                                axis 0 0 -1
                                anchor 0 0.13 0
                              }
                              device [
                                RotationalMotor {
                                  name "pe_esquerdo_16"
                                  maxVelocity 6
                                }
                                PositionSensor {
                                  name "pe_esquerdo_16_sensor"
                                }
                              ]
                              endPoint Solid {
                                translation 0 0.13 0
                                rotation -0.9999999999999437 3.359410410054298e-07 5.818670271331429e-14 3.141593
                                children [
                                  Shape {
                                    appearance DEF motores_duplos_4_material PBRAppearance {
                                      baseColor 0.64258 0.703747 0.720738
                                      roughness 1
                                      metalness 0
                                    }
                                    geometry DEF motores_duplos_4_visual Mesh {
                                      url [
                                        "/home/lucas/Desktop/RoboFEI/IC/webots_prometheus/protos/motores_duplos_4_visual.stl"
                                      ]
                                    }
                                  }
                                  HingeJoint {
                                    jointParameters HingeJointParameters {
                                      position 2.79894460233739e-07
                                      axis -1 0 0
                                      anchor 0.0741 -0.031 -0.025
                                    }
                                    device [
                                      RotationalMotor {
                                        name "pe_esquerdo_18"
                                        maxVelocity 6
                                      }
                                      PositionSensor {
                                        name "pe_esquerdo_18_sensor"
                                      }
                                    ]
                                    endPoint Solid {
                                      translation 0.0741 -0.031 -0.025
                                      rotation -0.5773503230553385 -0.5773501614581946 0.5773503230553291 2.0943951615971494
                                      children [
                                        Shape {
                                          appearance DEF pe_esquerdo_material PBRAppearance {
                                            baseColor 0.598579 0.624151 0.631254
                                            roughness 1
                                            metalness 0
                                          }
                                          geometry DEF pe_esquerdo_visual Mesh {
                                            url [
                                              "/home/lucas/Desktop/RoboFEI/IC/webots_prometheus/protos/pe_esquerdo_visual.stl"
                                            ]
                                          }
                                        }
                                      ]
                                      name "pe_esquerdo"
                                      boundingObject Group {
                                        children [
                                          Pose {
                                            translation -0.036 -0.0638 0.201
                                            rotation 0 1 0 1.570796
                                            children [
                                              USE pe
                                            ]
                                          }
                                          Pose {
                                            translation -0.033 -0.0202 0.0575
                                            rotation 0.5773502691896258 0.5773502691896258 -0.5773502691896258 2.094395
                                            children [
                                              USE conector_calcanhar
                                            ]
                                          }
                                        ]
                                      }
                                      physics Physics {
                                        density -1
                                        mass 0.239194
                                        centerOfMass [
                                          -0.029588 -0.003976 0.071403
                                        ]
                                        inertiaMatrix [
                                          0.0008333298 0.0007303742 0.0001321754
                                          -4.672117e-06 2.009087e-05 3.23004e-05
                                        ]
                                      }
                                      linearVelocity 1.3656918892056337e-05 -3.413330725065913e-06 -1.9859073342208423e-06
                                      angularVelocity -1.4845197024540052e-05 -3.699142277299462e-05 -1.5588790000968513e-05
                                    }
                                  }
                                ]
                                name "motores_duplos_4"
                                boundingObject Group {
                                  children [
                                    Pose {
                                      translation 0.0496 -0.031 -0.025
                                      rotation -0.7071067811865476 0 -0.7071067811865476 3.141593
                                      children [
                                        USE xm_540
                                      ]
                                    }
                                    Pose {
                                      translation -0.035 -0.031 -0.02443
                                      rotation -0.5773502691896258 0.5773502691896258 0.5773502691896258 2.094395
                                      children [
                                        USE rolamento
                                      ]
                                    }
                                    Pose {
                                      translation 0 0 -0.0245
                                      children [
                                        USE xm_540
                                      ]
                                    }
                                    Pose {
                                      translation -0.0297 0.0098 0
                                      rotation -0.5773502691896258 0.5773502691896258 0.5773502691896258 2.094395
                                      children [
                                        USE rolamento_motor
                                      ]
                                    }
                                    Pose {
                                      translation 0.01675 -0.04475 -0.0025
                                      rotation 0 1 0 1.570796
                                      children [
                                        USE junta_motores
                                      ]
                                    }
                                    Pose {
                                      translation -0.035 -0.031 -0.02443
                                      rotation -0.5773502691896258 0.5773502691896258 0.5773502691896258 2.094395
                                      children [
                                        USE peca_rolamento
                                      ]
                                    }
                                  ]
                                }
                                physics Physics {
                                  density -1
                                  mass 1.532598
                                  centerOfMass [
                                    0.024014 -0.015763 -0.024413
                                  ]
                                  inertiaMatrix [
                                    0.0006473235 0.001393334 0.001610811
                                    -9.715833e-06 2.01501e-05 -1.585238e-06
                                  ]
                                }
                                linearVelocity 1.1629384053270699e-05 -2.8013578590314458e-06 -1.5166623947724549e-06
                                angularVelocity -1.484316740005405e-05 -3.9575676911049836e-05 -1.5588953957387917e-05
                              }
                            }
                          ]
                          name "canela_2"
                          boundingObject Pose {
                            translation -0.01675 0.1465 0.052
                            rotation 0.5773502691896258 0.5773502691896258 -0.5773502691896258 2.094395
                            children [
                              USE canela
                            ]
                          }
                          physics Physics {
                            density -1
                            mass 0.192578
                            centerOfMass [
                              0 0.065 0.025
                            ]
                            inertiaMatrix [
                              0.0004464264 0.0001319352 0.0003451714
                              2.345912e-49 -1.095901e-13 -1.739556e-11
                            ]
                          }
                          linearVelocity 8.821776828553699e-06 -1.8094221867561266e-06 -1.635675188416911e-06
                          angularVelocity -1.1863153803556237e-05 -3.958116419660925e-05 -1.5588776608515283e-05
                        }
                      }
                    ]
                    name "joelho_2"
                    boundingObject Group {
                      children [
                        Pose {
                          translation -0.01675 0.08575 -0.002
                          rotation 1 0 0 1.570796
                          children [
                            USE coxa
                          ]
                        }
                        Pose {
                          translation 0 0.1305 0.025
                          children [
                            USE xm_540
                          ]
                        }
                      ]
                    }
                    physics Physics {
                      density -1
                      mass 0.866918
                      centerOfMass [
                        0 0.098997 0.025522
                      ]
                      inertiaMatrix [
                        0.001311283 0.0002860721 0.001180637
                        -2.13929e-12 2.577287e-12 -8.727699e-06
                      ]
                    }
                    linearVelocity 5.017646533852615e-06 -7.732571554682461e-07 -1.4386172418681915e-06
                    angularVelocity -8.044439760715276e-06 -3.958921190254622e-05 -1.5588606417028667e-05
                  }
                }
              ]
              name "motores_duplos_3"
              boundingObject Group {
                children [
                  Pose {
                    translation 0.0225 0.01375 -0.05735
                    rotation 0 0 -1 3.141593
                    children [
                      USE junta_motores
                    ]
                  }
                  Pose {
                    translation 0.025 -0.0408 -0.1038
                    rotation 0 0.7071067811865476 -0.7071067811865476 3.141593
                    children [
                      USE rolamento_motor
                    ]
                  }
                  Pose {
                    translation 0 0 -0.0245
                    children [
                      USE xm_540
                    ]
                  }
                  Pose {
                    translation 0.00057 0 -0.1091
                    rotation 0 0.7071067811865476 -0.7071067811865476 3.141593
                    children [
                      USE peca_rolamento
                    ]
                  }
                  Pose {
                    translation 0.0005 -0.031 -0.0741
                    rotation -0.7071067811865476 0 -0.7071067811865476 3.141593
                    children [
                      USE xm_540
                    ]
                  }
                  Pose {
                    translation 0.00057 0 -0.1091
                    rotation 0 0.7071067811865476 -0.7071067811865476 3.141593
                    children [
                      USE rolamento
                    ]
                  }
                ]
              }
              physics Physics {
                density -1
                mass 1.532598
                centerOfMass [
                  0.000586 -0.015237 -0.050086
                ]
                inertiaMatrix [
                  0.001610811 0.001393334 0.0006473235
                  1.585238e-06 2.01501e-05 9.715833e-06
                ]
              }
              linearVelocity 1.189560980034916e-07 1.0801186766967894e-09 -1.0522125386231918e-06
              angularVelocity -1.533715596904795e-08 -3.958522846491354e-05 -1.5588213376850203e-05
            }
          }
        ]
        name "conector_calcanhar_2"
        boundingObject Pose {
          translation 0.0212 0.0202 0
          rotation -1 0 0 1.570796
          children [
            USE conector_calcanhar
          ]
        }
        physics Physics {
          density -1
          mass 0.152543
          centerOfMass [
            0.024705 0 -0.006202
          ]
          inertiaMatrix [
            3.117182e-05 0.0002757415 0.0002843804
            3.806312e-13 -3.620273e-07 -2.157674e-13
          ]
        }
        linearVelocity -4.0409286822934157e-07 5.085926442388449e-09 -5.463718969371031e-07
        angularVelocity 1.3460074956185654e-08 5.902654492100459e-09 -1.558927633422922e-05
      }
    }
  ]
  name "Onshape"
  boundingObject Group {
    children [
      Pose {
        translation -0.058713 0.070969 0.149205
        rotation -0.7071067811865476 0 0.7071067811865476 3.141593
        children [
          USE xm_540
        ]
      }
      Pose {
        translation 0.087287 0.013219 0.000455
        rotation 0 -1 0 3.141593
        children [
          DEF tampa_peito Mesh {
            url [
              "/home/lucas/Desktop/RoboFEI/IC/webots_prometheus/protos/tampa_peito.stl"
            ]
          }
        ]
      }
      Pose {
        translation -0.040713 0.057719 -0.021545
        rotation 1 0 0 3.141593
        children [
          USE xm_540
        ]
      }
      Pose {
        translation 0.045287 0.057719 -0.021545
        rotation 1 0 0 3.141593
        children [
          USE xm_540
        ]
      }
      Pose {
        translation 0.053752 0.1765 -0.003545
        rotation -0.5773502691896258 0.5773502691896258 -0.5773502691896258 2.094395
        children [
          DEF tampa_bateria Mesh {
            url [
              "/home/lucas/Desktop/RoboFEI/IC/webots_prometheus/protos/tampa_bateria.stl"
            ]
          }
        ]
      }
      Pose {
        translation -0.052713 0.087219 0.067455
        children [
          DEF peito_esquerda Mesh {
            url [
              "/home/lucas/Desktop/RoboFEI/IC/webots_prometheus/protos/peito_esquerda.stl"
            ]
          }
        ]
      }
      Pose {
        translation -0.009713 0.097219 0.002455
        rotation 0 0 1 3.141593
        children [
          DEF peito_base Mesh {
            url [
              "/home/lucas/Desktop/RoboFEI/IC/webots_prometheus/protos/peito_base.stl"
            ]
          }
        ]
      }
      Pose {
        translation 0.063287 0.070969 0.149205
        rotation 0.7071067811865476 0 0.7071067811865476 3.141593
        children [
          USE xm_540
        ]
      }
      Pose {
        translation -0.047213 0.102776 0.103955
        rotation 0.5773502691896258 -0.5773502691896258 -0.5773502691896258 2.094395
        children [
          DEF hub Mesh {
            url [
              "/home/lucas/Desktop/RoboFEI/IC/webots_prometheus/protos/hub.stl"
            ]
          }
        ]
      }
      Pose {
        translation -0.082713 0.087219 0.067455
        children [
          DEF peito_direita Mesh {
            url [
              "/home/lucas/Desktop/RoboFEI/IC/webots_prometheus/protos/peito_direita.stl"
            ]
          }
        ]
      }
      Pose {
        translation 0.067287 0.150219 0.007455
        rotation 0 0.7071067811865476 0.7071067811865476 3.141593
        children [
          DEF placa_eletrica Mesh {
            url [
              "/home/lucas/Desktop/RoboFEI/IC/webots_prometheus/protos/placa_eletrica.stl"
            ]
          }
        ]
      }
      Pose {
        translation 0.002498 0.048469 0.148955
        rotation 0 0 1 3.141593
        children [
          USE xm_430
        ]
      }
      Pose {
        translation 0.027752 0 0.000455
        rotation -0.5773502691896258 -0.5773502691896258 0.5773502691896258 2.094395
        children [
          DEF bateria1 Mesh {
            url [
              "/home/lucas/Desktop/RoboFEI/IC/webots_prometheus/protos/bateria1.stl"
            ]
          }
        ]
      }
      Pose {
        translation 0.064787 0.152219 0.002455
        rotation 0 0.7071067811865476 0.7071067811865476 3.141593
        children [
          DEF suporte_interno Mesh {
            url [
              "/home/lucas/Desktop/RoboFEI/IC/webots_prometheus/protos/suporte_interno.stl"
            ]
          }
        ]
      }
      Pose {
        translation 0.040252 0.169 -0.012545
        rotation 0 -0.7071067811865476 0.7071067811865476 3.141593
        children [
          DEF bateria2 Mesh {
            url [
              "/home/lucas/Desktop/RoboFEI/IC/webots_prometheus/protos/bateria2.stl"
            ]
          }
        ]
      }
      Pose {
        translation 0.002498 0.090969 0.168455
        rotation -1 0 0 3.141593
        children [
          DEF porta_botao Mesh {
            url [
              "/home/lucas/Desktop/RoboFEI/IC/webots_prometheus/protos/porta_botao.stl"
            ]
          }
        ]
      }
      Pose {
        translation 0.002287 0.029 -0.045545
        children [
          DEF base_baterias Mesh {
            url [
              "/home/lucas/Desktop/RoboFEI/IC/webots_prometheus/protos/base_baterias.stl"
            ]
          }
        ]
      }
      Pose {
        translation -0.054213 0.140219 0.102455
        rotation -1 0 0 1.570796
        children [
          DEF nuc Mesh {
            url [
              "/home/lucas/Desktop/RoboFEI/IC/webots_prometheus/protos/nuc.stl"
            ]
          }
        ]
      }
      Pose {
        translation -0.011713 0.034319 0.121455
        rotation 1 0 0 1.570796
        children [
          DEF imu Mesh {
            url [
              "/home/lucas/Desktop/RoboFEI/IC/webots_prometheus/protos/imu.stl"
            ]
          }
        ]
      }
      Pose {
        translation -0.082713 0.161219 0.000455
        rotation 1 0 0 3.141593
        children [
          USE tampa_peito
        ]
      }
    ]
  }
}
