#VRML_SIM R2023b utf8
# license: Apache License 2.0
# license url: http://www.apache.org/licenses/LICENSE-2.0
# This is a proto file for Webots for the Onshape
# Extracted from: /home/lucas/Desktop/RoboFEI/IC/onshape-to-robot-examples/sigmaban2019/robot.urdf

PROTO Onshape [
  field  SFVec3f     translation     0 0 0
  field  SFRotation  rotation        0 0 1 0
  field  SFString    name            "Onshape"  # Is `Robot.name`.
  field  SFString    controller      "void"     # Is `Robot.controller`.
  field  MFString    controllerArgs  []         # Is `Robot.controllerArgs`.
  field  SFString    customData      ""         # Is `Robot.customData`.
  field  SFBool      supervisor      FALSE      # Is `Robot.supervisor`.
  field  SFBool      synchronization TRUE       # Is `Robot.synchronization`.
  field  SFBool      selfCollision   FALSE      # Is `Robot.selfCollision`.
]
{
  Robot {
    translation IS translation
    rotation IS rotation
    controller IS controller
    controllerArgs IS controllerArgs
    customData IS customData
    supervisor IS supervisor
    synchronization IS synchronization
    selfCollision IS selfCollision
    children [
      Pose {
        translation -0.031000 -0.054127 0.090900
        children [
          Shape {
            appearance DEF pillar_tube_material PBRAppearance {
              baseColor 0.501961 0.486275 0.439216
              roughness 1.000000
              metalness 0
            }
            geometry Cylinder {
              radius 0.004
              height 0.086
            }
          }
        ]
      }
      Pose {
        translation -0.046375 -0.026254 0.020000
        rotation 0.000001 -1.000000 -0.000001 3.141593
        children [
          Shape {
            appearance DEF mx64_material PBRAppearance {
              baseColor 0.211765 0.211765 0.211765
              roughness 1.000000
              metalness 0
            }
            geometry Box {
               size 0.029000 0.050000 0.040000
            }
          }
        ]
      }
      Pose {
        translation 0.050000 -0.017127 0.160900
        rotation -0.707105 -0.000001 -0.707108 3.141591
        children [
          Shape {
            appearance USE mx64_material
            geometry Box {
               size 0.029000 0.050000 0.040000
            }
          }
        ]
      }
      Pose {
        translation 0.046375 -0.026254 0.020000
        rotation 0.000001 -1.000000 -0.000001 3.141593
        children [
          Shape {
            appearance USE mx64_material
            geometry Box {
               size 0.029000 0.050000 0.040000
            }
          }
        ]
      }
      Pose {
        translation 0.000000 0.071323 0.189900
        rotation 0.577350 0.577350 -0.577352 2.094399
        children [
          Shape {
            appearance DEF handle_material PBRAppearance {
              baseColor 0.701961 0.682353 0.623529
              roughness 1.000000
              metalness 0
            }
            geometry Box {
               size 0.010000 0.130000 0.003000
            }
          }
        ]
      }
      Pose {
        translation -0.060000 0.071323 0.164900
        rotation 0.577350 0.577350 -0.577352 2.094399
        children [
          Shape {
            appearance USE handle_material
            geometry Box {
               size 0.040000 0.010000 0.003000
            }
          }
        ]
      }
      Pose {
        translation 0.060000 0.071323 0.164900
        rotation 0.577350 0.577350 -0.577352 2.094399
        children [
          Shape {
            appearance USE handle_material
            geometry Box {
               size 0.040000 0.010000 0.003000
            }
          }
        ]
      }
      Pose {
        translation 0.062500 0.037873 0.090900
        rotation -1.000000 -0.000000 0.000000 3.141590
        children [
          Shape {
            appearance USE pillar_tube_material
            geometry Cylinder {
              radius 0.004
              height 0.086
            }
          }
        ]
      }
      Pose {
        translation -0.050587 -0.017127 0.160900
        rotation 0.707105 0.000001 -0.707108 3.141591
        children [
          Shape {
            appearance USE mx64_material
            geometry Box {
               size 0.029000 0.050000 0.040000
            }
          }
        ]
      }
      Pose {
        translation 0.000000 -0.019127 0.135400
        rotation 0.000001 -1.000000 -0.000001 3.141593
        children [
          Shape {
            appearance DEF torso_top_plate_nuc_material PBRAppearance {
              baseColor 0.301961 0.301961 0.301961
              roughness 1.000000
              metalness 0
            }
            geometry Box {
               size 0.130000 0.080000 0.003000
            }
          }
        ]
      }
      Pose {
        translation 0.000000 0.010373 0.046900
        children [
          Shape {
            appearance DEF torso_middle_plate_nuc_material PBRAppearance {
              baseColor 0.301961 0.301961 0.301961
              roughness 1.000000
              metalness 0
            }
            geometry Box {
               size 0.130000 0.080000 0.003000
            }
          }
        ]
      }
      Pose {
        translation -0.062500 0.037873 0.090900
        children [
          Shape {
            appearance USE pillar_tube_material
            geometry Cylinder {
              radius 0.004
              height 0.086
            }
          }
        ]
      }
      Pose {
        translation 0.000000 0.035873 0.106150
        rotation 0.000001 -0.707108 -0.707105 3.141591
        children [
          Shape {
            appearance DEF nuc_material PBRAppearance {
              baseColor 0.301961 0.290196 0.262745
              roughness 1.000000
              metalness 0
            }
            geometry Box {
               size 0.110000 0.110000 0.033000
            }
          }
        ]
      }
      Pose {
        translation 0.000000 0.031123 0.001500
        children [
          Shape {
            appearance DEF torso_bottom_plate_nuc_material PBRAppearance {
              baseColor 0.400000 0.400000 0.400000
              roughness 1.000000
              metalness 0
            }
            geometry Box {
               size 0.130000 0.044000 0.003000
            }
          }
        ]
      }
      Pose {
        translation -0.030000 -0.007877 0.001500
        children [
          Shape {
            appearance USE torso_bottom_plate_nuc_material
            geometry Box {
               size 0.010000 0.035000 0.003000
            }
          }
        ]
      }
      Pose {
        translation 0.030000 -0.007877 0.001500
        children [
          Shape {
            appearance USE torso_bottom_plate_nuc_material
            geometry Box {
               size 0.010000 0.035000 0.003000
            }
          }
        ]
      }
      Pose {
        translation 0.000000 0.059373 0.138400
        rotation -0.707105 0.707108 -0.000001 3.141591
        children [
          Shape {
            appearance DEF nuc_fix_material PBRAppearance {
              baseColor 0.301961 0.301961 0.301961
              roughness 1.000000
              metalness 0
            }
            geometry Box {
               size 0.010000 0.135000 0.003000
            }
          }
        ]
      }
      Pose {
        translation 0.000000 -0.022127 0.162300
        rotation -0.000000 -0.000000 -1.000000 3.141590
        children [
          Shape {
            appearance USE mx64_material
            geometry Box {
               size 0.029000 0.050000 0.040000
            }
          }
        ]
      }
      Pose {
        translation 0.031000 -0.054127 0.091400
        children [
          Shape {
            appearance USE pillar_tube_material
            geometry Cylinder {
              radius 0.004
              height 0.086
            }
          }
        ]
      }
      HingeJoint {
        jointParameters HingeJointParameters {
          axis -0.000003 -0.000000 1.000000
          anchor -0.046375 -0.011254 -0.003500
        }
        device [
          RotationalMotor {
            name "right_hip_yaw"
            maxVelocity 6.0
            maxTorque 10.0
          }
          PositionSensor {
            name "right_hip_yaw_sensor"
          }
        ]
        endPoint Solid {
          translation -0.046375 -0.011254 -0.003500
          rotation 0.707105 0.707108 0.000001 3.141591
          children [
            Pose {
              translation -0.004940 0.000000 0.003000
              children [
                Shape {
                  appearance DEF u_base_motors_blocs_material PBRAppearance {
                    baseColor 0.301961 0.301961 0.301961
                    roughness 1.000000
                    metalness 0
                  }
                  geometry Box {
                     size 0.050000 0.030000 0.006000
                  }
                }
              ]
            }
            Pose {
              translation -0.031440 0.000000 0.023000
              rotation 0.577350 0.577352 0.577350 2.094399
              children [
                Shape {
                  appearance DEF u_side_small_material PBRAppearance {
                    baseColor 0.301961 0.301961 0.301961
                    roughness 1.000000
                    metalness 0
                  }
                  geometry Box {
                     size 0.025000 0.044000 0.003000
                  }
                }
              ]
            }
            Pose {
              translation 0.021900 -0.000000 0.023000
              rotation 0.577350 -0.577352 -0.577350 2.094399
              children [
                Shape {
                  appearance DEF u_side_small_with_trace_material PBRAppearance {
                    baseColor 0.301961 0.301961 0.301961
                    roughness 1.000000
                    metalness 0
                  }
                  geometry Box {
                     size 0.027000 0.042000 0.003000
                  }
                }
              ]
            }
            HingeJoint {
              jointParameters HingeJointParameters {
                axis -1.000000 -0.000004 -0.000004
                anchor 0.023400 -0.000000 0.040000
              }
              device [
                RotationalMotor {
                  name "right_hip_roll"
                  maxVelocity 6.0
                  maxTorque 10.0
                }
                PositionSensor {
                  name "right_hip_roll_sensor"
                }
              ]
              endPoint Solid {
                translation 0.023400 -0.000000 0.040000
                rotation -0.577350 -0.577352 0.577350 2.094399
                children [
                  Pose {
                    translation -0.000000 -0.015000 0.023400
                    rotation 0.000000 -1.000000 0.000000 1.570800
                    children [
                      Shape {
                        appearance DEF mx106_material PBRAppearance {
                          baseColor 0.301961 0.301961 0.301961
                          roughness 1.000000
                          metalness 0
                        }
                        geometry Box {
                           size 0.030000 0.055000 0.040000
                        }
                      }
                    ]
                  }
                  Pose {
                    translation 0.000000 -0.015000 -0.026000
                    children [
                      Shape {
                        appearance USE mx106_material
                        geometry Box {
                           size 0.030000 0.055000 0.040000
                        }
                      }
                    ]
                  }
                  HingeJoint {
                    jointParameters HingeJointParameters {
                      axis 1.000000 0.000000 -0.000004
                      anchor -0.026000 -0.000000 0.023400
                    }
                    device [
                      RotationalMotor {
                        name "right_hip_pitch"
                        maxVelocity 6.0
                        maxTorque 10.0
                      }
                      PositionSensor {
                        name "right_hip_pitch_sensor"
                      }
                    ]
                    endPoint Solid {
                      translation -0.026000 -0.000000 0.023400
                      rotation -0.000000 1.000000 0.000000 1.570800
                      children [
                        Pose {
                          translation 0.000000 -0.039500 0.053500
                          children [
                            Shape {
                              appearance DEF u_side_femur_mir_material PBRAppearance {
                                baseColor 0.301961 0.301961 0.301961
                                roughness 1.000000
                                metalness 0
                              }
                              geometry Box {
                                 size 0.040000 0.090000 0.003000
                              }
                            }
                          ]
                        }
                        Pose {
                          translation 0.000000 -0.125000 0.026000
                          rotation -1.000000 -0.000000 -0.000000 3.141590
                          children [
                            Shape {
                              appearance USE mx106_material
                              geometry Box {
                                 size 0.030000 0.055000 0.040000
                              }
                            }
                          ]
                        }
                        Pose {
                          translation 0.000000 -0.039500 -0.001500
                          children [
                            Shape {
                              appearance DEF u_side_femur_material PBRAppearance {
                                baseColor 0.301961 0.301961 0.301961
                                roughness 1.000000
                                metalness 0
                              }
                              geometry Box {
                                 size 0.040000 0.090000 0.003000
                              }
                            }
                          ]
                        }
                        Pose {
                          translation 0.000000 -0.082500 0.026000
                          rotation -0.577350 0.577350 0.577352 2.094399
                          children [
                            Shape {
                              appearance DEF u_base_64_material PBRAppearance {
                                baseColor 0.301961 0.301961 0.301961
                                roughness 1.000000
                                metalness 0
                              }
                              geometry Box {
                                 size 0.047000 0.027500 0.006000
                              }
                            }
                          ]
                        }
                        HingeJoint {
                          jointParameters HingeJointParameters {
                            axis 0.000000 -0.000003 1.000000
                            anchor 0.000000 -0.140000 0.000000
                          }
                          device [
                            RotationalMotor {
                              name "right_knee"
                              maxVelocity 6.0
                              maxTorque 10.0
                            }
                            PositionSensor {
                              name "right_knee_sensor"
                            }
                          ]
                          endPoint Solid {
                            translation 0.000000 -0.140000 0.000000
                            rotation 0.000001 -1.000000 -0.000001 3.141593
                            children [
                              Pose {
                                translation -0.000000 -0.067000 0.001500
                                children [
                                  Shape {
                                    appearance DEF tibia_plate_material PBRAppearance {
                                      baseColor 0.301961 0.301961 0.301961
                                      roughness 1.000000
                                      metalness 0
                                    }
                                    geometry Box {
                                       size 0.030000 0.165000 0.003000
                                    }
                                  }
                                ]
                              }
                              Pose {
                                translation 0.000000 -0.067000 -0.053500
                                children [
                                  Shape {
                                    appearance USE tibia_plate_material
                                    geometry Box {
                                       size 0.030000 0.165000 0.003000
                                    }
                                  }
                                ]
                              }
                              HingeJoint {
                                jointParameters HingeJointParameters {
                                  axis -0.000000 0.000000 -1.000000
                                  anchor 0.000000 -0.140000 0.000000
                                }
                                device [
                                  RotationalMotor {
                                    name "right_ankle_pitch"
                                    maxVelocity 6.0
                                    maxTorque 10.0
                                  }
                                  PositionSensor {
                                    name "right_ankle_pitch_sensor"
                                  }
                                ]
                                endPoint Solid {
                                  translation 0.000000 -0.140000 0.000000
                                  rotation 0.000000 -0.000000 1.000000 3.141590
                                  children [
                                    Pose {
                                      translation 0.000000 -0.015000 -0.026000
                                      children [
                                        Shape {
                                          appearance USE mx106_material
                                          geometry Box {
                                             size 0.030000 0.055000 0.040000
                                          }
                                        }
                                      ]
                                    }
                                    Pose {
                                      translation 0.049400 -0.015000 -0.026000
                                      rotation 0.000000 -1.000000 0.000000 1.570800
                                      children [
                                        Shape {
                                          appearance USE mx106_material
                                          geometry Box {
                                             size 0.030000 0.055000 0.040000
                                          }
                                        }
                                      ]
                                    }
                                    HingeJoint {
                                      jointParameters HingeJointParameters {
                                        axis -1.000000 -0.000003 0.000004
                                        anchor 0.023400 -0.000000 -0.026000
                                      }
                                      device [
                                        RotationalMotor {
                                          name "right_ankle_roll"
                                          maxVelocity 6.0
                                          maxTorque 10.0
                                        }
                                        PositionSensor {
                                          name "right_ankle_roll_sensor"
                                        }
                                      ]
                                      endPoint Solid {
                                        translation 0.023400 -0.000000 -0.026000
                                        rotation 0.707105 0.000001 -0.707108 3.141591
                                        children [
                                          Pose {
                                            translation -0.043500 -0.050000 -0.032130
                                            rotation -0.070673 -0.705340 0.705337 3.282702
                                            children [
                                              Shape {
                                                appearance DEF cleat_material PBRAppearance {
                                                  baseColor 0.301961 0.290196 0.262745
                                                  roughness 1.000000
                                                  metalness 0
                                                }
                                                geometry Cylinder {
                                                  radius 0.008
                                                  height 0.02
                                                }
                                              }
                                            ]
                                          }
                                          Pose {
                                            translation -0.043500 -0.050000 0.109470
                                            rotation -0.070673 -0.705340 0.705337 3.282702
                                            children [
                                              Shape {
                                                appearance USE cleat_material
                                                geometry Cylinder {
                                                  radius 0.008
                                                  height 0.02
                                                }
                                              }
                                            ]
                                          }
                                          Pose {
                                            translation 0.000000 -0.017000 0.054840
                                            rotation -0.000001 -1.000000 0.000001 3.141593
                                            children [
                                              Shape {
                                                appearance USE u_side_small_material
                                                geometry Box {
                                                   size 0.025000 0.044000 0.003000
                                                }
                                              }
                                            ]
                                          }
                                          Pose {
                                            translation 0.032500 -0.050000 0.109470
                                            rotation 0.927512 0.264311 -0.264312 1.645979
                                            children [
                                              Shape {
                                                appearance USE cleat_material
                                                geometry Cylinder {
                                                  radius 0.008
                                                  height 0.02
                                                }
                                              }
                                            ]
                                          }
                                          Pose {
                                            translation -0.005500 -0.041500 0.038670
                                            rotation 0.000001 0.707108 0.707105 3.141591
                                            children [
                                              Shape {
                                                appearance DEF foot_plate_material PBRAppearance {
                                                  baseColor 0.301961 0.301961 0.301961
                                                  roughness 1.000000
                                                  metalness 0
                                                }
                                                geometry Box {
                                                   size 0.090000 0.155000 0.003000
                                                }
                                              }
                                            ]
                                          }
                                          Pose {
                                            translation 0.000000 -0.017000 0.001500
                                            children [
                                              Shape {
                                                appearance USE u_side_small_with_trace_material
                                                geometry Box {
                                                   size 0.027000 0.042000 0.003000
                                                }
                                              }
                                            ]
                                          }
                                          Pose {
                                            translation 0.032500 -0.050000 -0.032130
                                            rotation 0.976227 -0.153267 0.153267 1.594858
                                            children [
                                              Shape {
                                                appearance USE cleat_material
                                                geometry Cylinder {
                                                  radius 0.008
                                                  height 0.02
                                                }
                                              }
                                            ]
                                          }
                                          Pose {
                                            translation -0.005500 -0.027500 0.122470
                                            rotation 0.678597 -0.678599 -0.281085 3.689620
                                            children [
                                              Shape {
                                                appearance DEF foot_protection_material PBRAppearance {
                                                  baseColor 0.301961 0.290196 0.262745
                                                  roughness 1.000000
                                                  metalness 0
                                                }
                                                geometry Box {
                                                   size 0.010000 0.090000 0.010000
                                                }
                                              }
                                            ]
                                          }
                                          Pose {
                                            translation 0.000000 -0.037000 0.028340
                                            rotation -0.577350 0.577350 0.577352 2.094399
                                            children [
                                              Shape {
                                                appearance USE u_base_motors_blocs_material
                                                geometry Box {
                                                   size 0.050000 0.030000 0.006000
                                                }
                                              }
                                            ]
                                          }
                                        ]
                                        name "right_foot_cleat_back_left"
                                        boundingObject Group {
                                          children [
                                            Pose {
                                              translation -0.043500 -0.050000 -0.032130
                                              rotation -0.070673 -0.705340 0.705337 3.282702
                                              children [
                                                Cylinder {
                                                  radius 0.008
                                                  height 0.02
                                                }
                                              ]
                                            }
                                            Pose {
                                              translation -0.043500 -0.050000 0.109470
                                              rotation -0.070673 -0.705340 0.705337 3.282702
                                              children [
                                                Cylinder {
                                                  radius 0.008
                                                  height 0.02
                                                }
                                              ]
                                            }
                                            Pose {
                                              translation 0.000000 -0.017000 0.054840
                                              rotation -0.000001 -1.000000 0.000001 3.141593
                                              children [
                                                Box {
                                                   size 0.025000 0.044000 0.003000
                                                }
                                              ]
                                            }
                                            Pose {
                                              translation 0.032500 -0.050000 0.109470
                                              rotation 0.927512 0.264311 -0.264312 1.645979
                                              children [
                                                Cylinder {
                                                  radius 0.008
                                                  height 0.02
                                                }
                                              ]
                                            }
                                            Pose {
                                              translation -0.005500 -0.041500 0.038670
                                              rotation 0.000001 0.707108 0.707105 3.141591
                                              children [
                                                Box {
                                                   size 0.090000 0.155000 0.003000
                                                }
                                              ]
                                            }
                                            Pose {
                                              translation 0.000000 -0.017000 0.001500
                                              children [
                                                Box {
                                                   size 0.027000 0.042000 0.003000
                                                }
                                              ]
                                            }
                                            Pose {
                                              translation 0.032500 -0.050000 -0.032130
                                              rotation 0.976227 -0.153267 0.153267 1.594858
                                              children [
                                                Cylinder {
                                                  radius 0.008
                                                  height 0.02
                                                }
                                              ]
                                            }
                                            Pose {
                                              translation -0.005500 -0.027500 0.122470
                                              rotation 0.678597 -0.678599 -0.281085 3.689620
                                              children [
                                                Box {
                                                   size 0.010000 0.090000 0.010000
                                                }
                                              ]
                                            }
                                            Pose {
                                              translation 0.000000 -0.037000 0.028340
                                              rotation -0.577350 0.577350 0.577352 2.094399
                                              children [
                                                Box {
                                                   size 0.050000 0.030000 0.006000
                                                }
                                              ]
                                            }
                                          ]
                                        }
                                        physics Physics {
                                          density -1
                                          mass 0.239067
                                          centerOfMass [ -0.004685 -0.036578 0.051153 ]
                                          inertiaMatrix [
                                            6.447360e-04 7.808750e-04 1.957110e-04
                                            -2.730760e-06 4.226380e-06 -2.653670e-05
                                          ]
                                        }
                                      }
                                    }
                                  ]
                                  name "mx106_block_1"
                                  boundingObject Group {
                                    children [
                                      Pose {
                                        translation 0.000000 -0.015000 -0.026000
                                        children [
                                          Box {
                                             size 0.030000 0.055000 0.040000
                                          }
                                        ]
                                      }
                                      Pose {
                                        translation 0.049400 -0.015000 -0.026000
                                        rotation 0.000000 -1.000000 0.000000 1.570800
                                        children [
                                          Box {
                                             size 0.030000 0.055000 0.040000
                                          }
                                        ]
                                      }
                                    ]
                                  }
                                  physics Physics {
                                    density -1
                                    mass 0.427481
                                    centerOfMass [ 0.019588 -0.018098 -0.025825 ]
                                    inertiaMatrix [
                                      1.946820e-04 4.101910e-04 4.859250e-04
                                      1.888610e-05 4.223170e-07 -2.224930e-06
                                    ]
                                  }
                                }
                              }
                            ]
                            name "tibia_1"
                            boundingObject Group {
                              children [
                                Pose {
                                  translation -0.000000 -0.067000 0.001500
                                  children [
                                    Box {
                                       size 0.030000 0.165000 0.003000
                                    }
                                  ]
                                }
                                Pose {
                                  translation 0.000000 -0.067000 -0.053500
                                  children [
                                    Box {
                                       size 0.030000 0.165000 0.003000
                                    }
                                  ]
                                }
                              ]
                            }
                            physics Physics {
                              density -1
                              mass 0.088844
                              centerOfMass [ -0.003422 -0.064607 -0.026000 ]
                              inertiaMatrix [
                                2.452470e-04 7.672550e-05 1.874630e-04
                                6.127190e-06 -1.442860e-11 3.806600e-11
                              ]
                            }
                          }
                        }
                      ]
                      name "right_knee_1"
                      boundingObject Group {
                        children [
                          Pose {
                            translation 0.000000 -0.039500 0.053500
                            children [
                              Box {
                                 size 0.040000 0.090000 0.003000
                              }
                            ]
                          }
                          Pose {
                            translation 0.000000 -0.125000 0.026000
                            rotation -1.000000 -0.000000 -0.000000 3.141590
                            children [
                              Box {
                                 size 0.030000 0.055000 0.040000
                              }
                            ]
                          }
                          Pose {
                            translation 0.000000 -0.039500 -0.001500
                            children [
                              Box {
                                 size 0.040000 0.090000 0.003000
                              }
                            ]
                          }
                          Pose {
                            translation 0.000000 -0.082500 0.026000
                            rotation -0.577350 0.577350 0.577352 2.094399
                            children [
                              Box {
                                 size 0.047000 0.027500 0.006000
                              }
                            ]
                          }
                        ]
                      }
                      physics Physics {
                        density -1
                        mass 0.269758
                        centerOfMass [ 0.000224 -0.098034 0.025713 ]
                        inertiaMatrix [
                          5.035950e-04 1.099410e-04 4.386440e-04
                          9.058650e-07 -4.567790e-07 -5.721190e-06
                        ]
                      }
                    }
                  }
                ]
                name "mx106_block_mir_1"
                boundingObject Group {
                  children [
                    Pose {
                      translation -0.000000 -0.015000 0.023400
                      rotation 0.000000 -1.000000 0.000000 1.570800
                      children [
                        Box {
                           size 0.030000 0.055000 0.040000
                        }
                      ]
                    }
                    Pose {
                      translation 0.000000 -0.015000 -0.026000
                      children [
                        Box {
                           size 0.030000 0.055000 0.040000
                        }
                      ]
                    }
                  ]
                }
                physics Physics {
                  density -1
                  mass 0.427481
                  centerOfMass [ -0.000304 -0.018098 0.003917 ]
                  inertiaMatrix [
                    4.822080e-04 4.083920e-04 2.036710e-04
                    -1.577920e-05 3.503960e-06 -3.688370e-05
                  ]
                }
              }
            }
          ]
          name "u_block_1"
          boundingObject Group {
            children [
              Pose {
                translation -0.004940 0.000000 0.003000
                children [
                  Box {
                     size 0.050000 0.030000 0.006000
                  }
                ]
              }
              Pose {
                translation -0.031440 0.000000 0.023000
                rotation 0.577350 0.577352 0.577350 2.094399
                children [
                  Box {
                     size 0.025000 0.044000 0.003000
                  }
                ]
              }
              Pose {
                translation 0.021900 -0.000000 0.023000
                rotation 0.577350 -0.577352 -0.577350 2.094399
                children [
                  Box {
                     size 0.027000 0.042000 0.003000
                  }
                ]
              }
            ]
          }
          physics Physics {
            density -1
            mass 0.035440
            centerOfMass [ -0.006070 0.000000 0.011765 ]
            inertiaMatrix [
              6.023600e-06 2.434300e-05 2.132800e-05
              -2.059660e-08 7.974420e-07 -8.886030e-13
            ]
          }
        }
      }
      HingeJoint {
        jointParameters HingeJointParameters {
          axis 0.000003 0.000000 1.000000
          anchor 0.046375 -0.011254 -0.003500
        }
        device [
          RotationalMotor {
            name "left_hip_yaw"
            maxVelocity 6.0
            maxTorque 10.0
          }
          PositionSensor {
            name "left_hip_yaw_sensor"
          }
        ]
        endPoint Solid {
          translation 0.046375 -0.011254 -0.003500
          rotation -0.707105 -0.707108 0.000001 3.141591
          children [
            Pose {
              translation -0.004940 -0.000000 0.003000
              children [
                Shape {
                  appearance USE u_base_motors_blocs_material
                  geometry Box {
                     size 0.050000 0.030000 0.006000
                  }
                }
              ]
            }
            Pose {
              translation 0.021900 -0.000000 0.023000
              rotation 0.577350 -0.577352 -0.577350 2.094399
              children [
                Shape {
                  appearance USE u_side_small_with_trace_material
                  geometry Box {
                     size 0.027000 0.042000 0.003000
                  }
                }
              ]
            }
            Pose {
              translation -0.031440 -0.000000 0.023000
              rotation 0.577350 0.577352 0.577350 2.094399
              children [
                Shape {
                  appearance USE u_side_small_material
                  geometry Box {
                     size 0.025000 0.044000 0.003000
                  }
                }
              ]
            }
            HingeJoint {
              jointParameters HingeJointParameters {
                axis -1.000000 -0.000004 -0.000004
                anchor 0.023400 -0.000000 0.040000
              }
              device [
                RotationalMotor {
                  name "left_hip_roll"
                  maxVelocity 6.0
                  maxTorque 10.0
                }
                PositionSensor {
                  name "left_hip_roll_sensor"
                }
              ]
              endPoint Solid {
                translation 0.023400 -0.000000 0.040000
                rotation -0.577350 -0.577352 0.577350 2.094399
                children [
                  Pose {
                    translation -0.000000 -0.015000 -0.026000
                    children [
                      Shape {
                        appearance USE mx106_material
                        geometry Box {
                           size 0.030000 0.055000 0.040000
                        }
                      }
                    ]
                  }
                  Pose {
                    translation -0.000000 -0.015000 0.023400
                    rotation -0.000000 1.000000 0.000000 1.570800
                    children [
                      Shape {
                        appearance USE mx106_material
                        geometry Box {
                           size 0.030000 0.055000 0.040000
                        }
                      }
                    ]
                  }
                  HingeJoint {
                    jointParameters HingeJointParameters {
                      axis 1.000000 0.000000 0.000004
                      anchor 0.026000 0.000000 0.023400
                    }
                    device [
                      RotationalMotor {
                        name "left_hip_pitch"
                        maxVelocity 6.0
                        maxTorque 10.0
                      }
                      PositionSensor {
                        name "left_hip_pitch_sensor"
                      }
                    ]
                    endPoint Solid {
                      translation 0.026000 0.000000 0.023400
                      rotation 0.000000 -1.000000 0.000000 1.570800
                      children [
                        Pose {
                          translation 0.000000 -0.082500 0.026000
                          rotation -0.577350 0.577350 0.577352 2.094399
                          children [
                            Shape {
                              appearance USE u_base_64_material
                              geometry Box {
                                 size 0.047000 0.027500 0.006000
                              }
                            }
                          ]
                        }
                        Pose {
                          translation 0.000000 -0.039500 -0.001500
                          children [
                            Shape {
                              appearance USE u_side_femur_material
                              geometry Box {
                                 size 0.040000 0.090000 0.003000
                              }
                            }
                          ]
                        }
                        Pose {
                          translation 0.000000 -0.039500 0.053500
                          children [
                            Shape {
                              appearance USE u_side_femur_mir_material
                              geometry Box {
                                 size 0.040000 0.090000 0.003000
                              }
                            }
                          ]
                        }
                        Pose {
                          translation -0.000000 -0.125000 0.026000
                          rotation -1.000000 0.000000 0.000000 3.141590
                          children [
                            Shape {
                              appearance USE mx106_material
                              geometry Box {
                                 size 0.030000 0.055000 0.040000
                              }
                            }
                          ]
                        }
                        HingeJoint {
                          jointParameters HingeJointParameters {
                            axis -0.000000 -0.000000 -1.000000
                            anchor -0.000000 -0.140000 -0.000000
                          }
                          device [
                            RotationalMotor {
                              name "left_knee"
                              maxVelocity 6.0
                              maxTorque 10.0
                            }
                            PositionSensor {
                              name "left_knee_sensor"
                            }
                          ]
                          endPoint Solid {
                            translation -0.000000 -0.140000 -0.000000
                            children [
                              Pose {
                                translation -0.000000 -0.067000 -0.001500
                                children [
                                  Shape {
                                    appearance USE tibia_plate_material
                                    geometry Box {
                                       size 0.030000 0.165000 0.003000
                                    }
                                  }
                                ]
                              }
                              Pose {
                                translation 0.000000 -0.067000 0.053500
                                children [
                                  Shape {
                                    appearance USE tibia_plate_material
                                    geometry Box {
                                       size 0.030000 0.165000 0.003000
                                    }
                                  }
                                ]
                              }
                              HingeJoint {
                                jointParameters HingeJointParameters {
                                  axis -0.000000 -0.000003 -1.000000
                                  anchor 0.000000 -0.140000 0.000000
                                }
                                device [
                                  RotationalMotor {
                                    name "left_ankle_pitch"
                                    maxVelocity 6.0
                                    maxTorque 10.0
                                  }
                                  PositionSensor {
                                    name "left_ankle_pitch_sensor"
                                  }
                                ]
                                endPoint Solid {
                                  translation 0.000000 -0.140000 0.000000
                                  rotation 1.000000 0.000000 -0.000000 3.141590
                                  children [
                                    Pose {
                                      translation 0.000000 -0.015000 -0.026000
                                      children [
                                        Shape {
                                          appearance USE mx106_material
                                          geometry Box {
                                             size 0.030000 0.055000 0.040000
                                          }
                                        }
                                      ]
                                    }
                                    Pose {
                                      translation -0.049400 -0.015000 -0.026000
                                      rotation -0.000000 1.000000 0.000000 1.570800
                                      children [
                                        Shape {
                                          appearance USE mx106_material
                                          geometry Box {
                                             size 0.030000 0.055000 0.040000
                                          }
                                        }
                                      ]
                                    }
                                    HingeJoint {
                                      jointParameters HingeJointParameters {
                                        axis 1.000000 0.000003 0.000004
                                        anchor -0.023400 -0.000000 -0.026000
                                      }
                                      device [
                                        RotationalMotor {
                                          name "left_ankle_roll"
                                          maxVelocity 6.0
                                          maxTorque 10.0
                                        }
                                        PositionSensor {
                                          name "left_ankle_roll_sensor"
                                        }
                                      ]
                                      endPoint Solid {
                                        translation -0.023400 -0.000000 -0.026000
                                        rotation -0.707105 -0.000001 -0.707108 3.141591
                                        children [
                                          Pose {
                                            translation 0.005500 -0.027500 0.122470
                                            rotation -0.678597 0.678600 0.281083 2.593562
                                            children [
                                              Shape {
                                                appearance USE foot_protection_material
                                                geometry Box {
                                                   size 0.010000 0.090000 0.010000
                                                }
                                              }
                                            ]
                                          }
                                          Pose {
                                            translation 0.043500 -0.050000 -0.032130
                                            rotation -0.170700 -0.696730 0.696728 3.479730
                                            children [
                                              Shape {
                                                appearance USE cleat_material
                                                geometry Cylinder {
                                                  radius 0.008
                                                  height 0.02
                                                }
                                              }
                                            ]
                                          }
                                          Pose {
                                            translation -0.000000 -0.017000 0.054840
                                            rotation -0.000001 1.000000 -0.000001 3.141593
                                            children [
                                              Shape {
                                                appearance USE u_side_small_material
                                                geometry Box {
                                                   size 0.025000 0.044000 0.003000
                                                }
                                              }
                                            ]
                                          }
                                          Pose {
                                            translation 0.043500 -0.050000 0.109470
                                            rotation -0.170700 -0.696730 0.696728 3.479730
                                            children [
                                              Shape {
                                                appearance USE cleat_material
                                                geometry Cylinder {
                                                  radius 0.008
                                                  height 0.02
                                                }
                                              }
                                            ]
                                          }
                                          Pose {
                                            translation -0.000000 -0.037000 0.028340
                                            rotation -0.577350 0.577350 0.577352 2.094399
                                            children [
                                              Shape {
                                                appearance USE u_base_motors_blocs_material
                                                geometry Box {
                                                   size 0.050000 0.030000 0.006000
                                                }
                                              }
                                            ]
                                          }
                                          Pose {
                                            translation -0.032500 -0.050000 0.109470
                                            rotation -0.170700 -0.696730 0.696728 3.479730
                                            children [
                                              Shape {
                                                appearance USE cleat_material
                                                geometry Cylinder {
                                                  radius 0.008
                                                  height 0.02
                                                }
                                              }
                                            ]
                                          }
                                          Pose {
                                            translation -0.032500 -0.050000 -0.032130
                                            rotation 0.170698 0.696730 -0.696727 2.803451
                                            children [
                                              Shape {
                                                appearance USE cleat_material
                                                geometry Cylinder {
                                                  radius 0.008
                                                  height 0.02
                                                }
                                              }
                                            ]
                                          }
                                          Pose {
                                            translation 0.000000 -0.017000 0.001500
                                            children [
                                              Shape {
                                                appearance USE u_side_small_with_trace_material
                                                geometry Box {
                                                   size 0.027000 0.042000 0.003000
                                                }
                                              }
                                            ]
                                          }
                                          Pose {
                                            translation 0.005500 -0.041500 0.038670
                                            rotation 0.000001 -0.707108 -0.707105 3.141591
                                            children [
                                              Shape {
                                                appearance USE foot_plate_material
                                                geometry Box {
                                                   size 0.090000 0.155000 0.003000
                                                }
                                              }
                                            ]
                                          }
                                        ]
                                        name "left_foot_cleat_front_right"
                                        boundingObject Group {
                                          children [
                                            Pose {
                                              translation 0.005500 -0.027500 0.122470
                                              rotation -0.678597 0.678600 0.281083 2.593562
                                              children [
                                                Box {
                                                   size 0.010000 0.090000 0.010000
                                                }
                                              ]
                                            }
                                            Pose {
                                              translation 0.043500 -0.050000 -0.032130
                                              rotation -0.170700 -0.696730 0.696728 3.479730
                                              children [
                                                Cylinder {
                                                  radius 0.008
                                                  height 0.02
                                                }
                                              ]
                                            }
                                            Pose {
                                              translation -0.000000 -0.017000 0.054840
                                              rotation -0.000001 1.000000 -0.000001 3.141593
                                              children [
                                                Box {
                                                   size 0.025000 0.044000 0.003000
                                                }
                                              ]
                                            }
                                            Pose {
                                              translation 0.043500 -0.050000 0.109470
                                              rotation -0.170700 -0.696730 0.696728 3.479730
                                              children [
                                                Cylinder {
                                                  radius 0.008
                                                  height 0.02
                                                }
                                              ]
                                            }
                                            Pose {
                                              translation -0.000000 -0.037000 0.028340
                                              rotation -0.577350 0.577350 0.577352 2.094399
                                              children [
                                                Box {
                                                   size 0.050000 0.030000 0.006000
                                                }
                                              ]
                                            }
                                            Pose {
                                              translation -0.032500 -0.050000 0.109470
                                              rotation -0.170700 -0.696730 0.696728 3.479730
                                              children [
                                                Cylinder {
                                                  radius 0.008
                                                  height 0.02
                                                }
                                              ]
                                            }
                                            Pose {
                                              translation -0.032500 -0.050000 -0.032130
                                              rotation 0.170698 0.696730 -0.696727 2.803451
                                              children [
                                                Cylinder {
                                                  radius 0.008
                                                  height 0.02
                                                }
                                              ]
                                            }
                                            Pose {
                                              translation 0.000000 -0.017000 0.001500
                                              children [
                                                Box {
                                                   size 0.027000 0.042000 0.003000
                                                }
                                              ]
                                            }
                                            Pose {
                                              translation 0.005500 -0.041500 0.038670
                                              rotation 0.000001 -0.707108 -0.707105 3.141591
                                              children [
                                                Box {
                                                   size 0.090000 0.155000 0.003000
                                                }
                                              ]
                                            }
                                          ]
                                        }
                                        physics Physics {
                                          density -1
                                          mass 0.239067
                                          centerOfMass [ 0.004685 -0.036578 0.051153 ]
                                          inertiaMatrix [
                                            6.447360e-04 7.808740e-04 1.957110e-04
                                            5.212560e-07 -4.226380e-06 -2.653670e-05
                                          ]
                                        }
                                      }
                                    }
                                  ]
                                  name "mx106_block_mir_2"
                                  boundingObject Group {
                                    children [
                                      Pose {
                                        translation 0.000000 -0.015000 -0.026000
                                        children [
                                          Box {
                                             size 0.030000 0.055000 0.040000
                                          }
                                        ]
                                      }
                                      Pose {
                                        translation -0.049400 -0.015000 -0.026000
                                        rotation -0.000000 1.000000 0.000000 1.570800
                                        children [
                                          Box {
                                             size 0.030000 0.055000 0.040000
                                          }
                                        ]
                                      }
                                    ]
                                  }
                                  physics Physics {
                                    density -1
                                    mass 0.427481
                                    centerOfMass [ -0.019483 -0.018098 -0.025696 ]
                                    inertiaMatrix [
                                      1.942610e-04 4.123230e-04 4.876880e-04
                                      -2.048030e-05 -3.716210e-06 -3.980840e-06
                                    ]
                                  }
                                }
                              }
                            ]
                            name "tibia_2"
                            boundingObject Group {
                              children [
                                Pose {
                                  translation -0.000000 -0.067000 -0.001500
                                  children [
                                    Box {
                                       size 0.030000 0.165000 0.003000
                                    }
                                  ]
                                }
                                Pose {
                                  translation 0.000000 -0.067000 0.053500
                                  children [
                                    Box {
                                       size 0.030000 0.165000 0.003000
                                    }
                                  ]
                                }
                              ]
                            }
                            physics Physics {
                              density -1
                              mass 0.088844
                              centerOfMass [ -0.003422 -0.064607 0.026000 ]
                              inertiaMatrix [
                                2.452470e-04 7.672550e-05 1.874630e-04
                                6.127190e-06 -1.442860e-11 3.806600e-11
                              ]
                            }
                          }
                        }
                      ]
                      name "left_knee_1"
                      boundingObject Group {
                        children [
                          Pose {
                            translation 0.000000 -0.082500 0.026000
                            rotation -0.577350 0.577350 0.577352 2.094399
                            children [
                              Box {
                                 size 0.047000 0.027500 0.006000
                              }
                            ]
                          }
                          Pose {
                            translation 0.000000 -0.039500 -0.001500
                            children [
                              Box {
                                 size 0.040000 0.090000 0.003000
                              }
                            ]
                          }
                          Pose {
                            translation 0.000000 -0.039500 0.053500
                            children [
                              Box {
                                 size 0.040000 0.090000 0.003000
                              }
                            ]
                          }
                          Pose {
                            translation -0.000000 -0.125000 0.026000
                            rotation -1.000000 0.000000 0.000000 3.141590
                            children [
                              Box {
                                 size 0.030000 0.055000 0.040000
                              }
                            ]
                          }
                        ]
                      }
                      physics Physics {
                        density -1
                        mass 0.269758
                        centerOfMass [ -0.000057 -0.098034 0.025527 ]
                        inertiaMatrix [
                          5.035570e-04 1.099160e-04 4.386560e-04
                          1.647190e-06 -5.019870e-07 -5.373840e-06
                        ]
                      }
                    }
                  }
                ]
                name "mx106_block_2"
                boundingObject Group {
                  children [
                    Pose {
                      translation -0.000000 -0.015000 -0.026000
                      children [
                        Box {
                           size 0.030000 0.055000 0.040000
                        }
                      ]
                    }
                    Pose {
                      translation -0.000000 -0.015000 0.023400
                      rotation -0.000000 1.000000 0.000000 1.570800
                      children [
                        Box {
                           size 0.030000 0.055000 0.040000
                        }
                      ]
                    }
                  ]
                }
                physics Physics {
                  density -1
                  mass 0.427481
                  centerOfMass [ 0.000175 -0.018098 0.003812 ]
                  inertiaMatrix [
                    4.808750e-04 4.062260e-04 2.036980e-04
                    1.445660e-05 -4.949000e-07 -3.863230e-05
                  ]
                }
              }
            }
          ]
          name "u_block_2"
          boundingObject Group {
            children [
              Pose {
                translation -0.004940 -0.000000 0.003000
                children [
                  Box {
                     size 0.050000 0.030000 0.006000
                  }
                ]
              }
              Pose {
                translation 0.021900 -0.000000 0.023000
                rotation 0.577350 -0.577352 -0.577350 2.094399
                children [
                  Box {
                     size 0.027000 0.042000 0.003000
                  }
                ]
              }
              Pose {
                translation -0.031440 -0.000000 0.023000
                rotation 0.577350 0.577352 0.577350 2.094399
                children [
                  Box {
                     size 0.025000 0.044000 0.003000
                  }
                ]
              }
            ]
          }
          physics Physics {
            density -1
            mass 0.035440
            centerOfMass [ -0.006070 0.000000 0.011765 ]
            inertiaMatrix [
              6.023600e-06 2.434300e-05 2.132800e-05
              -2.059660e-08 7.974420e-07 -8.886030e-13
            ]
          }
        }
      }
      HingeJoint {
        jointParameters HingeJointParameters {
          axis 1.000000 -0.000004 -0.000004
          anchor 0.073500 -0.032127 0.160900
        }
        device [
          RotationalMotor {
            name "left_shoulder_pitch"
            maxVelocity 6.0
            maxTorque 10.0
          }
          PositionSensor {
            name "left_shoulder_pitch_sensor"
          }
        ]
        endPoint Solid {
          translation 0.073500 -0.032127 0.160900
          rotation -0.577350 0.577352 -0.577350 2.094399
          children [
            Pose {
              translation 0.000000 -0.000000 0.003000
              children [
                Shape {
                  appearance USE u_base_64_material
                  geometry Box {
                     size 0.047000 0.027500 0.006000
                  }
                }
              ]
            }
            HingeJoint {
              jointParameters HingeJointParameters {
                axis 1.000000 0.000003 0.000004
                anchor 0.022500 0.030000 0.035000
              }
              device [
                RotationalMotor {
                  name "left_shoulder_roll"
                  maxVelocity 6.0
                  maxTorque 10.0
                }
                PositionSensor {
                  name "left_shoulder_roll_sensor"
                }
              ]
              endPoint Solid {
                translation 0.022500 0.030000 0.035000
                rotation -0.707105 -0.000001 -0.707108 3.141591
                children [
                  Pose {
                    translation -0.000000 -0.015000 -0.023500
                    children [
                      Shape {
                        appearance USE mx64_material
                        geometry Box {
                           size 0.029000 0.050000 0.040000
                        }
                      }
                    ]
                  }
                  Pose {
                    translation -0.000000 -0.092000 -0.039174
                    rotation 0.000000 -1.000000 0.000000 1.570800
                    children [
                      Shape {
                        appearance DEF humerus_plate_material PBRAppearance {
                          baseColor 0.301961 0.301961 0.301961
                          roughness 1.000000
                          metalness 0
                        }
                        geometry Box {
                           size 0.003000 0.070000 0.030000
                        }
                      }
                    ]
                  }
                  Pose {
                    translation -0.000000 -0.054000 -0.023174
                    rotation 0.000000 -1.000000 0.000000 1.570800
                    children [
                      Shape {
                        appearance USE humerus_plate_material
                        geometry Box {
                           size 0.030000 0.003000 0.030000
                        }
                      }
                    ]
                  }
                  HingeJoint {
                    jointParameters HingeJointParameters {
                      axis 1.000000 -0.000000 -0.000004
                      anchor 0.023500 -0.112000 -0.001674
                    }
                    device [
                      RotationalMotor {
                        name "left_elbow"
                        maxVelocity 6.0
                        maxTorque 10.0
                      }
                      PositionSensor {
                        name "left_elbow_sensor"
                      }
                    ]
                    endPoint Solid {
                      translation 0.023500 -0.112000 -0.001674
                      rotation 0.000000 1.000000 -0.000000 1.570800
                      children [
                        Pose {
                          translation -0.000000 -0.015000 -0.023500
                          children [
                            Shape {
                              appearance USE mx64_material
                              geometry Box {
                                 size 0.029000 0.050000 0.040000
                              }
                            }
                          ]
                        }
                        Pose {
                          translation 0.018000 -0.098500 -0.023500
                          rotation -0.000001 -1.000000 0.000001 3.141593
                          children [
                            Shape {
                              appearance DEF radius_plate_material PBRAppearance {
                                baseColor 0.301961 0.301961 0.301961
                                roughness 1.000000
                                metalness 0
                              }
                              geometry Box {
                                 size 0.003000 0.085000 0.030000
                              }
                            }
                          ]
                        }
                        Pose {
                          translation 0.007500 -0.141000 -0.023500
                          rotation -0.000001 -1.000000 0.000001 3.141593
                          children [
                            Shape {
                              appearance USE radius_plate_material
                              geometry Cylinder {
                                radius 0.012
                                height 0.03
                              }
                            }
                          ]
                        }
                      ]
                      name "left_radius_1"
                      boundingObject Group {
                        children [
                          Pose {
                            translation -0.000000 -0.015000 -0.023500
                            children [
                              Box {
                                 size 0.029000 0.050000 0.040000
                              }
                            ]
                          }
                          Pose {
                            translation 0.018000 -0.098500 -0.023500
                            rotation -0.000001 -1.000000 0.000001 3.141593
                            children [
                              Box {
                                 size 0.003000 0.085000 0.030000
                              }
                            ]
                          }
                          Pose {
                            translation 0.007500 -0.141000 -0.023500
                            rotation -0.000001 -1.000000 0.000001 3.141593
                            children [
                              Cylinder {
                                radius 0.012
                                height 0.03
                              }
                            ]
                          }
                        ]
                      }
                      physics Physics {
                        density -1
                        mass 0.206880
                        centerOfMass [ 0.002534 -0.037040 -0.023878 ]
                        inertiaMatrix [
                          3.790300e-04 5.362680e-05 3.637800e-04
                          3.042260e-05 4.208030e-07 -4.790400e-07
                        ]
                      }
                    }
                  }
                ]
                name "left_humerus_1"
                boundingObject Group {
                  children [
                    Pose {
                      translation -0.000000 -0.015000 -0.023500
                      children [
                        Box {
                           size 0.029000 0.050000 0.040000
                        }
                      ]
                    }
                    Pose {
                      translation -0.000000 -0.092000 -0.039174
                      rotation 0.000000 -1.000000 0.000000 1.570800
                      children [
                        Box {
                           size 0.003000 0.070000 0.030000
                        }
                      ]
                    }
                    Pose {
                      translation -0.000000 -0.054000 -0.023174
                      rotation 0.000000 -1.000000 0.000000 1.570800
                      children [
                        Box {
                           size 0.030000 0.003000 0.030000
                        }
                      ]
                    }
                  ]
                }
                physics Physics {
                  density -1
                  mass 0.214223
                  centerOfMass [ -0.000853 -0.037640 -0.024852 ]
                  inertiaMatrix [
                    3.477010e-04 6.511660e-05 3.333020e-04
                    -1.373130e-05 2.972770e-06 -8.640980e-06
                  ]
                }
              }
            }
          ]
          name "u_shoulder_1"
          boundingObject Pose {
            translation 0.000000 -0.000000 0.003000
            children [
              Box {
                 size 0.047000 0.027500 0.006000
              }
            ]
          }
          physics Physics {
            density -1
            mass 0.042898
            centerOfMass [ 0.000000 0.004860 0.016783 ]
            inertiaMatrix [
              1.579910e-05 2.849830e-05 2.500370e-05
              1.592480e-20 -7.273910e-21 -3.761370e-06
            ]
          }
        }
      }
      HingeJoint {
        jointParameters HingeJointParameters {
          axis 1.000000 0.000004 0.000004
          anchor -0.074087 -0.032127 0.160900
        }
        device [
          RotationalMotor {
            name "right_shoulder_pitch"
            maxVelocity 6.0
            maxTorque 10.0
          }
          PositionSensor {
            name "right_shoulder_pitch_sensor"
          }
        ]
        endPoint Solid {
          translation -0.074087 -0.032127 0.160900
          rotation -0.577350 -0.577352 0.577350 2.094399
          children [
            Pose {
              translation 0.000000 -0.000000 0.003000
              children [
                Shape {
                  appearance USE u_base_64_material
                  geometry Box {
                     size 0.047000 0.027500 0.006000
                  }
                }
              ]
            }
            HingeJoint {
              jointParameters HingeJointParameters {
                axis -1.000000 -0.000003 0.000004
                anchor -0.022500 0.030000 0.035000
              }
              device [
                RotationalMotor {
                  name "right_shoulder_roll"
                  maxVelocity 6.0
                  maxTorque 10.0
                }
                PositionSensor {
                  name "right_shoulder_roll_sensor"
                }
              ]
              endPoint Solid {
                translation -0.022500 0.030000 0.035000
                rotation 0.707105 0.000001 -0.707108 3.141591
                children [
                  Pose {
                    translation -0.000000 -0.092000 -0.040000
                    rotation -0.000000 -1.000000 -0.000000 1.570800
                    children [
                      Shape {
                        appearance USE humerus_plate_material
                        geometry Box {
                           size 0.003000 0.070000 0.030000
                        }
                      }
                    ]
                  }
                  Pose {
                    translation 0.000000 -0.054000 -0.024000
                    rotation -0.000000 -1.000000 -0.000000 1.570800
                    children [
                      Shape {
                        appearance USE humerus_plate_material
                        geometry Box {
                           size 0.030000 0.003000 0.030000
                        }
                      }
                    ]
                  }
                  Pose {
                    translation -0.000000 -0.015000 -0.023500
                    children [
                      Shape {
                        appearance USE mx64_material
                        geometry Box {
                           size 0.029000 0.050000 0.040000
                        }
                      }
                    ]
                  }
                  HingeJoint {
                    jointParameters HingeJointParameters {
                      axis 1.000000 -0.000000 0.000004
                      anchor -0.023500 -0.112000 -0.002500
                    }
                    device [
                      RotationalMotor {
                        name "right_elbow"
                        maxVelocity 6.0
                        maxTorque 10.0
                      }
                      PositionSensor {
                        name "right_elbow_sensor"
                      }
                    ]
                    endPoint Solid {
                      translation -0.023500 -0.112000 -0.002500
                      rotation -0.000000 -1.000000 -0.000000 1.570800
                      children [
                        Pose {
                          translation -0.018000 -0.098500 -0.023500
                          children [
                            Shape {
                              appearance USE radius_plate_material
                              geometry Box {
                                 size 0.003000 0.085000 0.030000
                              }
                            }
                          ]
                        }
                        Pose {
                          translation -0.007500 -0.141000 -0.023500
                          children [
                            Shape {
                              appearance USE radius_plate_material
                              geometry Cylinder {
                                radius 0.012
                                height 0.03
                              }
                            }
                          ]
                        }
                        Pose {
                          translation 0.000000 -0.015000 -0.023500
                          children [
                            Shape {
                              appearance USE mx64_material
                              geometry Box {
                                 size 0.029000 0.050000 0.040000
                              }
                            }
                          ]
                        }
                      ]
                      name "right_radius_1"
                      boundingObject Group {
                        children [
                          Pose {
                            translation -0.018000 -0.098500 -0.023500
                            children [
                              Box {
                                 size 0.003000 0.085000 0.030000
                              }
                            ]
                          }
                          Pose {
                            translation -0.007500 -0.141000 -0.023500
                            children [
                              Cylinder {
                                radius 0.012
                                height 0.03
                              }
                            ]
                          }
                          Pose {
                            translation 0.000000 -0.015000 -0.023500
                            children [
                              Box {
                                 size 0.029000 0.050000 0.040000
                              }
                            ]
                          }
                        ]
                      }
                      physics Physics {
                        density -1
                        mass 0.206880
                        centerOfMass [ -0.002335 -0.037040 -0.023635 ]
                        inertiaMatrix [
                          3.790560e-04 5.385220e-05 3.639800e-04
                          -3.241250e-05 7.541430e-07 -9.997150e-09
                        ]
                      }
                    }
                  }
                ]
                name "right_humerus_1"
                boundingObject Group {
                  children [
                    Pose {
                      translation -0.000000 -0.092000 -0.040000
                      rotation -0.000000 -1.000000 -0.000000 1.570800
                      children [
                        Box {
                           size 0.003000 0.070000 0.030000
                        }
                      ]
                    }
                    Pose {
                      translation 0.000000 -0.054000 -0.024000
                      rotation -0.000000 -1.000000 -0.000000 1.570800
                      children [
                        Box {
                           size 0.030000 0.003000 0.030000
                        }
                      ]
                    }
                    Pose {
                      translation -0.000000 -0.015000 -0.023500
                      children [
                        Box {
                           size 0.029000 0.050000 0.040000
                        }
                      ]
                    }
                  ]
                }
                physics Physics {
                  density -1
                  mass 0.214223
                  centerOfMass [ 0.001044 -0.037640 -0.025366 ]
                  inertiaMatrix [
                    3.477880e-04 6.512500e-05 3.332240e-04
                    1.171670e-05 -1.667710e-06 -1.166480e-05
                  ]
                }
              }
            }
          ]
          name "u_shoulder_2"
          boundingObject Pose {
            translation 0.000000 -0.000000 0.003000
            children [
              Box {
                 size 0.047000 0.027500 0.006000
              }
            ]
          }
          physics Physics {
            density -1
            mass 0.042898
            centerOfMass [ 0.000000 0.004860 0.016783 ]
            inertiaMatrix [
              1.579910e-05 2.849830e-05 2.500370e-05
              6.776260e-21 -1.355250e-20 -3.761370e-06
            ]
          }
        }
      }
      HingeJoint {
        jointParameters HingeJointParameters {
          axis 0.000000 0.000000 1.000000
          anchor 0.000000 -0.037127 0.185800
        }
        device [
          RotationalMotor {
            name "head_yaw"
            maxVelocity 6.0
            maxTorque 10.0
          }
          PositionSensor {
            name "head_yaw_sensor"
          }
        ]
        endPoint Solid {
          translation 0.000000 -0.037127 0.185800
          rotation -0.000000 -0.000000 -1.000000 3.141590
          children [
            Pose {
              translation 0.000000 -0.000000 0.003000
              children [
                Shape {
                  appearance USE u_base_64_material
                  geometry Box {
                     size 0.047000 0.027500 0.006000
                  }
                }
              ]
            }
            Pose {
              translation -0.025000 -0.000000 0.023000
              rotation 0.577350 0.577352 0.577350 2.094399
              children [
                Shape {
                  appearance USE u_side_small_material
                  geometry Box {
                     size 0.025000 0.044000 0.003000
                  }
                }
              ]
            }
            Pose {
              translation 0.025000 -0.000000 0.023000
              rotation 0.577350 -0.577352 -0.577350 2.094399
              children [
                Shape {
                  appearance USE u_side_small_material
                  geometry Box {
                     size 0.025000 0.044000 0.003000
                  }
                }
              ]
            }
            HingeJoint {
              jointParameters HingeJointParameters {
                axis -1.000000 -0.000004 -0.000004
                anchor -0.023500 -0.000000 0.040000
              }
              device [
                RotationalMotor {
                  name "head_pitch"
                  maxVelocity 6.0
                  maxTorque 10.0
                }
                PositionSensor {
                  name "head_pitch_sensor"
                }
              ]
              endPoint Solid {
                translation -0.023500 -0.000000 0.040000
                rotation -0.577350 -0.577352 0.577350 2.094399
                children [
                  Pose {
                    translation -0.037500 -0.069800 -0.005000
                    rotation -1.000000 -0.000000 0.000000 3.141590
                    children [
                      Shape {
                        appearance DEF head_plate_material PBRAppearance {
                          baseColor 0.701961 0.682353 0.623529
                          roughness 1.000000
                          metalness 0
                        }
                        geometry Box {
                           size 0.008000 0.050000 0.003000
                        }
                      }
                    ]
                  }
                  Pose {
                    translation -0.000000 -0.069800 -0.005000
                    rotation -1.000000 -0.000000 0.000000 3.141590
                    children [
                      Shape {
                        appearance USE head_plate_material
                        geometry Box {
                           size 0.008000 0.050000 0.003000
                        }
                      }
                    ]
                  }
                  Pose {
                    translation 0.037500 -0.069800 -0.005000
                    rotation -1.000000 -0.000000 0.000000 3.141590
                    children [
                      Shape {
                        appearance USE head_plate_material
                        geometry Box {
                           size 0.008000 0.050000 0.003000
                        }
                      }
                    ]
                  }
                  Pose {
                    translation -0.000000 -0.046800 -0.005000
                    rotation -1.000000 -0.000000 0.000000 3.141590
                    children [
                      Shape {
                        appearance USE head_plate_material
                        geometry Box {
                           size 0.083000 0.008000 0.003000
                        }
                      }
                    ]
                  }
                  Pose {
                    translation -0.000000 -0.069800 -0.005000
                    rotation -1.000000 -0.000000 0.000000 3.141590
                    children [
                      Shape {
                        appearance USE head_plate_material
                        geometry Box {
                           size 0.083000 0.008000 0.003000
                        }
                      }
                    ]
                  }
                  Pose {
                    translation -0.000000 -0.092800 -0.005000
                    rotation -1.000000 -0.000000 0.000000 3.141590
                    children [
                      Shape {
                        appearance USE head_plate_material
                        geometry Box {
                           size 0.083000 0.008000 0.003000
                        }
                      }
                    ]
                  }
                  Pose {
                    translation 0.004968 -0.069050 -0.023500
                    rotation 0.577350 -0.577350 0.577352 2.094399
                    children [
                      Shape {
                        appearance DEF ptgrey_camera_material PBRAppearance {
                          baseColor 0.400000 0.400000 0.400000
                          roughness 1.000000
                          metalness 0
                        }
                        geometry Box {
                           size 0.030000 0.030000 0.028000
                        }
                      }
                    ]
                  }
                  Pose {
                    translation -0.037500 -0.069800 -0.042000
                    rotation -1.000000 -0.000000 0.000000 3.141590
                    children [
                      Shape {
                        appearance USE head_plate_material
                        geometry Box {
                           size 0.008000 0.050000 0.003000
                        }
                      }
                    ]
                  }
                  Pose {
                    translation -0.000000 -0.069800 -0.042000
                    rotation -1.000000 -0.000000 0.000000 3.141590
                    children [
                      Shape {
                        appearance USE head_plate_material
                        geometry Box {
                           size 0.008000 0.050000 0.003000
                        }
                      }
                    ]
                  }
                  Pose {
                    translation 0.037500 -0.069800 -0.042000
                    rotation -1.000000 -0.000000 0.000000 3.141590
                    children [
                      Shape {
                        appearance USE head_plate_material
                        geometry Box {
                           size 0.008000 0.050000 0.003000
                        }
                      }
                    ]
                  }
                  Pose {
                    translation -0.000000 -0.046800 -0.042000
                    rotation -1.000000 -0.000000 0.000000 3.141590
                    children [
                      Shape {
                        appearance USE head_plate_material
                        geometry Box {
                           size 0.083000 0.008000 0.003000
                        }
                      }
                    ]
                  }
                  Pose {
                    translation -0.000000 -0.069800 -0.042000
                    rotation -1.000000 -0.000000 0.000000 3.141590
                    children [
                      Shape {
                        appearance USE head_plate_material
                        geometry Box {
                           size 0.083000 0.008000 0.003000
                        }
                      }
                    ]
                  }
                  Pose {
                    translation -0.000000 -0.092800 -0.042000
                    rotation -1.000000 -0.000000 0.000000 3.141590
                    children [
                      Shape {
                        appearance USE head_plate_material
                        geometry Box {
                           size 0.083000 0.008000 0.003000
                        }
                      }
                    ]
                  }
                  Pose {
                    translation 0.000000 -0.015000 -0.023500
                    children [
                      Shape {
                        appearance USE mx64_material
                        geometry Box {
                           size 0.029000 0.050000 0.040000
                        }
                      }
                    ]
                  }
                ]
                name "head_1"
                boundingObject Group {
                  children [
                    Pose {
                      translation -0.037500 -0.069800 -0.005000
                      rotation -1.000000 -0.000000 0.000000 3.141590
                      children [
                        Box {
                           size 0.008000 0.050000 0.003000
                        }
                      ]
                    }
                    Pose {
                      translation -0.000000 -0.069800 -0.005000
                      rotation -1.000000 -0.000000 0.000000 3.141590
                      children [
                        Box {
                           size 0.008000 0.050000 0.003000
                        }
                      ]
                    }
                    Pose {
                      translation 0.037500 -0.069800 -0.005000
                      rotation -1.000000 -0.000000 0.000000 3.141590
                      children [
                        Box {
                           size 0.008000 0.050000 0.003000
                        }
                      ]
                    }
                    Pose {
                      translation -0.000000 -0.046800 -0.005000
                      rotation -1.000000 -0.000000 0.000000 3.141590
                      children [
                        Box {
                           size 0.083000 0.008000 0.003000
                        }
                      ]
                    }
                    Pose {
                      translation -0.000000 -0.069800 -0.005000
                      rotation -1.000000 -0.000000 0.000000 3.141590
                      children [
                        Box {
                           size 0.083000 0.008000 0.003000
                        }
                      ]
                    }
                    Pose {
                      translation -0.000000 -0.092800 -0.005000
                      rotation -1.000000 -0.000000 0.000000 3.141590
                      children [
                        Box {
                           size 0.083000 0.008000 0.003000
                        }
                      ]
                    }
                    Pose {
                      translation 0.004968 -0.069050 -0.023500
                      rotation 0.577350 -0.577350 0.577352 2.094399
                      children [
                        Box {
                           size 0.030000 0.030000 0.028000
                        }
                      ]
                    }
                    Pose {
                      translation -0.037500 -0.069800 -0.042000
                      rotation -1.000000 -0.000000 0.000000 3.141590
                      children [
                        Box {
                           size 0.008000 0.050000 0.003000
                        }
                      ]
                    }
                    Pose {
                      translation -0.000000 -0.069800 -0.042000
                      rotation -1.000000 -0.000000 0.000000 3.141590
                      children [
                        Box {
                           size 0.008000 0.050000 0.003000
                        }
                      ]
                    }
                    Pose {
                      translation 0.037500 -0.069800 -0.042000
                      rotation -1.000000 -0.000000 0.000000 3.141590
                      children [
                        Box {
                           size 0.008000 0.050000 0.003000
                        }
                      ]
                    }
                    Pose {
                      translation -0.000000 -0.046800 -0.042000
                      rotation -1.000000 -0.000000 0.000000 3.141590
                      children [
                        Box {
                           size 0.083000 0.008000 0.003000
                        }
                      ]
                    }
                    Pose {
                      translation -0.000000 -0.069800 -0.042000
                      rotation -1.000000 -0.000000 0.000000 3.141590
                      children [
                        Box {
                           size 0.083000 0.008000 0.003000
                        }
                      ]
                    }
                    Pose {
                      translation -0.000000 -0.092800 -0.042000
                      rotation -1.000000 -0.000000 0.000000 3.141590
                      children [
                        Box {
                           size 0.083000 0.008000 0.003000
                        }
                      ]
                    }
                    Pose {
                      translation 0.000000 -0.015000 -0.023500
                      children [
                        Box {
                           size 0.029000 0.050000 0.040000
                        }
                      ]
                    }
                  ]
                }
                physics Physics {
                  density -1
                  mass 0.228227
                  centerOfMass [ 0.001274 -0.034352 -0.023721 ]
                  inertiaMatrix [
                    2.369020e-04 8.770150e-05 2.356680e-04
                    9.174760e-06 5.766680e-07 -3.391630e-07
                  ]
                }
              }
            }
          ]
          name "u_neck_1"
          boundingObject Group {
            children [
              Pose {
                translation 0.000000 -0.000000 0.003000
                children [
                  Box {
                     size 0.047000 0.027500 0.006000
                  }
                ]
              }
              Pose {
                translation -0.025000 -0.000000 0.023000
                rotation 0.577350 0.577352 0.577350 2.094399
                children [
                  Box {
                     size 0.025000 0.044000 0.003000
                  }
                ]
              }
              Pose {
                translation 0.025000 -0.000000 0.023000
                rotation 0.577350 -0.577352 -0.577350 2.094399
                children [
                  Box {
                     size 0.025000 0.044000 0.003000
                  }
                ]
              }
            ]
          }
          physics Physics {
            density -1
            mass 0.036209
            centerOfMass [ -0.000000 -0.000000 0.012892 ]
            inertiaMatrix [
              6.419550e-06 2.381990e-05 2.029730e-05
              4.273710e-12 3.647010e-13 4.495010e-20
            ]
          }
        }
      }
    ]
    name IS name
    boundingObject Group {
      children [
        Pose {
          translation -0.031000 -0.054127 0.090900
          children [
            Cylinder {
              radius 0.004
              height 0.086
            }
          ]
        }
        Pose {
          translation -0.046375 -0.026254 0.020000
          rotation 0.000001 -1.000000 -0.000001 3.141593
          children [
            Box {
               size 0.029000 0.050000 0.040000
            }
          ]
        }
        Pose {
          translation 0.050000 -0.017127 0.160900
          rotation -0.707105 -0.000001 -0.707108 3.141591
          children [
            Box {
               size 0.029000 0.050000 0.040000
            }
          ]
        }
        Pose {
          translation 0.046375 -0.026254 0.020000
          rotation 0.000001 -1.000000 -0.000001 3.141593
          children [
            Box {
               size 0.029000 0.050000 0.040000
            }
          ]
        }
        Pose {
          translation 0.000000 0.071323 0.189900
          rotation 0.577350 0.577350 -0.577352 2.094399
          children [
            Box {
               size 0.010000 0.130000 0.003000
            }
          ]
        }
        Pose {
          translation -0.060000 0.071323 0.164900
          rotation 0.577350 0.577350 -0.577352 2.094399
          children [
            Box {
               size 0.040000 0.010000 0.003000
            }
          ]
        }
        Pose {
          translation 0.060000 0.071323 0.164900
          rotation 0.577350 0.577350 -0.577352 2.094399
          children [
            Box {
               size 0.040000 0.010000 0.003000
            }
          ]
        }
        Pose {
          translation 0.062500 0.037873 0.090900
          rotation -1.000000 -0.000000 0.000000 3.141590
          children [
            Cylinder {
              radius 0.004
              height 0.086
            }
          ]
        }
        Pose {
          translation -0.050587 -0.017127 0.160900
          rotation 0.707105 0.000001 -0.707108 3.141591
          children [
            Box {
               size 0.029000 0.050000 0.040000
            }
          ]
        }
        Pose {
          translation 0.000000 -0.019127 0.135400
          rotation 0.000001 -1.000000 -0.000001 3.141593
          children [
            Box {
               size 0.130000 0.080000 0.003000
            }
          ]
        }
        Pose {
          translation 0.000000 0.010373 0.046900
          children [
            Box {
               size 0.130000 0.080000 0.003000
            }
          ]
        }
        Pose {
          translation -0.062500 0.037873 0.090900
          children [
            Cylinder {
              radius 0.004
              height 0.086
            }
          ]
        }
        Pose {
          translation 0.000000 0.035873 0.106150
          rotation 0.000001 -0.707108 -0.707105 3.141591
          children [
            Box {
               size 0.110000 0.110000 0.033000
            }
          ]
        }
        Pose {
          translation 0.000000 0.031123 0.001500
          children [
            Box {
               size 0.130000 0.044000 0.003000
            }
          ]
        }
        Pose {
          translation -0.030000 -0.007877 0.001500
          children [
            Box {
               size 0.010000 0.035000 0.003000
            }
          ]
        }
        Pose {
          translation 0.030000 -0.007877 0.001500
          children [
            Box {
               size 0.010000 0.035000 0.003000
            }
          ]
        }
        Pose {
          translation 0.000000 0.059373 0.138400
          rotation -0.707105 0.707108 -0.000001 3.141591
          children [
            Box {
               size 0.010000 0.135000 0.003000
            }
          ]
        }
        Pose {
          translation 0.000000 -0.022127 0.162300
          rotation -0.000000 -0.000000 -1.000000 3.141590
          children [
            Box {
               size 0.029000 0.050000 0.040000
            }
          ]
        }
        Pose {
          translation 0.031000 -0.054127 0.091400
          children [
            Cylinder {
              radius 0.004
              height 0.086
            }
          ]
        }
      ]
    }
    physics Physics {
      density -1
      mass 1.759120
      centerOfMass [ 0.000186 0.000530 0.092243 ]
      inertiaMatrix [
        8.238960e-03 9.158670e-03 5.111560e-03
        2.574940e-06 1.973400e-05 -1.694330e-04
      ]
    }
  }
}
