#VRML_SIM R2023b utf8

EXTERNPROTO "https://raw.githubusercontent.com/cyberbotics/webots/R2023b/projects/objects/backgrounds/protos/TexturedBackground.proto"
EXTERNPROTO "https://raw.githubusercontent.com/cyberbotics/webots/R2023b/projects/objects/backgrounds/protos/TexturedBackgroundLight.proto"
EXTERNPROTO "https://raw.githubusercontent.com/cyberbotics/webots/R2023b/projects/objects/floors/protos/RectangleArena.proto"

WorldInfo {
}
Viewpoint {
  orientation 0.1927462922289837 -0.12035574118821529 -0.9738394951915917 4.2342722095646375
  position 0.8372777287953124 -1.617805008327252 1.1117177613587332
}
TexturedBackground {
}
TexturedBackgroundLight {
}
RectangleArena {
}
Robot {
  translation 1.5805670543011336e-07 0.0007391661049447096 0.38299211083859686
  rotation -0.9999990705556626 -0.0007216706687549564 0.0011567537579301218 0.0009783876008589705
  children [
    Gyro {
      translation 0 0 0.09
      name "Gyro"
    }
    Accelerometer {
      translation 0 0 0.09
      name "Accelerometer"
    }
    Pose {
      translation -0.031 -0.054127 0.0909
      children [
        Shape {
          appearance DEF pillar_tube_material PBRAppearance {
            baseColor 0.501961 0.486275 0.439216
            roughness 1
            metalness 0
          }
          geometry Cylinder {
            height 0.086
            radius 0.004
          }
        }
      ]
    }
    Pose {
      translation -0.046375 -0.026254 0.02
      rotation 1e-06 -1 -1e-06 3.141593
      children [
        Shape {
          appearance DEF mx64_material PBRAppearance {
            baseColor 0.211765 0.211765 0.211765
            roughness 1
            metalness 0
          }
          geometry Box {
            size 0.029 0.05 0.04
          }
        }
      ]
    }
    Pose {
      translation 0.05 -0.017127 0.1609
      rotation -0.7071052811840065 -1.0000003976552372e-06 -0.7071082811851994 3.141591
      children [
        Shape {
          appearance USE mx64_material
          geometry Box {
            size 0.029 0.05 0.04
          }
        }
      ]
    }
    Pose {
      translation 0.046375 -0.026254 0.02
      rotation 1e-06 -1 -1e-06 3.141593
      children [
        Shape {
          appearance USE mx64_material
          geometry Box {
            size 0.029 0.05 0.04
          }
        }
      ]
    }
    Pose {
      translation 0 0.071323 0.1899
      rotation 0.5773496025226482 0.5773496025226482 -0.5773516025212713 2.094399
      children [
        Shape {
          appearance DEF handle_material PBRAppearance {
            baseColor 0.701961 0.682353 0.623529
            roughness 1
            metalness 0
          }
          geometry Box {
            size 0.01 0.13 0.003
          }
        }
      ]
    }
    Pose {
      translation -0.06 0.071323 0.1649
      rotation 0.5773496025226482 0.5773496025226482 -0.5773516025212713 2.094399
      children [
        Shape {
          appearance USE handle_material
          geometry Box {
            size 0.04 0.01 0.003
          }
        }
      ]
    }
    Pose {
      translation 0.06 0.071323 0.1649
      rotation 0.5773496025226482 0.5773496025226482 -0.5773516025212713 2.094399
      children [
        Shape {
          appearance USE handle_material
          geometry Box {
            size 0.04 0.01 0.003
          }
        }
      ]
    }
    Pose {
      translation 0.0625 0.037873 0.0909
      rotation -1 0 0 3.14159
      children [
        Shape {
          appearance USE pillar_tube_material
          geometry Cylinder {
            height 0.086
            radius 0.004
          }
        }
      ]
    }
    Pose {
      translation -0.050587 -0.017127 0.1609
      rotation 0.7071052811840065 1.0000003976552372e-06 -0.7071082811851994 3.141591
      children [
        Shape {
          appearance USE mx64_material
          geometry Box {
            size 0.029 0.05 0.04
          }
        }
      ]
    }
    Pose {
      translation 0 -0.019127 0.1354
      rotation 1e-06 -1 -1e-06 3.141593
      children [
        Shape {
          appearance DEF torso_top_plate_nuc_material PBRAppearance {
            baseColor 0.301961 0.301961 0.301961
            roughness 1
            metalness 0
          }
          geometry Box {
            size 0.13 0.08 0.003
          }
        }
      ]
    }
    Pose {
      translation 0 0.010373 0.0469
      children [
        Shape {
          appearance DEF torso_middle_plate_nuc_material PBRAppearance {
            baseColor 0.301961 0.301961 0.301961
            roughness 1
            metalness 0
          }
          geometry Box {
            size 0.13 0.08 0.003
          }
        }
      ]
    }
    Pose {
      translation -0.0625 0.037873 0.0909
      children [
        Shape {
          appearance USE pillar_tube_material
          geometry Cylinder {
            height 0.086
            radius 0.004
          }
        }
      ]
    }
    Pose {
      translation 0 0.035873 0.10615
      rotation 1.0000003976552372e-06 -0.7071082811851994 -0.7071052811840065 3.141591
      children [
        Shape {
          appearance DEF nuc_material PBRAppearance {
            baseColor 0.301961 0.290196 0.262745
            roughness 1
            metalness 0
          }
          geometry Box {
            size 0.11 0.11 0.033
          }
        }
      ]
    }
    Pose {
      translation 0 0.031123 0.0015
      children [
        Shape {
          appearance DEF torso_bottom_plate_nuc_material PBRAppearance {
            baseColor 0.4 0.4 0.4
            roughness 1
            metalness 0
          }
          geometry Box {
            size 0.13 0.044 0.003
          }
        }
      ]
    }
    Pose {
      translation -0.03 -0.007877 0.0015
      children [
        Shape {
          appearance USE torso_bottom_plate_nuc_material
          geometry Box {
            size 0.01 0.035 0.003
          }
        }
      ]
    }
    Pose {
      translation 0.03 -0.007877 0.0015
      children [
        Shape {
          appearance USE torso_bottom_plate_nuc_material
          geometry Box {
            size 0.01 0.035 0.003
          }
        }
      ]
    }
    Pose {
      translation 0 0.059373 0.1384
      rotation -0.7071052811840065 0.7071082811851994 -1.0000003976552372e-06 3.141591
      children [
        Shape {
          appearance DEF nuc_fix_material PBRAppearance {
            baseColor 0.301961 0.301961 0.301961
            roughness 1
            metalness 0
          }
          geometry Box {
            size 0.01 0.135 0.003
          }
        }
      ]
    }
    Pose {
      translation 0 -0.022127 0.1623
      rotation 0 0 -1 3.14159
      children [
        Shape {
          appearance USE mx64_material
          geometry Box {
            size 0.029 0.05 0.04
          }
        }
      ]
    }
    Pose {
      translation 0.031 -0.054127 0.0914
      children [
        Shape {
          appearance USE pillar_tube_material
          geometry Cylinder {
            height 0.086
            radius 0.004
          }
        }
      ]
    }
    HingeJoint {
      jointParameters HingeJointParameters {
        position 5.485895489848345e-07
        axis -3e-06 0 1
        anchor -0.046375 -0.011254 -0.0035
      }
      device [
        RotationalMotor {
          name "right_hip_yaw"
          maxVelocity 6
        }
        PositionSensor {
          name "right_hip_yaw_sensor"
        }
      ]
      endPoint Solid {
        translation -0.046375 -0.011254 -0.0035
        rotation 0.7071050872278735 0.7071084751404564 1.0000000425723998e-06 3.141590999999385
        children [
          Pose {
            translation -0.00494 0 0.003
            children [
              Shape {
                appearance DEF u_base_motors_blocs_material PBRAppearance {
                  baseColor 0.301961 0.301961 0.301961
                  roughness 1
                  metalness 0
                }
                geometry Box {
                  size 0.05 0.03 0.006
                }
              }
            ]
          }
          Pose {
            translation -0.03144 0 0.023
            rotation 0.5773496025226483 0.5773516025212714 0.5773496025226483 2.094399
            children [
              Shape {
                appearance DEF u_side_small_material PBRAppearance {
                  baseColor 0.301961 0.301961 0.301961
                  roughness 1
                  metalness 0
                }
                geometry Box {
                  size 0.025 0.044 0.003
                }
              }
            ]
          }
          Pose {
            translation 0.0219 0 0.023
            rotation 0.5773496025226483 -0.5773516025212714 -0.5773496025226483 2.094399
            children [
              Shape {
                appearance DEF u_side_small_with_trace_material PBRAppearance {
                  baseColor 0.301961 0.301961 0.301961
                  roughness 1
                  metalness 0
                }
                geometry Box {
                  size 0.027 0.042 0.003
                }
              }
            ]
          }
          HingeJoint {
            jointParameters HingeJointParameters {
              position 1.3412522304817755e-06
              axis -1 -4e-06 -4e-06
              anchor 0.0234 0 0.04
            }
            device [
              RotationalMotor {
                name "right_hip_roll"
                maxVelocity 6
              }
              PositionSensor {
                name "right_hip_roll_sensor"
              }
            ]
            endPoint Solid {
              translation 0.0234 0 0.04
              rotation -0.5773498606488212 -0.5773510862739257 0.5773498606452632 2.0943997743716145
              children [
                Pose {
                  translation 0 -0.015 0.0234
                  rotation 0 -1 0 1.5708
                  children [
                    Shape {
                      appearance DEF mx106_material PBRAppearance {
                        baseColor 0.301961 0.301961 0.301961
                        roughness 1
                        metalness 0
                      }
                      geometry Box {
                        size 0.03 0.055 0.04
                      }
                    }
                  ]
                }
                Pose {
                  translation 0 -0.015 -0.026
                  children [
                    Shape {
                      appearance USE mx106_material
                      geometry Box {
                        size 0.03 0.055 0.04
                      }
                    }
                  ]
                }
                HingeJoint {
                  jointParameters HingeJointParameters {
                    position 1.7276831370059747e-08
                    axis 1 0 -4e-06
                    anchor -0.026 0 0.0234
                  }
                  device [
                    RotationalMotor {
                      name "right_hip_pitch"
                      maxVelocity 6
                    }
                    PositionSensor {
                      name "right_hip_pitch_sensor"
                    }
                  ]
                  endPoint Solid {
                    translation -0.026 0 0.0234
                    rotation 8.379746960853654e-09 1 8.379710703485658e-09 1.5708
                    children [
                      Pose {
                        translation 0 -0.0395 0.0535
                        children [
                          Shape {
                            appearance DEF u_side_femur_mir_material PBRAppearance {
                              baseColor 0.301961 0.301961 0.301961
                              roughness 1
                              metalness 0
                            }
                            geometry Box {
                              size 0.04 0.09 0.003
                            }
                          }
                        ]
                      }
                      Pose {
                        translation 0 -0.125 0.026
                        rotation -1 0 0 3.14159
                        children [
                          Shape {
                            appearance USE mx106_material
                            geometry Box {
                              size 0.03 0.055 0.04
                            }
                          }
                        ]
                      }
                      Pose {
                        translation 0 -0.0395 -0.0015
                        children [
                          Shape {
                            appearance DEF u_side_femur_material PBRAppearance {
                              baseColor 0.301961 0.301961 0.301961
                              roughness 1
                              metalness 0
                            }
                            geometry Box {
                              size 0.04 0.09 0.003
                            }
                          }
                        ]
                      }
                      Pose {
                        translation 0 -0.0825 0.026
                        rotation -0.5773496025226482 0.5773496025226482 0.5773516025212713 2.094399
                        children [
                          Shape {
                            appearance DEF u_base_64_material PBRAppearance {
                              baseColor 0.301961 0.301961 0.301961
                              roughness 1
                              metalness 0
                            }
                            geometry Box {
                              size 0.047 0.0275 0.006
                            }
                          }
                        ]
                      }
                      HingeJoint {
                        jointParameters HingeJointParameters {
                          position 1.962701350562683e-08
                          axis 0 -3e-06 1
                          anchor 0 -0.14 0
                        }
                        device [
                          RotationalMotor {
                            name "right_knee"
                            maxVelocity 6
                          }
                          PositionSensor {
                            name "right_knee_sensor"
                          }
                        ]
                        endPoint Solid {
                          translation 0 -0.14 0
                          rotation 1.009813506751788e-06 -0.9999999999989903 -1.0000000016987188e-06 3.141593000000039
                          children [
                            Pose {
                              translation 0 -0.067 0.0015
                              children [
                                Shape {
                                  appearance DEF tibia_plate_material PBRAppearance {
                                    baseColor 0.301961 0.301961 0.301961
                                    roughness 1
                                    metalness 0
                                  }
                                  geometry Box {
                                    size 0.03 0.165 0.003
                                  }
                                }
                              ]
                            }
                            Pose {
                              translation 0 -0.067 -0.0535
                              children [
                                Shape {
                                  appearance USE tibia_plate_material
                                  geometry Box {
                                    size 0.03 0.165 0.003
                                  }
                                }
                              ]
                            }
                            HingeJoint {
                              jointParameters HingeJointParameters {
                                position 6.139183757189557e-08
                                axis 0 0 -1
                                anchor 0 -0.14 0
                              }
                              device [
                                RotationalMotor {
                                  name "right_ankle_pitch"
                                  maxVelocity 6
                                }
                                PositionSensor {
                                  name "right_ankle_pitch_sensor"
                                }
                              ]
                              endPoint Solid {
                                translation 0 -0.14 0
                                rotation 0 0 1 3.1415899386081625
                                children [
                                  Pose {
                                    translation 0 -0.015 -0.026
                                    children [
                                      Shape {
                                        appearance USE mx106_material
                                        geometry Box {
                                          size 0.03 0.055 0.04
                                        }
                                      }
                                    ]
                                  }
                                  Pose {
                                    translation 0.0494 -0.015 -0.026
                                    rotation 0 -1 0 1.5708
                                    children [
                                      Shape {
                                        appearance USE mx106_material
                                        geometry Box {
                                          size 0.03 0.055 0.04
                                        }
                                      }
                                    ]
                                  }
                                  HingeJoint {
                                    jointParameters HingeJointParameters {
                                      position 1.7838555036247989e-06
                                      axis -1 -3e-06 4e-06
                                      anchor 0.0234 0 -0.026
                                    }
                                    device [
                                      RotationalMotor {
                                        name "right_ankle_roll"
                                        maxVelocity 6
                                      }
                                      PositionSensor {
                                        name "right_ankle_roll_sensor"
                                      }
                                    ]
                                    endPoint Solid {
                                      translation 0.0234 0 -0.026
                                      rotation 0.7071052811853894 3.693134208827111e-07 -0.7071082811844275 3.141589738621307
                                      children [
                                        Pose {
                                          translation -0.0435 -0.05 -0.03213
                                          rotation -0.07067301865421641 -0.705340186175272 0.7053371861744802 3.282702
                                          children [
                                            Shape {
                                              appearance DEF cleat_material PBRAppearance {
                                                baseColor 0.301961 0.290196 0.262745
                                                roughness 1
                                                metalness 0
                                              }
                                              geometry Cylinder {
                                                height 0.02
                                                radius 0.008
                                              }
                                            }
                                          ]
                                        }
                                        Pose {
                                          translation -0.0435 -0.05 0.10947
                                          rotation -0.07067301865421641 -0.705340186175272 0.7053371861744802 3.282702
                                          children [
                                            Shape {
                                              appearance USE cleat_material
                                              geometry Cylinder {
                                                height 0.02
                                                radius 0.008
                                              }
                                            }
                                          ]
                                        }
                                        Pose {
                                          translation 0 -0.017 0.05484
                                          rotation -1e-06 -1 1e-06 3.141593
                                          children [
                                            Shape {
                                              appearance USE u_side_small_material
                                              geometry Box {
                                                size 0.025 0.044 0.003
                                              }
                                            }
                                          ]
                                        }
                                        Pose {
                                          translation 0.0325 -0.05 0.10947
                                          rotation 0.92751216314523 0.26431104649112774 -0.26431204649130363 1.645979
                                          children [
                                            Shape {
                                              appearance USE cleat_material
                                              geometry Cylinder {
                                                height 0.02
                                                radius 0.008
                                              }
                                            }
                                          ]
                                        }
                                        Pose {
                                          translation -0.0055 -0.0415 0.03867
                                          rotation 1.0000003976552372e-06 0.7071082811851994 0.7071052811840065 3.141591
                                          children [
                                            Shape {
                                              appearance DEF foot_plate_material PBRAppearance {
                                                baseColor 0.301961 0.301961 0.301961
                                                roughness 1
                                                metalness 0
                                              }
                                              geometry Box {
                                                size 0.09 0.155 0.003
                                              }
                                            }
                                          ]
                                        }
                                        Pose {
                                          translation 0 -0.017 0.0015
                                          children [
                                            Shape {
                                              appearance USE u_side_small_with_trace_material
                                              geometry Box {
                                                size 0.027 0.042 0.003
                                              }
                                            }
                                          ]
                                        }
                                        Pose {
                                          translation 0.0325 -0.05 -0.03213
                                          rotation 0.9762266572922753 -0.15326694619511155 0.15326694619511155 1.594858
                                          children [
                                            Shape {
                                              appearance USE cleat_material
                                              geometry Cylinder {
                                                height 0.02
                                                radius 0.008
                                              }
                                            }
                                          ]
                                        }
                                        Pose {
                                          translation -0.0055 -0.0275 0.12247
                                          rotation 0.6785972482190434 -0.6785992482197749 -0.28108510281603044 3.68962
                                          children [
                                            Shape {
                                              appearance DEF foot_protection_material PBRAppearance {
                                                baseColor 0.301961 0.290196 0.262745
                                                roughness 1
                                                metalness 0
                                              }
                                              geometry Box {
                                                size 0.01 0.09 0.01
                                              }
                                            }
                                          ]
                                        }
                                        Pose {
                                          translation 0 -0.037 0.02834
                                          rotation -0.5773496025226482 0.5773496025226482 0.5773516025212713 2.094399
                                          children [
                                            Shape {
                                              appearance USE u_base_motors_blocs_material
                                              geometry Box {
                                                size 0.05 0.03 0.006
                                              }
                                            }
                                          ]
                                        }
                                      ]
                                      name "right_foot_cleat_back_left"
                                      boundingObject Group {
                                        children [
                                          Pose {
                                            translation -0.0435 -0.05 -0.03213
                                            rotation -0.07067301865421641 -0.705340186175272 0.7053371861744802 3.282702
                                            children [
                                              Cylinder {
                                                height 0.02
                                                radius 0.008
                                              }
                                            ]
                                          }
                                          Pose {
                                            translation -0.0435 -0.05 0.10947
                                            rotation -0.07067301865421641 -0.705340186175272 0.7053371861744802 3.282702
                                            children [
                                              Cylinder {
                                                height 0.02
                                                radius 0.008
                                              }
                                            ]
                                          }
                                          Pose {
                                            translation 0 -0.017 0.05484
                                            rotation -1e-06 -1 1e-06 3.141593
                                            children [
                                              Box {
                                                size 0.025 0.044 0.003
                                              }
                                            ]
                                          }
                                          Pose {
                                            translation 0.0325 -0.05 0.10947
                                            rotation 0.92751216314523 0.26431104649112774 -0.26431204649130363 1.645979
                                            children [
                                              Cylinder {
                                                height 0.02
                                                radius 0.008
                                              }
                                            ]
                                          }
                                          Pose {
                                            translation -0.0055 -0.0415 0.03867
                                            rotation 1.0000003976552372e-06 0.7071082811851994 0.7071052811840065 3.141591
                                            children [
                                              Box {
                                                size 0.09 0.155 0.003
                                              }
                                            ]
                                          }
                                          Pose {
                                            translation 0 -0.017 0.0015
                                            children [
                                              Box {
                                                size 0.027 0.042 0.003
                                              }
                                            ]
                                          }
                                          Pose {
                                            translation 0.0325 -0.05 -0.03213
                                            rotation 0.9762266572922753 -0.15326694619511155 0.15326694619511155 1.594858
                                            children [
                                              Cylinder {
                                                height 0.02
                                                radius 0.008
                                              }
                                            ]
                                          }
                                          Pose {
                                            translation -0.0055 -0.0275 0.12247
                                            rotation 0.6785972482190434 -0.6785992482197749 -0.28108510281603044 3.68962
                                            children [
                                              Box {
                                                size 0.01 0.09 0.01
                                              }
                                            ]
                                          }
                                          Pose {
                                            translation 0 -0.037 0.02834
                                            rotation -0.5773496025226482 0.5773496025226482 0.5773516025212713 2.094399
                                            children [
                                              Box {
                                                size 0.05 0.03 0.006
                                              }
                                            ]
                                          }
                                        ]
                                      }
                                      physics Physics {
                                        density -1
                                        mass 0.239067
                                        centerOfMass [
                                          -0.004685 -0.036578 0.051153
                                        ]
                                        inertiaMatrix [
                                          0.000644736 0.000780875 0.000195711
                                          -2.73076e-06 4.22638e-06 -2.65367e-05
                                        ]
                                      }
                                      linearVelocity -2.06250540788789e-07 7.172704622452808e-08 1.8888620334988853e-06
                                      angularVelocity -2.9968924649975454e-06 -1.1171258788636168e-05 1.5828229568204808e-06
                                    }
                                  }
                                ]
                                name "mx106_block_1"
                                boundingObject Group {
                                  children [
                                    Pose {
                                      translation 0 -0.015 -0.026
                                      children [
                                        Box {
                                          size 0.03 0.055 0.04
                                        }
                                      ]
                                    }
                                    Pose {
                                      translation 0.0494 -0.015 -0.026
                                      rotation 0 -1 0 1.5708
                                      children [
                                        Box {
                                          size 0.03 0.055 0.04
                                        }
                                      ]
                                    }
                                  ]
                                }
                                physics Physics {
                                  density -1
                                  mass 0.427481
                                  centerOfMass [
                                    0.019588 -0.018098 -0.025825
                                  ]
                                  inertiaMatrix [
                                    0.000194682 0.000410191 0.000485925
                                    1.88861e-05 4.22317e-07 -2.22493e-06
                                  ]
                                }
                                linearVelocity -4.500527745399348e-07 2.474375540427595e-07 1.4668571956906846e-06
                                angularVelocity -2.992648879429527e-06 -4.519819487750743e-06 1.7713307053126299e-06
                              }
                            }
                          ]
                          name "tibia_1"
                          boundingObject Group {
                            children [
                              Pose {
                                translation 0 -0.067 0.0015
                                children [
                                  Box {
                                    size 0.03 0.165 0.003
                                  }
                                ]
                              }
                              Pose {
                                translation 0 -0.067 -0.0535
                                children [
                                  Box {
                                    size 0.03 0.165 0.003
                                  }
                                ]
                              }
                            ]
                          }
                          physics Physics {
                            density -1
                            mass 0.088844
                            centerOfMass [
                              -0.003422 -0.064607 -0.026
                            ]
                            inertiaMatrix [
                              0.000245247 7.67255e-05 0.000187463
                              6.12719e-06 -1.44286e-11 3.8066e-11
                            ]
                          }
                          linearVelocity -3.620525409276495e-07 -8.341765607498064e-08 1.2606873921576011e-06
                          angularVelocity 3.806569659959233e-06 -4.5360757309596e-06 1.959026001784517e-06
                        }
                      }
                    ]
                    name "right_knee_1"
                    boundingObject Group {
                      children [
                        Pose {
                          translation 0 -0.0395 0.0535
                          children [
                            Box {
                              size 0.04 0.09 0.003
                            }
                          ]
                        }
                        Pose {
                          translation 0 -0.125 0.026
                          rotation -1 0 0 3.14159
                          children [
                            Box {
                              size 0.03 0.055 0.04
                            }
                          ]
                        }
                        Pose {
                          translation 0 -0.0395 -0.0015
                          children [
                            Box {
                              size 0.04 0.09 0.003
                            }
                          ]
                        }
                        Pose {
                          translation 0 -0.0825 0.026
                          rotation -0.5773496025226482 0.5773496025226482 0.5773516025212713 2.094399
                          children [
                            Box {
                              size 0.047 0.0275 0.006
                            }
                          ]
                        }
                      ]
                    }
                    physics Physics {
                      density -1
                      mass 0.269758
                      centerOfMass [
                        0.000224 -0.098034 0.025713
                      ]
                      inertiaMatrix [
                        0.000503595 0.000109941 0.000438644
                        9.05865e-07 -4.56779e-07 -5.72119e-06
                      ]
                    }
                    linearVelocity -5.216737482385793e-07 -7.454338758391264e-07 9.823312396195479e-07
                    angularVelocity 1.013597303485236e-05 -4.597465272722355e-06 2.1467540368490007e-06
                  }
                }
              ]
              name "mx106_block_mir_1"
              boundingObject Group {
                children [
                  Pose {
                    translation 0 -0.015 0.0234
                    rotation 0 -1 0 1.5708
                    children [
                      Box {
                        size 0.03 0.055 0.04
                      }
                    ]
                  }
                  Pose {
                    translation 0 -0.015 -0.026
                    children [
                      Box {
                        size 0.03 0.055 0.04
                      }
                    ]
                  }
                ]
              }
              physics Physics {
                density -1
                mass 0.427481
                centerOfMass [
                  -0.000304 -0.018098 0.003917
                ]
                inertiaMatrix [
                  0.000482208 0.000408392 0.000203671
                  -1.57792e-05 3.50396e-06 -3.68837e-05
                ]
              }
              linearVelocity -6.119243211693164e-07 -1.451001593330932e-06 1.0471832540109368e-06
              angularVelocity 1.5369073765792138e-05 -4.704556608518345e-06 2.334534141787677e-06
            }
          }
        ]
        name "u_block_1"
        boundingObject Group {
          children [
            Pose {
              translation -0.00494 0 0.003
              children [
                Box {
                  size 0.05 0.03 0.006
                }
              ]
            }
            Pose {
              translation -0.03144 0 0.023
              rotation 0.5773496025226483 0.5773516025212714 0.5773496025226483 2.094399
              children [
                Box {
                  size 0.025 0.044 0.003
                }
              ]
            }
            Pose {
              translation 0.0219 0 0.023
              rotation 0.5773496025226483 -0.5773516025212714 -0.5773496025226483 2.094399
              children [
                Box {
                  size 0.027 0.042 0.003
                }
              ]
            }
          ]
        }
        physics Physics {
          density -1
          mass 0.03544
          centerOfMass [
            -0.00607 0 0.011765
          ]
          inertiaMatrix [
            6.0236e-06 2.4343e-05 2.1328e-05
            -2.05966e-08 7.97442e-07 -8.88603e-13
          ]
        }
        linearVelocity -3.0786393927260374e-07 -2.1584912704540313e-06 4.728779141522026e-07
        angularVelocity 1.5373413106764884e-05 1.28638001165032e-07 2.52480315736388e-06
      }
    }
    HingeJoint {
      jointParameters HingeJointParameters {
        position -5.48361830309927e-07
        axis 3e-06 0 1
        anchor 0.046375 -0.011254 -0.0035
      }
      device [
        RotationalMotor {
          name "left_hip_yaw"
          maxVelocity 6
        }
        PositionSensor {
          name "left_hip_yaw_sensor"
        }
      ]
      endPoint Solid {
        translation 0.046375 -0.011254 -0.0035
        rotation -0.7071054750595757 -0.7071080873103996 1.0000007525906057e-06 3.141591000000615
        children [
          Pose {
            translation -0.00494 0 0.003
            children [
              Shape {
                appearance USE u_base_motors_blocs_material
                geometry Box {
                  size 0.05 0.03 0.006
                }
              }
            ]
          }
          Pose {
            translation 0.0219 0 0.023
            rotation 0.5773496025226483 -0.5773516025212714 -0.5773496025226483 2.094399
            children [
              Shape {
                appearance USE u_side_small_with_trace_material
                geometry Box {
                  size 0.027 0.042 0.003
                }
              }
            ]
          }
          Pose {
            translation -0.03144 0 0.023
            rotation 0.5773496025226483 0.5773516025212714 0.5773496025226483 2.094399
            children [
              Shape {
                appearance USE u_side_small_material
                geometry Box {
                  size 0.025 0.044 0.003
                }
              }
            ]
          }
          HingeJoint {
            jointParameters HingeJointParameters {
              position -1.4010455619905532e-06
              axis -1 -4e-06 -4e-06
              anchor 0.0234 0 0.04
            }
            device [
              RotationalMotor {
                name "left_hip_roll"
                maxVelocity 6
              }
              PositionSensor {
                name "left_hip_roll_sensor"
              }
            ]
            endPoint Solid {
              translation 0.0234 0 0.04
              rotation -0.5773493328887819 -0.5773521417830413 0.5773493328924988 2.0943981911070906
              children [
                Pose {
                  translation 0 -0.015 -0.026
                  children [
                    Shape {
                      appearance USE mx106_material
                      geometry Box {
                        size 0.03 0.055 0.04
                      }
                    }
                  ]
                }
                Pose {
                  translation 0 -0.015 0.0234
                  rotation 0 1 0 1.5708
                  children [
                    Shape {
                      appearance USE mx106_material
                      geometry Box {
                        size 0.03 0.055 0.04
                      }
                    }
                  ]
                }
                HingeJoint {
                  jointParameters HingeJointParameters {
                    position 2.464685878828855e-08
                    axis 1 0 4e-06
                    anchor 0.026 0 0.0234
                  }
                  device [
                    RotationalMotor {
                      name "left_hip_pitch"
                      maxVelocity 6
                    }
                    PositionSensor {
                      name "left_hip_pitch_sensor"
                    }
                  ]
                  endPoint Solid {
                    translation 0.026 0 0.0234
                    rotation 1.2323433421362702e-08 -0.9999999999999998 -1.2323380100509139e-08 1.5708
                    children [
                      Pose {
                        translation 0 -0.0825 0.026
                        rotation -0.5773496025226482 0.5773496025226482 0.5773516025212713 2.094399
                        children [
                          Shape {
                            appearance USE u_base_64_material
                            geometry Box {
                              size 0.047 0.0275 0.006
                            }
                          }
                        ]
                      }
                      Pose {
                        translation 0 -0.0395 -0.0015
                        children [
                          Shape {
                            appearance USE u_side_femur_material
                            geometry Box {
                              size 0.04 0.09 0.003
                            }
                          }
                        ]
                      }
                      Pose {
                        translation 0 -0.0395 0.0535
                        children [
                          Shape {
                            appearance USE u_side_femur_mir_material
                            geometry Box {
                              size 0.04 0.09 0.003
                            }
                          }
                        ]
                      }
                      Pose {
                        translation 0 -0.125 0.026
                        rotation -1 0 0 3.14159
                        children [
                          Shape {
                            appearance USE mx106_material
                            geometry Box {
                              size 0.03 0.055 0.04
                            }
                          }
                        ]
                      }
                      HingeJoint {
                        jointParameters HingeJointParameters {
                          position 2.3149763394867417e-08
                          axis 0 0 -1
                          anchor 0 -0.14 0
                        }
                        device [
                          RotationalMotor {
                            name "left_knee"
                            maxVelocity 6
                          }
                          PositionSensor {
                            name "left_knee_sensor"
                          }
                        ]
                        endPoint Solid {
                          translation 0 -0.14 0
                          rotation 0 0 -1 2.9802322387695313e-08
                          children [
                            Pose {
                              translation 0 -0.067 -0.0015
                              children [
                                Shape {
                                  appearance USE tibia_plate_material
                                  geometry Box {
                                    size 0.03 0.165 0.003
                                  }
                                }
                              ]
                            }
                            Pose {
                              translation 0 -0.067 0.0535
                              children [
                                Shape {
                                  appearance USE tibia_plate_material
                                  geometry Box {
                                    size 0.03 0.165 0.003
                                  }
                                }
                              ]
                            }
                            HingeJoint {
                              jointParameters HingeJointParameters {
                                position 6.302095778291718e-08
                                axis 0 -3e-06 -1
                                anchor 0 -0.14 0
                              }
                              device [
                                RotationalMotor {
                                  name "left_ankle_pitch"
                                  maxVelocity 6
                                }
                                PositionSensor {
                                  name "left_ankle_pitch_sensor"
                                }
                              ]
                              endPoint Solid {
                                translation 0 -0.14 0
                                rotation 0.9999999999999996 -3.151047889144216e-08 5.2723494089118194e-14 3.14159
                                children [
                                  Pose {
                                    translation 0 -0.015 -0.026
                                    children [
                                      Shape {
                                        appearance USE mx106_material
                                        geometry Box {
                                          size 0.03 0.055 0.04
                                        }
                                      }
                                    ]
                                  }
                                  Pose {
                                    translation -0.0494 -0.015 -0.026
                                    rotation 0 1 0 1.5708
                                    children [
                                      Shape {
                                        appearance USE mx106_material
                                        geometry Box {
                                          size 0.03 0.055 0.04
                                        }
                                      }
                                    ]
                                  }
                                  HingeJoint {
                                    jointParameters HingeJointParameters {
                                      position -1.6982581342045143e-06
                                      axis 1 3e-06 4e-06
                                      anchor -0.0234 0 -0.026
                                    }
                                    device [
                                      RotationalMotor {
                                        name "left_ankle_roll"
                                        maxVelocity 6
                                      }
                                      PositionSensor {
                                        name "left_ankle_roll_sensor"
                                      }
                                    ]
                                    endPoint Solid {
                                      translation -0.0234 0 -0.026
                                      rotation -0.7071052811824289 -1.6004241910973778e-06 -0.7071082811856731 3.141592200852099
                                      children [
                                        Pose {
                                          translation 0.0055 -0.0275 0.12247
                                          rotation -0.6785971692089039 0.6786001692096519 0.28108307008835337 2.593562
                                          children [
                                            Shape {
                                              appearance USE foot_protection_material
                                              geometry Box {
                                                size 0.01 0.09 0.01
                                              }
                                            }
                                          ]
                                        }
                                        Pose {
                                          translation 0.0435 -0.05 -0.03213
                                          rotation -0.17069990706382648 -0.6967296206712351 0.696727620672324 3.47973
                                          children [
                                            Shape {
                                              appearance USE cleat_material
                                              geometry Cylinder {
                                                height 0.02
                                                radius 0.008
                                              }
                                            }
                                          ]
                                        }
                                        Pose {
                                          translation 0 -0.017 0.05484
                                          rotation -1e-06 1 -1e-06 3.141593
                                          children [
                                            Shape {
                                              appearance USE u_side_small_material
                                              geometry Box {
                                                size 0.025 0.044 0.003
                                              }
                                            }
                                          ]
                                        }
                                        Pose {
                                          translation 0.0435 -0.05 0.10947
                                          rotation -0.17069990706382648 -0.6967296206712351 0.696727620672324 3.47973
                                          children [
                                            Shape {
                                              appearance USE cleat_material
                                              geometry Cylinder {
                                                height 0.02
                                                radius 0.008
                                              }
                                            }
                                          ]
                                        }
                                        Pose {
                                          translation 0 -0.037 0.02834
                                          rotation -0.5773496025226482 0.5773496025226482 0.5773516025212713 2.094399
                                          children [
                                            Shape {
                                              appearance USE u_base_motors_blocs_material
                                              geometry Box {
                                                size 0.05 0.03 0.006
                                              }
                                            }
                                          ]
                                        }
                                        Pose {
                                          translation -0.0325 -0.05 0.10947
                                          rotation -0.17069990706382648 -0.6967296206712351 0.696727620672324 3.47973
                                          children [
                                            Shape {
                                              appearance USE cleat_material
                                              geometry Cylinder {
                                                height 0.02
                                                radius 0.008
                                              }
                                            }
                                          ]
                                        }
                                        Pose {
                                          translation -0.0325 -0.05 -0.03213
                                          rotation 0.17069808427084848 0.6967303439643596 -0.6967273439628786 2.803451
                                          children [
                                            Shape {
                                              appearance USE cleat_material
                                              geometry Cylinder {
                                                height 0.02
                                                radius 0.008
                                              }
                                            }
                                          ]
                                        }
                                        Pose {
                                          translation 0 -0.017 0.0015
                                          children [
                                            Shape {
                                              appearance USE u_side_small_with_trace_material
                                              geometry Box {
                                                size 0.027 0.042 0.003
                                              }
                                            }
                                          ]
                                        }
                                        Pose {
                                          translation 0.0055 -0.0415 0.03867
                                          rotation 1.0000003976552372e-06 -0.7071082811851994 -0.7071052811840065 3.141591
                                          children [
                                            Shape {
                                              appearance USE foot_plate_material
                                              geometry Box {
                                                size 0.09 0.155 0.003
                                              }
                                            }
                                          ]
                                        }
                                      ]
                                      name "left_foot_cleat_front_right"
                                      boundingObject Group {
                                        children [
                                          Pose {
                                            translation 0.0055 -0.0275 0.12247
                                            rotation -0.6785971692089039 0.6786001692096519 0.28108307008835337 2.593562
                                            children [
                                              Box {
                                                size 0.01 0.09 0.01
                                              }
                                            ]
                                          }
                                          Pose {
                                            translation 0.0435 -0.05 -0.03213
                                            rotation -0.17069990706382648 -0.6967296206712351 0.696727620672324 3.47973
                                            children [
                                              Cylinder {
                                                height 0.02
                                                radius 0.008
                                              }
                                            ]
                                          }
                                          Pose {
                                            translation 0 -0.017 0.05484
                                            rotation -1e-06 1 -1e-06 3.141593
                                            children [
                                              Box {
                                                size 0.025 0.044 0.003
                                              }
                                            ]
                                          }
                                          Pose {
                                            translation 0.0435 -0.05 0.10947
                                            rotation -0.17069990706382648 -0.6967296206712351 0.696727620672324 3.47973
                                            children [
                                              Cylinder {
                                                height 0.02
                                                radius 0.008
                                              }
                                            ]
                                          }
                                          Pose {
                                            translation 0 -0.037 0.02834
                                            rotation -0.5773496025226482 0.5773496025226482 0.5773516025212713 2.094399
                                            children [
                                              Box {
                                                size 0.05 0.03 0.006
                                              }
                                            ]
                                          }
                                          Pose {
                                            translation -0.0325 -0.05 0.10947
                                            rotation -0.17069990706382648 -0.6967296206712351 0.696727620672324 3.47973
                                            children [
                                              Cylinder {
                                                height 0.02
                                                radius 0.008
                                              }
                                            ]
                                          }
                                          Pose {
                                            translation -0.0325 -0.05 -0.03213
                                            rotation 0.17069808427084848 0.6967303439643596 -0.6967273439628786 2.803451
                                            children [
                                              Cylinder {
                                                height 0.02
                                                radius 0.008
                                              }
                                            ]
                                          }
                                          Pose {
                                            translation 0 -0.017 0.0015
                                            children [
                                              Box {
                                                size 0.027 0.042 0.003
                                              }
                                            ]
                                          }
                                          Pose {
                                            translation 0.0055 -0.0415 0.03867
                                            rotation 1.0000003976552372e-06 -0.7071082811851994 -0.7071052811840065 3.141591
                                            children [
                                              Box {
                                                size 0.09 0.155 0.003
                                              }
                                            ]
                                          }
                                        ]
                                      }
                                      physics Physics {
                                        density -1
                                        mass 0.239067
                                        centerOfMass [
                                          0.004685 -0.036578 0.051153
                                        ]
                                        inertiaMatrix [
                                          0.000644736 0.000780874 0.000195711
                                          5.21256e-07 -4.22638e-06 -2.65367e-05
                                        ]
                                      }
                                      linearVelocity 2.0603803894554565e-07 7.187252777277002e-08 1.8886755908323483e-06
                                      angularVelocity -2.997494558907525e-06 1.1162703754014698e-05 -1.5837708619251953e-06
                                    }
                                  }
                                ]
                                name "mx106_block_mir_2"
                                boundingObject Group {
                                  children [
                                    Pose {
                                      translation 0 -0.015 -0.026
                                      children [
                                        Box {
                                          size 0.03 0.055 0.04
                                        }
                                      ]
                                    }
                                    Pose {
                                      translation -0.0494 -0.015 -0.026
                                      rotation 0 1 0 1.5708
                                      children [
                                        Box {
                                          size 0.03 0.055 0.04
                                        }
                                      ]
                                    }
                                  ]
                                }
                                physics Physics {
                                  density -1
                                  mass 0.427481
                                  centerOfMass [
                                    -0.019483 -0.018098 -0.025696
                                  ]
                                  inertiaMatrix [
                                    0.000194261 0.000412323 0.000487688
                                    -2.04803e-05 -3.71621e-06 -3.98084e-06
                                  ]
                                }
                                linearVelocity 4.492453845163649e-07 2.47214360583045e-07 1.4663771313496556e-06
                                angularVelocity -2.9932398320584974e-06 4.512419215096737e-06 -1.772267040236687e-06
                              }
                            }
                          ]
                          name "tibia_2"
                          boundingObject Group {
                            children [
                              Pose {
                                translation 0 -0.067 -0.0015
                                children [
                                  Box {
                                    size 0.03 0.165 0.003
                                  }
                                ]
                              }
                              Pose {
                                translation 0 -0.067 0.0535
                                children [
                                  Box {
                                    size 0.03 0.165 0.003
                                  }
                                ]
                              }
                            ]
                          }
                          physics Physics {
                            density -1
                            mass 0.088844
                            centerOfMass [
                              -0.003422 -0.064607 0.026
                            ]
                            inertiaMatrix [
                              0.000245247 7.67255e-05 0.000187463
                              6.12719e-06 -1.44286e-11 3.8066e-11
                            ]
                          }
                          linearVelocity 3.6098519095032896e-07 -8.349044029156642e-08 1.2605225331907335e-06
                          angularVelocity 3.8051091968770434e-06 4.528699165047348e-06 -1.959964597044756e-06
                        }
                      }
                    ]
                    name "left_knee_1"
                    boundingObject Group {
                      children [
                        Pose {
                          translation 0 -0.0825 0.026
                          rotation -0.5773496025226482 0.5773496025226482 0.5773516025212713 2.094399
                          children [
                            Box {
                              size 0.047 0.0275 0.006
                            }
                          ]
                        }
                        Pose {
                          translation 0 -0.0395 -0.0015
                          children [
                            Box {
                              size 0.04 0.09 0.003
                            }
                          ]
                        }
                        Pose {
                          translation 0 -0.0395 0.0535
                          children [
                            Box {
                              size 0.04 0.09 0.003
                            }
                          ]
                        }
                        Pose {
                          translation 0 -0.125 0.026
                          rotation -1 0 0 3.14159
                          children [
                            Box {
                              size 0.03 0.055 0.04
                            }
                          ]
                        }
                      ]
                    }
                    physics Physics {
                      density -1
                      mass 0.269758
                      centerOfMass [
                        -5.7e-05 -0.098034 0.025527
                      ]
                      inertiaMatrix [
                        0.000503557 0.000109916 0.000438656
                        1.64719e-06 -5.01987e-07 -5.37384e-06
                      ]
                    }
                    linearVelocity 5.194521591067869e-07 -7.458131532432864e-07 9.796687243756402e-07
                    angularVelocity 1.013173297767056e-05 4.590114010876266e-06 -2.147680542716827e-06
                  }
                }
              ]
              name "mx106_block_2"
              boundingObject Group {
                children [
                  Pose {
                    translation 0 -0.015 -0.026
                    children [
                      Box {
                        size 0.03 0.055 0.04
                      }
                    ]
                  }
                  Pose {
                    translation 0 -0.015 0.0234
                    rotation 0 1 0 1.5708
                    children [
                      Box {
                        size 0.03 0.055 0.04
                      }
                    ]
                  }
                ]
              }
              physics Physics {
                density -1
                mass 0.427481
                centerOfMass [
                  0.000175 -0.018098 0.003812
                ]
                inertiaMatrix [
                  0.000480875 0.000406226 0.000203698
                  1.44566e-05 -4.949e-07 -3.86323e-05
                ]
              }
              linearVelocity 6.097269365735055e-07 -1.4504364115828808e-06 1.049331444600148e-06
              angularVelocity 1.5369206103097582e-05 4.69722103801283e-06 -2.3354310802758187e-06
            }
          }
        ]
        name "u_block_2"
        boundingObject Group {
          children [
            Pose {
              translation -0.00494 0 0.003
              children [
                Box {
                  size 0.05 0.03 0.006
                }
              ]
            }
            Pose {
              translation 0.0219 0 0.023
              rotation 0.5773496025226483 -0.5773516025212714 -0.5773496025226483 2.094399
              children [
                Box {
                  size 0.027 0.042 0.003
                }
              ]
            }
            Pose {
              translation -0.03144 0 0.023
              rotation 0.5773496025226483 0.5773516025212714 0.5773496025226483 2.094399
              children [
                Box {
                  size 0.025 0.044 0.003
                }
              ]
            }
          ]
        }
        physics Physics {
          density -1
          mass 0.03544
          centerOfMass [
            -0.00607 0 0.011765
          ]
          inertiaMatrix [
            6.0236e-06 2.4343e-05 2.1328e-05
            -2.05966e-08 7.97442e-07 -8.88603e-13
          ]
        }
        linearVelocity 3.0525610251520977e-07 -2.1584113628767044e-06 4.728441160563268e-07
        angularVelocity 1.537348972173926e-05 -1.2877447759582817e-07 -2.525686602652371e-06
      }
    }
    HingeJoint {
      jointParameters HingeJointParameters {
        position 3.650887512850792e-08
        axis 1 -4e-06 -4e-06
        anchor 0.0735 -0.032127 0.1609
      }
      device [
        RotationalMotor {
          name "left_shoulder_pitch"
          maxVelocity 6
        }
        PositionSensor {
          name "left_shoulder_pitch_sensor"
        }
      ]
      endPoint Solid {
        translation 0.0735 -0.032127 0.1609
        rotation -0.5773495954964512 0.57735161657352 -0.5773495954965479 2.0943989789216158
        children [
          Pose {
            translation 0 0 0.003
            children [
              Shape {
                appearance USE u_base_64_material
                geometry Box {
                  size 0.047 0.0275 0.006
                }
              }
            ]
          }
          HingeJoint {
            jointParameters HingeJointParameters {
              position 6.088426363872786e-09
              axis 1 3e-06 4e-06
              anchor 0.0225 0.03 0.035
            }
            device [
              RotationalMotor {
                name "left_shoulder_roll"
                maxVelocity 6
              }
              PositionSensor {
                name "left_shoulder_roll_sensor"
              }
            ]
            endPoint Solid {
              translation 0.0225 0.03 0.035
              rotation -0.7071052811840117 -9.978478179149357e-07 -0.7071082811851973 3.1415909956948243
              children [
                Pose {
                  translation 0 -0.015 -0.0235
                  children [
                    Shape {
                      appearance USE mx64_material
                      geometry Box {
                        size 0.029 0.05 0.04
                      }
                    }
                  ]
                }
                Pose {
                  translation 0 -0.092 -0.039174
                  rotation 0 -1 0 1.5708
                  children [
                    Shape {
                      appearance DEF humerus_plate_material PBRAppearance {
                        baseColor 0.301961 0.301961 0.301961
                        roughness 1
                        metalness 0
                      }
                      geometry Box {
                        size 0.003 0.07 0.03
                      }
                    }
                  ]
                }
                Pose {
                  translation 0 -0.054 -0.023174
                  rotation 0 -1 0 1.5708
                  children [
                    Shape {
                      appearance USE humerus_plate_material
                      geometry Box {
                        size 0.03 0.003 0.03
                      }
                    }
                  ]
                }
                HingeJoint {
                  jointParameters HingeJointParameters {
                    position 7.430407219878902e-10
                    axis 1 0 -4e-06
                    anchor 0.0235 -0.112 -0.001674
                  }
                  device [
                    RotationalMotor {
                      name "left_elbow"
                      maxVelocity 6
                    }
                    PositionSensor {
                      name "left_elbow_sensor"
                    }
                  ]
                  endPoint Solid {
                    translation 0.0235 -0.112 -0.001674
                    rotation 2.8121365197040365e-10 1 2.8121243521924814e-10 1.5708
                    children [
                      Pose {
                        translation 0 -0.015 -0.0235
                        children [
                          Shape {
                            appearance USE mx64_material
                            geometry Box {
                              size 0.029 0.05 0.04
                            }
                          }
                        ]
                      }
                      Pose {
                        translation 0.018 -0.0985 -0.0235
                        rotation -1e-06 -1 1e-06 3.141593
                        children [
                          Shape {
                            appearance DEF radius_plate_material PBRAppearance {
                              baseColor 0.301961 0.301961 0.301961
                              roughness 1
                              metalness 0
                            }
                            geometry Box {
                              size 0.003 0.085 0.03
                            }
                          }
                        ]
                      }
                      Pose {
                        translation 0.0075 -0.141 -0.0235
                        rotation -1e-06 -1 1e-06 3.141593
                        children [
                          Shape {
                            appearance USE radius_plate_material
                            geometry Cylinder {
                              height 0.03
                              radius 0.012
                            }
                          }
                        ]
                      }
                    ]
                    name "left_radius_1"
                    boundingObject Group {
                      children [
                        Pose {
                          translation 0 -0.015 -0.0235
                          children [
                            Box {
                              size 0.029 0.05 0.04
                            }
                          ]
                        }
                        Pose {
                          translation 0.018 -0.0985 -0.0235
                          rotation -1e-06 -1 1e-06 3.141593
                          children [
                            Box {
                              size 0.003 0.085 0.03
                            }
                          ]
                        }
                        Pose {
                          translation 0.0075 -0.141 -0.0235
                          rotation -1e-06 -1 1e-06 3.141593
                          children [
                            Cylinder {
                              height 0.03
                              radius 0.012
                            }
                          ]
                        }
                      ]
                    }
                    physics Physics {
                      density -1
                      mass 0.20688
                      centerOfMass [
                        0.002534 -0.03704 -0.023878
                      ]
                      inertiaMatrix [
                        0.00037903 5.36268e-05 0.00036378
                        3.04226e-05 4.20803e-07 -4.7904e-07
                      ]
                    }
                    linearVelocity 1.4601942806021528e-07 -2.5154289891686503e-06 -3.1127127707014236e-07
                    angularVelocity 1.2428193884192132e-05 -9.901598783365637e-07 -4.0883520330452795e-11
                  }
                }
              ]
              name "left_humerus_1"
              boundingObject Group {
                children [
                  Pose {
                    translation 0 -0.015 -0.0235
                    children [
                      Box {
                        size 0.029 0.05 0.04
                      }
                    ]
                  }
                  Pose {
                    translation 0 -0.092 -0.039174
                    rotation 0 -1 0 1.5708
                    children [
                      Box {
                        size 0.003 0.07 0.03
                      }
                    ]
                  }
                  Pose {
                    translation 0 -0.054 -0.023174
                    rotation 0 -1 0 1.5708
                    children [
                      Box {
                        size 0.03 0.003 0.03
                      }
                    ]
                  }
                ]
              }
              physics Physics {
                density -1
                mass 0.214223
                centerOfMass [
                  -0.000853 -0.03764 -0.024852
                ]
                inertiaMatrix [
                  0.000347701 6.51166e-05 0.000333302
                  -1.37313e-05 2.97277e-06 -8.64098e-06
                ]
              }
              linearVelocity 3.580248129045029e-08 -3.962819990694035e-06 -9.13883347893857e-09
              angularVelocity 1.3272255718777951e-05 -9.895578685930786e-07 -3.416577391817679e-11
            }
          }
        ]
        name "u_shoulder_1"
        boundingObject Pose {
          translation 0 0 0.003
          children [
            Box {
              size 0.047 0.0275 0.006
            }
          ]
        }
        physics Physics {
          density -1
          mass 0.042898
          centerOfMass [
            0 0.00486 0.016783
          ]
          inertiaMatrix [
            1.57991e-05 2.84983e-05 2.50037e-05
            1.59248e-20 -7.27391e-21 -3.76137e-06
          ]
        }
        linearVelocity -1.3744865402166487e-09 -4.797112600986766e-06 1.2372217806200446e-08
        angularVelocity 1.3272922932679518e-05 1.7836732535236973e-09 -1.0006770048964756e-09
      }
    }
    HingeJoint {
      jointParameters HingeJointParameters {
        position 2.187076409197776e-08
        axis 1 4e-06 4e-06
        anchor -0.074087 -0.032127 0.1609
      }
      device [
        RotationalMotor {
          name "right_shoulder_pitch"
          maxVelocity 6
        }
        PositionSensor {
          name "right_shoulder_pitch_sensor"
        }
      ]
      endPoint Solid {
        translation -0.074087 -0.032127 0.1609
        rotation -0.5773495983135812 -0.577351610939318 0.5773495983136393 2.094398987372923
        children [
          Pose {
            translation 0 0 0.003
            children [
              Shape {
                appearance USE u_base_64_material
                geometry Box {
                  size 0.047 0.0275 0.006
                }
              }
            ]
          }
          HingeJoint {
            jointParameters HingeJointParameters {
              position -5.800543703136287e-09
              axis -1 -3e-06 4e-06
              anchor -0.0225 0.03 0.035
            }
            device [
              RotationalMotor {
                name "right_shoulder_roll"
                maxVelocity 6
              }
              PositionSensor {
                name "right_shoulder_roll_sensor"
              }
            ]
            endPoint Solid {
              translation -0.0225 0.03 0.035
              rotation 0.7071052811840017 1.0020511956959595e-06 -0.7071082811852015 3.1415910041016115
              children [
                Pose {
                  translation 0 -0.092 -0.04
                  rotation 0 -1 0 1.5708
                  children [
                    Shape {
                      appearance USE humerus_plate_material
                      geometry Box {
                        size 0.003 0.07 0.03
                      }
                    }
                  ]
                }
                Pose {
                  translation 0 -0.054 -0.024
                  rotation 0 -1 0 1.5708
                  children [
                    Shape {
                      appearance USE humerus_plate_material
                      geometry Box {
                        size 0.03 0.003 0.03
                      }
                    }
                  ]
                }
                Pose {
                  translation 0 -0.015 -0.0235
                  children [
                    Shape {
                      appearance USE mx64_material
                      geometry Box {
                        size 0.029 0.05 0.04
                      }
                    }
                  ]
                }
                HingeJoint {
                  jointParameters HingeJointParameters {
                    position -1.5891877997847884e-07
                    axis 1 0 4e-06
                    anchor -0.0235 -0.112 -0.0025
                  }
                  device [
                    RotationalMotor {
                      name "right_elbow"
                      maxVelocity 6
                    }
                    PositionSensor {
                      name "right_elbow_sensor"
                    }
                  ]
                  endPoint Solid {
                    translation -0.0235 -0.112 -0.0025
                    rotation -7.945941595606264e-08 -0.9999999999999938 7.945907215221098e-08 1.570800000000006
                    children [
                      Pose {
                        translation -0.018 -0.0985 -0.0235
                        children [
                          Shape {
                            appearance USE radius_plate_material
                            geometry Box {
                              size 0.003 0.085 0.03
                            }
                          }
                        ]
                      }
                      Pose {
                        translation -0.0075 -0.141 -0.0235
                        children [
                          Shape {
                            appearance USE radius_plate_material
                            geometry Cylinder {
                              height 0.03
                              radius 0.012
                            }
                          }
                        ]
                      }
                      Pose {
                        translation 0 -0.015 -0.0235
                        children [
                          Shape {
                            appearance USE mx64_material
                            geometry Box {
                              size 0.029 0.05 0.04
                            }
                          }
                        ]
                      }
                    ]
                    name "right_radius_1"
                    boundingObject Group {
                      children [
                        Pose {
                          translation -0.018 -0.0985 -0.0235
                          children [
                            Box {
                              size 0.003 0.085 0.03
                            }
                          ]
                        }
                        Pose {
                          translation -0.0075 -0.141 -0.0235
                          children [
                            Cylinder {
                              height 0.03
                              radius 0.012
                            }
                          ]
                        }
                        Pose {
                          translation 0 -0.015 -0.0235
                          children [
                            Box {
                              size 0.029 0.05 0.04
                            }
                          ]
                        }
                      ]
                    }
                    physics Physics {
                      density -1
                      mass 0.20688
                      centerOfMass [
                        -0.002335 -0.03704 -0.023635
                      ]
                      inertiaMatrix [
                        0.000379056 5.38522e-05 0.00036398
                        -3.24125e-05 7.54143e-07 -9.99715e-09
                      ]
                    }
                    linearVelocity -1.5423068354404594e-07 -2.5115626960916964e-06 -3.0290427545267393e-07
                    angularVelocity 1.2456330941877158e-05 1.0270520722866375e-06 -2.095060703540721e-09
                  }
                }
              ]
              name "right_humerus_1"
              boundingObject Group {
                children [
                  Pose {
                    translation 0 -0.092 -0.04
                    rotation 0 -1 0 1.5708
                    children [
                      Box {
                        size 0.003 0.07 0.03
                      }
                    ]
                  }
                  Pose {
                    translation 0 -0.054 -0.024
                    rotation 0 -1 0 1.5708
                    children [
                      Box {
                        size 0.03 0.003 0.03
                      }
                    ]
                  }
                  Pose {
                    translation 0 -0.015 -0.0235
                    children [
                      Box {
                        size 0.029 0.05 0.04
                      }
                    ]
                  }
                ]
              }
              physics Physics {
                density -1
                mass 0.214223
                centerOfMass [
                  0.001044 -0.03764 -0.025366
                ]
                inertiaMatrix [
                  0.000347788 6.5125e-05 0.000333224
                  1.17167e-05 -1.66771e-06 -1.16648e-05
                ]
              }
              linearVelocity -3.986011060453472e-08 -3.961420381344686e-06 -2.5047131117166836e-09
              angularVelocity 1.3292333258953735e-05 1.026458266764749e-06 -2.0993194164035312e-09
            }
          }
        ]
        name "u_shoulder_2"
        boundingObject Pose {
          translation 0 0 0.003
          children [
            Box {
              size 0.047 0.0275 0.006
            }
          ]
        }
        physics Physics {
          density -1
          mass 0.042898
          centerOfMass [
            0 0.00486 0.016783
          ]
          inertiaMatrix [
            1.57991e-05 2.84983e-05 2.50037e-05
            6.77626e-21 -1.35525e-20 -3.76137e-06
          ]
        }
        linearVelocity -1.3023405075564984e-09 -4.79692152969619e-06 1.2359377750142333e-08
        angularVelocity 1.3293044489067184e-05 -1.9260771541750245e-09 -1.0904194822676877e-09
      }
    }
    HingeJoint {
      jointParameters HingeJointParameters {
        position 6.39397965128237e-11
        axis 0 0 1
        anchor 0 -0.037127 0.1858
      }
      device [
        RotationalMotor {
          name "head_yaw"
          maxVelocity 6
        }
        PositionSensor {
          name "head_yaw_sensor"
        }
      ]
      endPoint Solid {
        translation 0 -0.037127 0.1858
        rotation 0 0 -1 3.141589999930459
        children [
          Pose {
            translation 0 0 0.003
            children [
              Shape {
                appearance USE u_base_64_material
                geometry Box {
                  size 0.047 0.0275 0.006
                }
              }
            ]
          }
          Pose {
            translation -0.025 0 0.023
            rotation 0.5773496025226483 0.5773516025212714 0.5773496025226483 2.094399
            children [
              Shape {
                appearance USE u_side_small_material
                geometry Box {
                  size 0.025 0.044 0.003
                }
              }
            ]
          }
          Pose {
            translation 0.025 0 0.023
            rotation 0.5773496025226483 -0.5773516025212714 -0.5773496025226483 2.094399
            children [
              Shape {
                appearance USE u_side_small_material
                geometry Box {
                  size 0.025 0.044 0.003
                }
              }
            ]
          }
          HingeJoint {
            jointParameters HingeJointParameters {
              position 7.002224004813785e-09
              axis -1 -4e-06 -4e-06
              anchor -0.0235 0 0.04
            }
            device [
              RotationalMotor {
                name "head_pitch"
                maxVelocity 6
              }
              PositionSensor {
                name "head_pitch_sensor"
              }
            ]
            endPoint Solid {
              translation -0.0235 0 0.04
              rotation -0.5773496038702386 -0.5773515998261186 0.57734960387022 2.0943990040427307
              children [
                Pose {
                  translation -0.0375 -0.0698 -0.005
                  rotation -1 0 0 3.14159
                  children [
                    Shape {
                      appearance DEF head_plate_material PBRAppearance {
                        baseColor 0.701961 0.682353 0.623529
                        roughness 1
                        metalness 0
                      }
                      geometry Box {
                        size 0.008 0.05 0.003
                      }
                    }
                  ]
                }
                Pose {
                  translation 0 -0.0698 -0.005
                  rotation -1 0 0 3.14159
                  children [
                    Shape {
                      appearance USE head_plate_material
                      geometry Box {
                        size 0.008 0.05 0.003
                      }
                    }
                  ]
                }
                Pose {
                  translation 0.0375 -0.0698 -0.005
                  rotation -1 0 0 3.14159
                  children [
                    Shape {
                      appearance USE head_plate_material
                      geometry Box {
                        size 0.008 0.05 0.003
                      }
                    }
                  ]
                }
                Pose {
                  translation 0 -0.0468 -0.005
                  rotation -1 0 0 3.14159
                  children [
                    Shape {
                      appearance USE head_plate_material
                      geometry Box {
                        size 0.083 0.008 0.003
                      }
                    }
                  ]
                }
                Pose {
                  translation 0 -0.0698 -0.005
                  rotation -1 0 0 3.14159
                  children [
                    Shape {
                      appearance USE head_plate_material
                      geometry Box {
                        size 0.083 0.008 0.003
                      }
                    }
                  ]
                }
                Pose {
                  translation 0 -0.0928 -0.005
                  rotation -1 0 0 3.14159
                  children [
                    Shape {
                      appearance USE head_plate_material
                      geometry Box {
                        size 0.083 0.008 0.003
                      }
                    }
                  ]
                }
                Pose {
                  translation 0.004968 -0.06905 -0.0235
                  rotation 0.5773496025226482 -0.5773496025226482 0.5773516025212713 2.094399
                  children [
                    Shape {
                      appearance DEF ptgrey_camera_material PBRAppearance {
                        baseColor 0.4 0.4 0.4
                        roughness 1
                        metalness 0
                      }
                      geometry Box {
                        size 0.03 0.03 0.028
                      }
                    }
                  ]
                }
                Pose {
                  translation -0.0375 -0.0698 -0.042
                  rotation -1 0 0 3.14159
                  children [
                    Shape {
                      appearance USE head_plate_material
                      geometry Box {
                        size 0.008 0.05 0.003
                      }
                    }
                  ]
                }
                Pose {
                  translation 0 -0.0698 -0.042
                  rotation -1 0 0 3.14159
                  children [
                    Shape {
                      appearance USE head_plate_material
                      geometry Box {
                        size 0.008 0.05 0.003
                      }
                    }
                  ]
                }
                Pose {
                  translation 0.0375 -0.0698 -0.042
                  rotation -1 0 0 3.14159
                  children [
                    Shape {
                      appearance USE head_plate_material
                      geometry Box {
                        size 0.008 0.05 0.003
                      }
                    }
                  ]
                }
                Pose {
                  translation 0 -0.0468 -0.042
                  rotation -1 0 0 3.14159
                  children [
                    Shape {
                      appearance USE head_plate_material
                      geometry Box {
                        size 0.083 0.008 0.003
                      }
                    }
                  ]
                }
                Pose {
                  translation 0 -0.0698 -0.042
                  rotation -1 0 0 3.14159
                  children [
                    Shape {
                      appearance USE head_plate_material
                      geometry Box {
                        size 0.083 0.008 0.003
                      }
                    }
                  ]
                }
                Pose {
                  translation 0 -0.0928 -0.042
                  rotation -1 0 0 3.14159
                  children [
                    Shape {
                      appearance USE head_plate_material
                      geometry Box {
                        size 0.083 0.008 0.003
                      }
                    }
                  ]
                }
                Pose {
                  translation 0 -0.015 -0.0235
                  children [
                    Shape {
                      appearance USE mx64_material
                      geometry Box {
                        size 0.029 0.05 0.04
                      }
                    }
                  ]
                }
              ]
              name "head_1"
              boundingObject Group {
                children [
                  Pose {
                    translation -0.0375 -0.0698 -0.005
                    rotation -1 0 0 3.14159
                    children [
                      Box {
                        size 0.008 0.05 0.003
                      }
                    ]
                  }
                  Pose {
                    translation 0 -0.0698 -0.005
                    rotation -1 0 0 3.14159
                    children [
                      Box {
                        size 0.008 0.05 0.003
                      }
                    ]
                  }
                  Pose {
                    translation 0.0375 -0.0698 -0.005
                    rotation -1 0 0 3.14159
                    children [
                      Box {
                        size 0.008 0.05 0.003
                      }
                    ]
                  }
                  Pose {
                    translation 0 -0.0468 -0.005
                    rotation -1 0 0 3.14159
                    children [
                      Box {
                        size 0.083 0.008 0.003
                      }
                    ]
                  }
                  Pose {
                    translation 0 -0.0698 -0.005
                    rotation -1 0 0 3.14159
                    children [
                      Box {
                        size 0.083 0.008 0.003
                      }
                    ]
                  }
                  Pose {
                    translation 0 -0.0928 -0.005
                    rotation -1 0 0 3.14159
                    children [
                      Box {
                        size 0.083 0.008 0.003
                      }
                    ]
                  }
                  Pose {
                    translation 0.004968 -0.06905 -0.0235
                    rotation 0.5773496025226482 -0.5773496025226482 0.5773516025212713 2.094399
                    children [
                      Box {
                        size 0.03 0.03 0.028
                      }
                    ]
                  }
                  Pose {
                    translation -0.0375 -0.0698 -0.042
                    rotation -1 0 0 3.14159
                    children [
                      Box {
                        size 0.008 0.05 0.003
                      }
                    ]
                  }
                  Pose {
                    translation 0 -0.0698 -0.042
                    rotation -1 0 0 3.14159
                    children [
                      Box {
                        size 0.008 0.05 0.003
                      }
                    ]
                  }
                  Pose {
                    translation 0.0375 -0.0698 -0.042
                    rotation -1 0 0 3.14159
                    children [
                      Box {
                        size 0.008 0.05 0.003
                      }
                    ]
                  }
                  Pose {
                    translation 0 -0.0468 -0.042
                    rotation -1 0 0 3.14159
                    children [
                      Box {
                        size 0.083 0.008 0.003
                      }
                    ]
                  }
                  Pose {
                    translation 0 -0.0698 -0.042
                    rotation -1 0 0 3.14159
                    children [
                      Box {
                        size 0.083 0.008 0.003
                      }
                    ]
                  }
                  Pose {
                    translation 0 -0.0928 -0.042
                    rotation -1 0 0 3.14159
                    children [
                      Box {
                        size 0.083 0.008 0.003
                      }
                    ]
                  }
                  Pose {
                    translation 0 -0.015 -0.0235
                    children [
                      Box {
                        size 0.029 0.05 0.04
                      }
                    ]
                  }
                ]
              }
              physics Physics {
                density -1
                mass 0.228227
                centerOfMass [
                  0.001274 -0.034352 -0.023721
                ]
                inertiaMatrix [
                  0.000236902 8.77015e-05 0.000235668
                  9.17476e-06 5.76668e-07 -3.39163e-07
                ]
              }
              linearVelocity -1.432446065452633e-09 -6.416437274393502e-06 -8.709007714163924e-08
              angularVelocity 1.625001437636539e-05 -7.671229938219326e-10 -4.5318506192322105e-08
            }
          }
        ]
        name "u_neck_1"
        boundingObject Group {
          children [
            Pose {
              translation 0 0 0.003
              children [
                Box {
                  size 0.047 0.0275 0.006
                }
              ]
            }
            Pose {
              translation -0.025 0 0.023
              rotation 0.5773496025226483 0.5773516025212714 0.5773496025226483 2.094399
              children [
                Box {
                  size 0.025 0.044 0.003
                }
              ]
            }
            Pose {
              translation 0.025 0 0.023
              rotation 0.5773496025226483 -0.5773516025212714 -0.5773496025226483 2.094399
              children [
                Box {
                  size 0.025 0.044 0.003
                }
              ]
            }
          ]
        }
        physics Physics {
          density -1
          mass 0.036209
          centerOfMass [
            0 0 0.012892
          ]
          inertiaMatrix [
            6.41955e-06 2.38199e-05 2.02973e-05
            4.27371e-12 3.64701e-13 4.49501e-20
          ]
        }
        linearVelocity -1.347036387385722e-09 -5.44254884024589e-06 -3.9665547778771704e-08
        angularVelocity 1.5373578452108445e-05 -1.1791094179548373e-10 -4.528960506547209e-08
      }
    }
  ]
  name "Onshape"
  boundingObject Group {
    children [
      Pose {
        translation -0.031 -0.054127 0.0909
        children [
          Cylinder {
            height 0.086
            radius 0.004
          }
        ]
      }
      Pose {
        translation -0.046375 -0.026254 0.02
        rotation 1e-06 -1 -1e-06 3.141593
        children [
          Box {
            size 0.029 0.05 0.04
          }
        ]
      }
      Pose {
        translation 0.05 -0.017127 0.1609
        rotation -0.7071052811840065 -1.0000003976552372e-06 -0.7071082811851994 3.141591
        children [
          Box {
            size 0.029 0.05 0.04
          }
        ]
      }
      Pose {
        translation 0.046375 -0.026254 0.02
        rotation 1e-06 -1 -1e-06 3.141593
        children [
          Box {
            size 0.029 0.05 0.04
          }
        ]
      }
      Pose {
        translation 0 0.071323 0.1899
        rotation 0.5773496025226482 0.5773496025226482 -0.5773516025212713 2.094399
        children [
          Box {
            size 0.01 0.13 0.003
          }
        ]
      }
      Pose {
        translation -0.06 0.071323 0.1649
        rotation 0.5773496025226482 0.5773496025226482 -0.5773516025212713 2.094399
        children [
          Box {
            size 0.04 0.01 0.003
          }
        ]
      }
      Pose {
        translation 0.06 0.071323 0.1649
        rotation 0.5773496025226482 0.5773496025226482 -0.5773516025212713 2.094399
        children [
          Box {
            size 0.04 0.01 0.003
          }
        ]
      }
      Pose {
        translation 0.0625 0.037873 0.0909
        rotation -1 0 0 3.14159
        children [
          Cylinder {
            height 0.086
            radius 0.004
          }
        ]
      }
      Pose {
        translation -0.050587 -0.017127 0.1609
        rotation 0.7071052811840065 1.0000003976552372e-06 -0.7071082811851994 3.141591
        children [
          Box {
            size 0.029 0.05 0.04
          }
        ]
      }
      Pose {
        translation 0 -0.019127 0.1354
        rotation 1e-06 -1 -1e-06 3.141593
        children [
          Box {
            size 0.13 0.08 0.003
          }
        ]
      }
      Pose {
        translation 0 0.010373 0.0469
        children [
          Box {
            size 0.13 0.08 0.003
          }
        ]
      }
      Pose {
        translation -0.0625 0.037873 0.0909
        children [
          Cylinder {
            height 0.086
            radius 0.004
          }
        ]
      }
      Pose {
        translation 0 0.035873 0.10615
        rotation 1.0000003976552372e-06 -0.7071082811851994 -0.7071052811840065 3.141591
        children [
          Box {
            size 0.11 0.11 0.033
          }
        ]
      }
      Pose {
        translation 0 0.031123 0.0015
        children [
          Box {
            size 0.13 0.044 0.003
          }
        ]
      }
      Pose {
        translation -0.03 -0.007877 0.0015
        children [
          Box {
            size 0.01 0.035 0.003
          }
        ]
      }
      Pose {
        translation 0.03 -0.007877 0.0015
        children [
          Box {
            size 0.01 0.035 0.003
          }
        ]
      }
      Pose {
        translation 0 0.059373 0.1384
        rotation -0.7071052811840065 0.7071082811851994 -1.0000003976552372e-06 3.141591
        children [
          Box {
            size 0.01 0.135 0.003
          }
        ]
      }
      Pose {
        translation 0 -0.022127 0.1623
        rotation 0 0 -1 3.14159
        children [
          Box {
            size 0.029 0.05 0.04
          }
        ]
      }
      Pose {
        translation 0.031 -0.054127 0.0914
        children [
          Cylinder {
            height 0.086
            radius 0.004
          }
        ]
      }
    ]
  }
  physics Physics {
    density -1
    mass 1.75912
    centerOfMass [
      0.000186 0.00053 0.092243
    ]
    inertiaMatrix [
      0.00823896 0.00915867 0.00511156
      2.57494e-06 1.9734e-05 -0.000169433
    ]
  }
}
