#VRML_SIM R2023b utf8

EXTERNPROTO "https://raw.githubusercontent.com/cyberbotics/webots/R2022b/projects/objects/backgrounds/protos/TexturedBackground.proto"
EXTERNPROTO "https://raw.githubusercontent.com/cyberbotics/webots/R2022b/projects/objects/backgrounds/protos/TexturedBackgroundLight.proto"
EXTERNPROTO "https://raw.githubusercontent.com/cyberbotics/webots/R2022b/projects/objects/floors/protos/RectangleArena.proto"

WorldInfo {
}
Viewpoint {
  orientation 0.20270658983222042 0.2822064656544357 -0.9376937395447534 0.8844256767220834
  position -1.6443626928895916 0.7493007606976094 0.403199642462244
}
TexturedBackground {
}
TexturedBackgroundLight {
}
RectangleArena {
  translation 0 0 -0.02
  floorSize 3 3
}
Robot {
  translation -0.6532944735579813 -0.441967482834188 0.3617244210450026
  rotation 0.0007587737725110721 -0.014702756913636114 0.9998916207277171 2.96584789060324
  children [
    Pose {
      translation -0.031 -0.054127 0.0909
      children [
        Shape {
          appearance DEF pillar_tube_material PBRAppearance {
            baseColor 0.501961 0.486275 0.439216
            roughness 1
            metalness 0
          }
          geometry Cylinder {
            height 0.086
            radius 0.004
          }
        }
      ]
    }
    Pose {
      translation -0.046375 -0.026254 0.02
      rotation 1e-06 -1 -1e-06 3.141593
      children [
        Shape {
          appearance DEF mx64_material PBRAppearance {
            baseColor 0.211765 0.211765 0.211765
            roughness 1
            metalness 0
          }
          geometry Box {
            size 0.029 0.05 0.04
          }
        }
      ]
    }
    Pose {
      translation 0.05 -0.017127 0.1609
      rotation -0.7071052811840065 -1.0000003976552372e-06 -0.7071082811851994 3.141591
      children [
        Shape {
          appearance USE mx64_material
          geometry Box {
            size 0.029 0.05 0.04
          }
        }
      ]
    }
    Pose {
      translation 0.046375 -0.026254 0.02
      rotation 1e-06 -1 -1e-06 3.141593
      children [
        Shape {
          appearance USE mx64_material
          geometry Box {
            size 0.029 0.05 0.04
          }
        }
      ]
    }
    Pose {
      translation 0 0.071323 0.1899
      rotation 0.5773496025226482 0.5773496025226482 -0.5773516025212713 2.094399
      children [
        Shape {
          appearance DEF handle_material PBRAppearance {
            baseColor 0.701961 0.682353 0.623529
            roughness 1
            metalness 0
          }
          geometry Box {
            size 0.01 0.13 0.003
          }
        }
      ]
    }
    Pose {
      translation -0.06 0.071323 0.1649
      rotation 0.5773496025226482 0.5773496025226482 -0.5773516025212713 2.094399
      children [
        Shape {
          appearance USE handle_material
          geometry Box {
            size 0.04 0.01 0.003
          }
        }
      ]
    }
    Pose {
      translation 0.06 0.071323 0.1649
      rotation 0.5773496025226482 0.5773496025226482 -0.5773516025212713 2.094399
      children [
        Shape {
          appearance USE handle_material
          geometry Box {
            size 0.04 0.01 0.003
          }
        }
      ]
    }
    Pose {
      translation 0.0625 0.037873 0.0909
      rotation -1 0 0 3.14159
      children [
        Shape {
          appearance USE pillar_tube_material
          geometry Cylinder {
            height 0.086
            radius 0.004
          }
        }
      ]
    }
    Pose {
      translation -0.050587 -0.017127 0.1609
      rotation 0.7071052811840065 1.0000003976552372e-06 -0.7071082811851994 3.141591
      children [
        Shape {
          appearance USE mx64_material
          geometry Box {
            size 0.029 0.05 0.04
          }
        }
      ]
    }
    Pose {
      translation 0 -0.019127 0.1354
      rotation 1e-06 -1 -1e-06 3.141593
      children [
        Shape {
          appearance DEF torso_top_plate_nuc_material PBRAppearance {
            baseColor 0.301961 0.301961 0.301961
            roughness 1
            metalness 0
          }
          geometry Box {
            size 0.13 0.08 0.003
          }
        }
      ]
    }
    Pose {
      translation 0 0.010373 0.0469
      children [
        Shape {
          appearance DEF torso_middle_plate_nuc_material PBRAppearance {
            baseColor 0.301961 0.301961 0.301961
            roughness 1
            metalness 0
          }
          geometry Box {
            size 0.13 0.08 0.003
          }
        }
      ]
    }
    Pose {
      translation -0.0625 0.037873 0.0909
      children [
        Shape {
          appearance USE pillar_tube_material
          geometry Cylinder {
            height 0.086
            radius 0.004
          }
        }
      ]
    }
    Pose {
      translation 0 0.035873 0.10615
      rotation 1.0000003976552372e-06 -0.7071082811851994 -0.7071052811840065 3.141591
      children [
        Shape {
          appearance DEF nuc_material PBRAppearance {
            baseColor 0.301961 0.290196 0.262745
            roughness 1
            metalness 0
          }
          geometry Box {
            size 0.11 0.11 0.033
          }
        }
      ]
    }
    Pose {
      translation 0 0.031123 0.0015
      children [
        Shape {
          appearance DEF torso_bottom_plate_nuc_material PBRAppearance {
            baseColor 0.4 0.4 0.4
            roughness 1
            metalness 0
          }
          geometry Box {
            size 0.13 0.044 0.003
          }
        }
      ]
    }
    Pose {
      translation -0.03 -0.007877 0.0015
      children [
        Shape {
          appearance USE torso_bottom_plate_nuc_material
          geometry Box {
            size 0.01 0.035 0.003
          }
        }
      ]
    }
    Pose {
      translation 0.03 -0.007877 0.0015
      children [
        Shape {
          appearance USE torso_bottom_plate_nuc_material
          geometry Box {
            size 0.01 0.035 0.003
          }
        }
      ]
    }
    Pose {
      translation 0 0.059373 0.1384
      rotation -0.7071052811840065 0.7071082811851994 -1.0000003976552372e-06 3.141591
      children [
        Shape {
          appearance DEF nuc_fix_material PBRAppearance {
            baseColor 0.301961 0.301961 0.301961
            roughness 1
            metalness 0
          }
          geometry Box {
            size 0.01 0.135 0.003
          }
        }
      ]
    }
    Pose {
      translation 0 -0.022127 0.1623
      rotation 0 0 -1 3.14159
      children [
        Shape {
          appearance USE mx64_material
          geometry Box {
            size 0.029 0.05 0.04
          }
        }
      ]
    }
    Pose {
      translation 0.031 -0.054127 0.0914
      children [
        Shape {
          appearance USE pillar_tube_material
          geometry Cylinder {
            height 0.086
            radius 0.004
          }
        }
      ]
    }
    HingeJoint {
      jointParameters HingeJointParameters {
        position -2.2156886525103066e-07
        axis -3e-06 0 1
        anchor -0.046375 -0.011254 -0.0035
      }
      device [
        RotationalMotor {
          name "right_hip_yaw"
          maxVelocity 6
        }
        PositionSensor {
          name "right_hip_yaw_sensor"
        }
      ]
      endPoint Solid {
        translation -0.04637537484264424 -0.011251535244468942 -0.0035713335989645515
        rotation 0.7070862645630808 -0.7071272953262345 -5.1680103395500745e-05 3.1414953663708327
        children [
          Pose {
            translation -0.00494 0 0.003
            children [
              Shape {
                appearance DEF u_base_motors_blocs_material PBRAppearance {
                  baseColor 0.301961 0.301961 0.301961
                  roughness 1
                  metalness 0
                }
                geometry Box {
                  size 0.05 0.03 0.006
                }
              }
            ]
          }
          Pose {
            translation -0.03144 0 0.023
            rotation 0.5773496025226483 0.5773516025212714 0.5773496025226483 2.094399
            children [
              Shape {
                appearance DEF u_side_small_material PBRAppearance {
                  baseColor 0.301961 0.301961 0.301961
                  roughness 1
                  metalness 0
                }
                geometry Box {
                  size 0.025 0.044 0.003
                }
              }
            ]
          }
          Pose {
            translation 0.0219 0 0.023
            rotation 0.5773496025226483 -0.5773516025212714 -0.5773496025226483 2.094399
            children [
              Shape {
                appearance DEF u_side_small_with_trace_material PBRAppearance {
                  baseColor 0.301961 0.301961 0.301961
                  roughness 1
                  metalness 0
                }
                geometry Box {
                  size 0.027 0.042 0.003
                }
              }
            ]
          }
          HingeJoint {
            jointParameters HingeJointParameters {
              position 6.465098515160971e-06
              axis -1 -4e-06 -4e-06
              anchor 0.0234 0 0.04
            }
            device [
              RotationalMotor {
                name "right_hip_roll"
                maxVelocity 6
              }
              PositionSensor {
                name "right_hip_roll_sensor"
              }
            ]
            endPoint Solid {
              translation -0.026599999999998656 -1.9999870697811374e-07 0.039999999999999994
              rotation -0.5773508467381842 -0.5773491141079272 0.5773508467210329 2.0944027326260706
              children [
                Pose {
                  translation 0 -0.015 0.0234
                  rotation 0 -1 0 1.5708
                  children [
                    Shape {
                      appearance DEF mx106_material PBRAppearance {
                        baseColor 0.301961 0.301961 0.301961
                        roughness 1
                        metalness 0
                      }
                      geometry Box {
                        size 0.03 0.055 0.04
                      }
                    }
                  ]
                }
                Pose {
                  translation 0 -0.015 -0.026
                  children [
                    Shape {
                      appearance USE mx106_material
                      geometry Box {
                        size 0.03 0.055 0.04
                      }
                    }
                  ]
                }
                HingeJoint {
                  jointParameters HingeJointParameters {
                    position 0.01696131764063293
                    axis 1 0 -4e-06
                    anchor -0.026 0 0.0234
                  }
                  device [
                    RotationalMotor {
                      name "right_hip_pitch"
                      maxVelocity 6
                    }
                    PositionSensor {
                      name "right_hip_pitch_sensor"
                    }
                  ]
                  endPoint Solid {
                    translation 0.026000000023244266 0.0006852013638440268 -0.016994288911721517
                    rotation 0.008482006148439362 -0.9999280518603132 -0.00848213855915349 1.5708619497221372
                    children [
                      Pose {
                        translation 0 -0.0395 0.0535
                        children [
                          Shape {
                            appearance DEF u_side_femur_mir_material PBRAppearance {
                              baseColor 0.301961 0.301961 0.301961
                              roughness 1
                              metalness 0
                            }
                            geometry Box {
                              size 0.04 0.09 0.003
                            }
                          }
                        ]
                      }
                      Pose {
                        translation 0 -0.125 0.026
                        rotation -1 0 0 3.14159
                        children [
                          Shape {
                            appearance USE mx106_material
                            geometry Box {
                              size 0.03 0.055 0.04
                            }
                          }
                        ]
                      }
                      Pose {
                        translation 0 -0.0395 -0.0015
                        children [
                          Shape {
                            appearance DEF u_side_femur_material PBRAppearance {
                              baseColor 0.301961 0.301961 0.301961
                              roughness 1
                              metalness 0
                            }
                            geometry Box {
                              size 0.04 0.09 0.003
                            }
                          }
                        ]
                      }
                      Pose {
                        translation 0 -0.0825 0.026
                        rotation -0.5773496025226482 0.5773496025226482 0.5773516025212713 2.094399
                        children [
                          Shape {
                            appearance DEF u_base_64_material PBRAppearance {
                              baseColor 0.301961 0.301961 0.301961
                              roughness 1
                              metalness 0
                            }
                            geometry Box {
                              size 0.047 0.0275 0.006
                            }
                          }
                        ]
                      }
                      HingeJoint {
                        jointParameters HingeJointParameters {
                          position -0.0029675141396694423
                          axis 0 -3e-06 1
                          anchor 0 -0.14 0
                        }
                        device [
                          RotationalMotor {
                            name "right_knee"
                            maxVelocity 6
                          }
                          PositionSensor {
                            name "right_knee_sensor"
                          }
                        ]
                        endPoint Solid {
                          translation 0 -0.14 0
                          rotation -0.0014827565265075012 -0.9999989007154376 -9.997419095390052e-07 3.1415929940645926
                          children [
                            Pose {
                              translation 0 -0.067 0.0015
                              children [
                                Shape {
                                  appearance DEF tibia_plate_material PBRAppearance {
                                    baseColor 0.301961 0.301961 0.301961
                                    roughness 1
                                    metalness 0
                                  }
                                  geometry Box {
                                    size 0.03 0.165 0.003
                                  }
                                }
                              ]
                            }
                            Pose {
                              translation 0 -0.067 -0.0535
                              children [
                                Shape {
                                  appearance USE tibia_plate_material
                                  geometry Box {
                                    size 0.03 0.165 0.003
                                  }
                                }
                              ]
                            }
                            HingeJoint {
                              jointParameters HingeJointParameters {
                                position 0.0497789618488974
                                axis 0 0 -1
                                anchor 0 -0.14 0
                              }
                              device [
                                RotationalMotor {
                                  name "right_ankle_pitch"
                                  maxVelocity 6
                                }
                                PositionSensor {
                                  name "right_ankle_pitch_sensor"
                                }
                              ]
                              endPoint Solid {
                                translation 0 -0.14 0
                                rotation 0 0 1 3.0918110381511035
                                children [
                                  Pose {
                                    translation 0 -0.015 -0.026
                                    children [
                                      Shape {
                                        appearance USE mx106_material
                                        geometry Box {
                                          size 0.03 0.055 0.04
                                        }
                                      }
                                    ]
                                  }
                                  Pose {
                                    translation 0.0494 -0.015 -0.026
                                    rotation 0 -1 0 1.5708
                                    children [
                                      Shape {
                                        appearance USE mx106_material
                                        geometry Box {
                                          size 0.03 0.055 0.04
                                        }
                                      }
                                    ]
                                  }
                                  HingeJoint {
                                    jointParameters HingeJointParameters {
                                      position -2.9411658938047234e-06
                                      axis -1 -3e-06 4e-06
                                      anchor 0.0234 0 -0.026
                                    }
                                    device [
                                      RotationalMotor {
                                        name "right_ankle_roll"
                                        maxVelocity 6
                                      }
                                      PositionSensor {
                                        name "right_ankle_roll_sensor"
                                      }
                                    ]
                                    endPoint Solid {
                                      translation 0.0234 0 -0.026
                                      rotation 0.7071052811811166 2.039857618140319e-06 -0.7071082811858542 3.1415930797222553
                                      children [
                                        Pose {
                                          translation -0.0435 -0.05 -0.03213
                                          rotation -0.07067301865421641 -0.705340186175272 0.7053371861744802 3.282702
                                          children [
                                            Shape {
                                              appearance DEF cleat_material PBRAppearance {
                                                baseColor 0.301961 0.290196 0.262745
                                                roughness 1
                                                metalness 0
                                              }
                                              geometry Cylinder {
                                                height 0.02
                                                radius 0.008
                                              }
                                            }
                                          ]
                                        }
                                        Pose {
                                          translation -0.0435 -0.05 0.10947
                                          rotation -0.07067301865421641 -0.705340186175272 0.7053371861744802 3.282702
                                          children [
                                            Shape {
                                              appearance USE cleat_material
                                              geometry Cylinder {
                                                height 0.02
                                                radius 0.008
                                              }
                                            }
                                          ]
                                        }
                                        Pose {
                                          translation 0 -0.017 0.05484
                                          rotation -1e-06 -1 1e-06 3.141593
                                          children [
                                            Shape {
                                              appearance USE u_side_small_material
                                              geometry Box {
                                                size 0.025 0.044 0.003
                                              }
                                            }
                                          ]
                                        }
                                        Pose {
                                          translation 0.0325 -0.05 0.10947
                                          rotation 0.92751216314523 0.26431104649112774 -0.26431204649130363 1.645979
                                          children [
                                            Shape {
                                              appearance USE cleat_material
                                              geometry Cylinder {
                                                height 0.02
                                                radius 0.008
                                              }
                                            }
                                          ]
                                        }
                                        Pose {
                                          translation -0.0055 -0.0415 0.03867
                                          rotation 1.0000003976552372e-06 0.7071082811851994 0.7071052811840065 3.141591
                                          children [
                                            Shape {
                                              appearance DEF foot_plate_material PBRAppearance {
                                                baseColor 0.301961 0.301961 0.301961
                                                roughness 1
                                                metalness 0
                                              }
                                              geometry Box {
                                                size 0.09 0.155 0.003
                                              }
                                            }
                                          ]
                                        }
                                        Pose {
                                          translation 0 -0.017 0.0015
                                          children [
                                            Shape {
                                              appearance USE u_side_small_with_trace_material
                                              geometry Box {
                                                size 0.027 0.042 0.003
                                              }
                                            }
                                          ]
                                        }
                                        Pose {
                                          translation 0.0325 -0.05 -0.03213
                                          rotation 0.9762266572922753 -0.15326694619511155 0.15326694619511155 1.594858
                                          children [
                                            Shape {
                                              appearance USE cleat_material
                                              geometry Cylinder {
                                                height 0.02
                                                radius 0.008
                                              }
                                            }
                                          ]
                                        }
                                        Pose {
                                          translation -0.0055 -0.0275 0.12247
                                          rotation 0.6785972482190434 -0.6785992482197749 -0.28108510281603044 3.68962
                                          children [
                                            Shape {
                                              appearance DEF foot_protection_material PBRAppearance {
                                                baseColor 0.301961 0.290196 0.262745
                                                roughness 1
                                                metalness 0
                                              }
                                              geometry Box {
                                                size 0.01 0.09 0.01
                                              }
                                            }
                                          ]
                                        }
                                        Pose {
                                          translation 0 -0.037 0.02834
                                          rotation -0.5773496025226482 0.5773496025226482 0.5773516025212713 2.094399
                                          children [
                                            Shape {
                                              appearance USE u_base_motors_blocs_material
                                              geometry Box {
                                                size 0.05 0.03 0.006
                                              }
                                            }
                                          ]
                                        }
                                      ]
                                      name "right_foot_cleat_back_left"
                                      boundingObject Group {
                                        children [
                                          Pose {
                                            translation -0.0435 -0.05 -0.03213
                                            rotation -0.07067301865421641 -0.705340186175272 0.7053371861744802 3.282702
                                            children [
                                              Cylinder {
                                                height 0.02
                                                radius 0.008
                                              }
                                            ]
                                          }
                                          Pose {
                                            translation -0.0435 -0.05 0.10947
                                            rotation -0.07067301865421641 -0.705340186175272 0.7053371861744802 3.282702
                                            children [
                                              Cylinder {
                                                height 0.02
                                                radius 0.008
                                              }
                                            ]
                                          }
                                          Pose {
                                            translation 0 -0.017 0.05484
                                            rotation -1e-06 -1 1e-06 3.141593
                                            children [
                                              Box {
                                                size 0.025 0.044 0.003
                                              }
                                            ]
                                          }
                                          Pose {
                                            translation 0.0325 -0.05 0.10947
                                            rotation 0.92751216314523 0.26431104649112774 -0.26431204649130363 1.645979
                                            children [
                                              Cylinder {
                                                height 0.02
                                                radius 0.008
                                              }
                                            ]
                                          }
                                          Pose {
                                            translation -0.0055 -0.0415 0.03867
                                            rotation 1.0000003976552372e-06 0.7071082811851994 0.7071052811840065 3.141591
                                            children [
                                              Box {
                                                size 0.09 0.155 0.003
                                              }
                                            ]
                                          }
                                          Pose {
                                            translation 0 -0.017 0.0015
                                            children [
                                              Box {
                                                size 0.027 0.042 0.003
                                              }
                                            ]
                                          }
                                          Pose {
                                            translation 0.0325 -0.05 -0.03213
                                            rotation 0.9762266572922753 -0.15326694619511155 0.15326694619511155 1.594858
                                            children [
                                              Cylinder {
                                                height 0.02
                                                radius 0.008
                                              }
                                            ]
                                          }
                                          Pose {
                                            translation -0.0055 -0.0275 0.12247
                                            rotation 0.6785972482190434 -0.6785992482197749 -0.28108510281603044 3.68962
                                            children [
                                              Box {
                                                size 0.01 0.09 0.01
                                              }
                                            ]
                                          }
                                          Pose {
                                            translation 0 -0.037 0.02834
                                            rotation -0.5773496025226482 0.5773496025226482 0.5773516025212713 2.094399
                                            children [
                                              Box {
                                                size 0.05 0.03 0.006
                                              }
                                            ]
                                          }
                                        ]
                                      }
                                      physics Physics {
                                        density -1
                                        mass 0.239067
                                        centerOfMass [
                                          -0.004685 -0.036578 0.051153
                                        ]
                                        inertiaMatrix [
                                          0.000644736 0.000780875 0.000195711
                                          -2.73076e-06 4.22638e-06 -2.65367e-05
                                        ]
                                      }
                                      linearVelocity -1.091672151366006e-05 -9.411831360978039e-06 -2.2524907543700058e-06
                                      angularVelocity -0.00011145938247632828 -0.0001381355432208961 0.000171901034098747
                                    }
                                  }
                                ]
                                name "mx106_block_1"
                                boundingObject Group {
                                  children [
                                    Pose {
                                      translation 0 -0.015 -0.026
                                      children [
                                        Box {
                                          size 0.03 0.055 0.04
                                        }
                                      ]
                                    }
                                    Pose {
                                      translation 0.0494 -0.015 -0.026
                                      rotation 0 -1 0 1.5708
                                      children [
                                        Box {
                                          size 0.03 0.055 0.04
                                        }
                                      ]
                                    }
                                  ]
                                }
                                physics Physics {
                                  density -1
                                  mass 0.427481
                                  centerOfMass [
                                    0.019588 -0.018098 -0.025825
                                  ]
                                  inertiaMatrix [
                                    0.000194682 0.000410191 0.000485925
                                    1.88861e-05 4.22317e-07 -2.22493e-06
                                  ]
                                }
                                linearVelocity -5.132200997150675e-06 -6.154091922675645e-06 8.984147917281363e-07
                                angularVelocity -9.830105755340095e-05 -6.367012151924015e-05 0.00017435480785662965
                              }
                            }
                          ]
                          name "tibia_1"
                          boundingObject Group {
                            children [
                              Pose {
                                translation 0 -0.067 0.0015
                                children [
                                  Box {
                                    size 0.03 0.165 0.003
                                  }
                                ]
                              }
                              Pose {
                                translation 0 -0.067 -0.0535
                                children [
                                  Box {
                                    size 0.03 0.165 0.003
                                  }
                                ]
                              }
                            ]
                          }
                          physics Physics {
                            density -1
                            mass 0.088844
                            centerOfMass [
                              -0.003422 -0.064607 -0.026
                            ]
                            inertiaMatrix [
                              0.000245247 7.67255e-05 0.000187463
                              6.12719e-06 -1.44286e-11 3.8066e-11
                            ]
                          }
                          linearVelocity -7.251175686767006e-06 -3.332910267256426e-06 -6.242434788581434e-07
                          angularVelocity -6.337193234531171e-05 -7.016936353570871e-05 0.00017681945531294264
                        }
                      }
                    ]
                    name "right_knee_1"
                    boundingObject Group {
                      children [
                        Pose {
                          translation 0 -0.0395 0.0535
                          children [
                            Box {
                              size 0.04 0.09 0.003
                            }
                          ]
                        }
                        Pose {
                          translation 0 -0.125 0.026
                          rotation -1 0 0 3.14159
                          children [
                            Box {
                              size 0.03 0.055 0.04
                            }
                          ]
                        }
                        Pose {
                          translation 0 -0.0395 -0.0015
                          children [
                            Box {
                              size 0.04 0.09 0.003
                            }
                          ]
                        }
                        Pose {
                          translation 0 -0.0825 0.026
                          rotation -0.5773496025226482 0.5773496025226482 0.5773516025212713 2.094399
                          children [
                            Box {
                              size 0.047 0.0275 0.006
                            }
                          ]
                        }
                      ]
                    }
                    physics Physics {
                      density -1
                      mass 0.269758
                      centerOfMass [
                        0.000224 -0.098034 0.025713
                      ]
                      inertiaMatrix [
                        0.000503595 0.000109941 0.000438644
                        9.05865e-07 -4.56779e-07 -5.72119e-06
                      ]
                    }
                    linearVelocity -1.0187101117496737e-05 3.517763783103143e-06 -6.886772830029665e-07
                    angularVelocity -7.700892090931654e-05 -6.863043333678453e-05 0.00017944881357107717
                  }
                }
              ]
              name "mx106_block_mir_1"
              boundingObject Group {
                children [
                  Pose {
                    translation 0 -0.015 0.0234
                    rotation 0 -1 0 1.5708
                    children [
                      Box {
                        size 0.03 0.055 0.04
                      }
                    ]
                  }
                  Pose {
                    translation 0 -0.015 -0.026
                    children [
                      Box {
                        size 0.03 0.055 0.04
                      }
                    ]
                  }
                ]
              }
              physics Physics {
                density -1
                mass 0.427481
                centerOfMass [
                  -0.000304 -0.018098 0.003917
                ]
                inertiaMatrix [
                  0.000482208 0.000408392 0.000203671
                  -1.57792e-05 3.50396e-06 -3.68837e-05
                ]
              }
              linearVelocity -6.6201085328897755e-06 1.106154520103652e-05 3.8549174015994554e-06
              angularVelocity 7.820883953691429e-05 -9.763046929096637e-05 0.0001812268836231868
            }
          }
        ]
        name "u_block_1"
        boundingObject Group {
          children [
            Pose {
              translation -0.00494 0 0.003
              children [
                Box {
                  size 0.05 0.03 0.006
                }
              ]
            }
            Pose {
              translation -0.03144 0 0.023
              rotation 0.5773496025226483 0.5773516025212714 0.5773496025226483 2.094399
              children [
                Box {
                  size 0.025 0.044 0.003
                }
              ]
            }
            Pose {
              translation 0.0219 0 0.023
              rotation 0.5773496025226483 -0.5773516025212714 -0.5773496025226483 2.094399
              children [
                Box {
                  size 0.027 0.042 0.003
                }
              ]
            }
          ]
        }
        physics Physics {
          density -1
          mass 0.03544
          centerOfMass [
            -0.00607 0 0.011765
          ]
          inertiaMatrix [
            6.0236e-06 2.4343e-05 2.1328e-05
            -2.05966e-08 7.97442e-07 -8.88603e-13
          ]
        }
        linearVelocity -1.1137122363519886e-05 7.700017274428164e-06 5.885733751468551e-06
        angularVelocity 7.797434407422431e-05 -9.902140676034199e-05 0.00018391992823220396
      }
    }
    HingeJoint {
      jointParameters HingeJointParameters {
        position -8.569915185062338e-06
        axis 3e-06 0 1
        anchor 0.046375 -0.011254 -0.0035
      }
      device [
        RotationalMotor {
          name "left_hip_yaw"
          maxVelocity 6
        }
        PositionSensor {
          name "left_hip_yaw_sensor"
        }
      ]
      endPoint Solid {
        translation 0.04640042541556198 -0.011240835480658854 -0.0035650135838050222
        rotation 0.7071088090785883 0.7071047532876166 1.2326587783082427e-06 3.1415905071755468
        children [
          Pose {
            translation -0.00494 0 0.003
            children [
              Shape {
                appearance USE u_base_motors_blocs_material
                geometry Box {
                  size 0.05 0.03 0.006
                }
              }
            ]
          }
          Pose {
            translation 0.0219 0 0.023
            rotation 0.5773496025226483 -0.5773516025212714 -0.5773496025226483 2.094399
            children [
              Shape {
                appearance USE u_side_small_with_trace_material
                geometry Box {
                  size 0.027 0.042 0.003
                }
              }
            ]
          }
          Pose {
            translation -0.03144 0 0.023
            rotation 0.5773496025226483 0.5773516025212714 0.5773496025226483 2.094399
            children [
              Shape {
                appearance USE u_side_small_material
                geometry Box {
                  size 0.025 0.044 0.003
                }
              }
            ]
          }
          HingeJoint {
            jointParameters HingeJointParameters {
              position 1.6051360052974963e-05
              axis -1 -4e-06 -4e-06
              anchor 0.0234 0 0.04
            }
            device [
              RotationalMotor {
                name "left_hip_roll"
                maxVelocity 6
              }
              PositionSensor {
                name "left_hip_roll_sensor"
              }
            ]
            endPoint Solid {
              translation 0.0234 0 0.04
              rotation -0.577352691610272 -0.5773454243604236 0.57735269156769 2.0944082672711364
              children [
                Pose {
                  translation 0 -0.015 -0.026
                  children [
                    Shape {
                      appearance USE mx106_material
                      geometry Box {
                        size 0.03 0.055 0.04
                      }
                    }
                  ]
                }
                Pose {
                  translation 0 -0.015 0.0234
                  rotation 0 1 0 1.5708
                  children [
                    Shape {
                      appearance USE mx106_material
                      geometry Box {
                        size 0.03 0.055 0.04
                      }
                    }
                  ]
                }
                HingeJoint {
                  jointParameters HingeJointParameters {
                    position 6.489130676422773e-06
                    axis 1 0 4e-06
                    anchor 0.026 0 0.0234
                  }
                  device [
                    RotationalMotor {
                      name "left_hip_pitch"
                      maxVelocity 6
                    }
                    PositionSensor {
                      name "left_hip_pitch_sensor"
                    }
                  ]
                  endPoint Solid {
                    translation 0.026 0 0.0234
                    rotation 3.2445663985548e-06 -0.9999999999894728 -3.244552359929353e-06 1.570800000010525
                    children [
                      Pose {
                        translation 0 -0.0825 0.026
                        rotation -0.5773496025226482 0.5773496025226482 0.5773516025212713 2.094399
                        children [
                          Shape {
                            appearance USE u_base_64_material
                            geometry Box {
                              size 0.047 0.0275 0.006
                            }
                          }
                        ]
                      }
                      Pose {
                        translation 0 -0.0395 -0.0015
                        children [
                          Shape {
                            appearance USE u_side_femur_material
                            geometry Box {
                              size 0.04 0.09 0.003
                            }
                          }
                        ]
                      }
                      Pose {
                        translation 0 -0.0395 0.0535
                        children [
                          Shape {
                            appearance USE u_side_femur_mir_material
                            geometry Box {
                              size 0.04 0.09 0.003
                            }
                          }
                        ]
                      }
                      Pose {
                        translation 0 -0.125 0.026
                        rotation -1 0 0 3.14159
                        children [
                          Shape {
                            appearance USE mx106_material
                            geometry Box {
                              size 0.03 0.055 0.04
                            }
                          }
                        ]
                      }
                      HingeJoint {
                        jointParameters HingeJointParameters {
                          position -0.00734330114237548
                          axis 0 0 -1
                          anchor 0 -0.14 0
                        }
                        device [
                          RotationalMotor {
                            name "left_knee"
                            maxVelocity 6
                          }
                          PositionSensor {
                            name "left_knee_sensor"
                          }
                        ]
                        endPoint Solid {
                          translation 0 -0.14 0
                          rotation 0 0 1 0.0073433011423776635
                          children [
                            Pose {
                              translation 0 -0.067 -0.0015
                              children [
                                Shape {
                                  appearance USE tibia_plate_material
                                  geometry Box {
                                    size 0.03 0.165 0.003
                                  }
                                }
                              ]
                            }
                            Pose {
                              translation 0 -0.067 0.0535
                              children [
                                Shape {
                                  appearance USE tibia_plate_material
                                  geometry Box {
                                    size 0.03 0.165 0.003
                                  }
                                }
                              ]
                            }
                            HingeJoint {
                              jointParameters HingeJointParameters {
                                position 0.029748331701082008
                                axis 0 -3e-06 -1
                                anchor 0 -0.14 0
                              }
                              device [
                                RotationalMotor {
                                  name "left_ankle_pitch"
                                  maxVelocity 6
                                }
                                PositionSensor {
                                  name "left_ankle_pitch_sensor"
                                }
                              ]
                              endPoint Solid {
                                translation 0 -0.14 0
                                rotation 0.9998893816345891 -0.014873617394517414 2.488661253432895e-08 3.1415900002935357
                                children [
                                  Pose {
                                    translation 0 -0.015 -0.026
                                    children [
                                      Shape {
                                        appearance USE mx106_material
                                        geometry Box {
                                          size 0.03 0.055 0.04
                                        }
                                      }
                                    ]
                                  }
                                  Pose {
                                    translation -0.0494 -0.015 -0.026
                                    rotation 0 1 0 1.5708
                                    children [
                                      Shape {
                                        appearance USE mx106_material
                                        geometry Box {
                                          size 0.03 0.055 0.04
                                        }
                                      }
                                    ]
                                  }
                                  HingeJoint {
                                    jointParameters HingeJointParameters {
                                      position 5.931719324931251e-06
                                      axis 1 3e-06 4e-06
                                      anchor -0.0234 0 -0.026
                                    }
                                    device [
                                      RotationalMotor {
                                        name "left_ankle_roll"
                                        maxVelocity 6
                                      }
                                      PositionSensor {
                                        name "left_ankle_roll_sensor"
                                      }
                                    ]
                                    endPoint Solid {
                                      translation -0.0234 0 -0.026
                                      rotation -0.7071052811875173 1.0971751417940006e-06 -0.7071082811815449 3.1415868056331613
                                      children [
                                        Pose {
                                          translation 0.0055 -0.0275 0.12247
                                          rotation -0.6785971692089039 0.6786001692096519 0.28108307008835337 2.593562
                                          children [
                                            Shape {
                                              appearance USE foot_protection_material
                                              geometry Box {
                                                size 0.01 0.09 0.01
                                              }
                                            }
                                          ]
                                        }
                                        Pose {
                                          translation 0.0435 -0.05 -0.03213
                                          rotation -0.17069990706382648 -0.6967296206712351 0.696727620672324 3.47973
                                          children [
                                            Shape {
                                              appearance USE cleat_material
                                              geometry Cylinder {
                                                height 0.02
                                                radius 0.008
                                              }
                                            }
                                          ]
                                        }
                                        Pose {
                                          translation 0 -0.017 0.05484
                                          rotation -1e-06 1 -1e-06 3.141593
                                          children [
                                            Shape {
                                              appearance USE u_side_small_material
                                              geometry Box {
                                                size 0.025 0.044 0.003
                                              }
                                            }
                                          ]
                                        }
                                        Pose {
                                          translation 0.0435 -0.05 0.10947
                                          rotation -0.17069990706382648 -0.6967296206712351 0.696727620672324 3.47973
                                          children [
                                            Shape {
                                              appearance USE cleat_material
                                              geometry Cylinder {
                                                height 0.02
                                                radius 0.008
                                              }
                                            }
                                          ]
                                        }
                                        Pose {
                                          translation 0 -0.037 0.02834
                                          rotation -0.5773496025226482 0.5773496025226482 0.5773516025212713 2.094399
                                          children [
                                            Shape {
                                              appearance USE u_base_motors_blocs_material
                                              geometry Box {
                                                size 0.05 0.03 0.006
                                              }
                                            }
                                          ]
                                        }
                                        Pose {
                                          translation -0.0325 -0.05 0.10947
                                          rotation -0.17069990706382648 -0.6967296206712351 0.696727620672324 3.47973
                                          children [
                                            Shape {
                                              appearance USE cleat_material
                                              geometry Cylinder {
                                                height 0.02
                                                radius 0.008
                                              }
                                            }
                                          ]
                                        }
                                        Pose {
                                          translation -0.0325 -0.05 -0.03213
                                          rotation 0.17069808427084848 0.6967303439643596 -0.6967273439628786 2.803451
                                          children [
                                            Shape {
                                              appearance USE cleat_material
                                              geometry Cylinder {
                                                height 0.02
                                                radius 0.008
                                              }
                                            }
                                          ]
                                        }
                                        Pose {
                                          translation 0 -0.017 0.0015
                                          children [
                                            Shape {
                                              appearance USE u_side_small_with_trace_material
                                              geometry Box {
                                                size 0.027 0.042 0.003
                                              }
                                            }
                                          ]
                                        }
                                        Pose {
                                          translation 0.0055 -0.0415 0.03867
                                          rotation 1.0000003976552372e-06 -0.7071082811851994 -0.7071052811840065 3.141591
                                          children [
                                            Shape {
                                              appearance USE foot_plate_material
                                              geometry Box {
                                                size 0.09 0.155 0.003
                                              }
                                            }
                                          ]
                                        }
                                      ]
                                      name "left_foot_cleat_front_right"
                                      boundingObject Group {
                                        children [
                                          Pose {
                                            translation 0.0055 -0.0275 0.12247
                                            rotation -0.6785971692089039 0.6786001692096519 0.28108307008835337 2.593562
                                            children [
                                              Box {
                                                size 0.01 0.09 0.01
                                              }
                                            ]
                                          }
                                          Pose {
                                            translation 0.0435 -0.05 -0.03213
                                            rotation -0.17069990706382648 -0.6967296206712351 0.696727620672324 3.47973
                                            children [
                                              Cylinder {
                                                height 0.02
                                                radius 0.008
                                              }
                                            ]
                                          }
                                          Pose {
                                            translation 0 -0.017 0.05484
                                            rotation -1e-06 1 -1e-06 3.141593
                                            children [
                                              Box {
                                                size 0.025 0.044 0.003
                                              }
                                            ]
                                          }
                                          Pose {
                                            translation 0.0435 -0.05 0.10947
                                            rotation -0.17069990706382648 -0.6967296206712351 0.696727620672324 3.47973
                                            children [
                                              Cylinder {
                                                height 0.02
                                                radius 0.008
                                              }
                                            ]
                                          }
                                          Pose {
                                            translation 0 -0.037 0.02834
                                            rotation -0.5773496025226482 0.5773496025226482 0.5773516025212713 2.094399
                                            children [
                                              Box {
                                                size 0.05 0.03 0.006
                                              }
                                            ]
                                          }
                                          Pose {
                                            translation -0.0325 -0.05 0.10947
                                            rotation -0.17069990706382648 -0.6967296206712351 0.696727620672324 3.47973
                                            children [
                                              Cylinder {
                                                height 0.02
                                                radius 0.008
                                              }
                                            ]
                                          }
                                          Pose {
                                            translation -0.0325 -0.05 -0.03213
                                            rotation 0.17069808427084848 0.6967303439643596 -0.6967273439628786 2.803451
                                            children [
                                              Cylinder {
                                                height 0.02
                                                radius 0.008
                                              }
                                            ]
                                          }
                                          Pose {
                                            translation 0 -0.017 0.0015
                                            children [
                                              Box {
                                                size 0.027 0.042 0.003
                                              }
                                            ]
                                          }
                                          Pose {
                                            translation 0.0055 -0.0415 0.03867
                                            rotation 1.0000003976552372e-06 -0.7071082811851994 -0.7071052811840065 3.141591
                                            children [
                                              Box {
                                                size 0.09 0.155 0.003
                                              }
                                            ]
                                          }
                                        ]
                                      }
                                      physics Physics {
                                        density -1
                                        mass 0.239067
                                        centerOfMass [
                                          0.004685 -0.036578 0.051153
                                        ]
                                        inertiaMatrix [
                                          0.000644736 0.000780874 0.000195711
                                          5.21256e-07 -4.22638e-06 -2.65367e-05
                                        ]
                                      }
                                      linearVelocity 1.4980952180847612e-05 1.994936003269483e-05 1.910588509065727e-06
                                      angularVelocity 0.00010158740680580534 3.783515132189751e-05 -3.6572167340208085e-05
                                    }
                                  }
                                ]
                                name "mx106_block_mir_2"
                                boundingObject Group {
                                  children [
                                    Pose {
                                      translation 0 -0.015 -0.026
                                      children [
                                        Box {
                                          size 0.03 0.055 0.04
                                        }
                                      ]
                                    }
                                    Pose {
                                      translation -0.0494 -0.015 -0.026
                                      rotation 0 1 0 1.5708
                                      children [
                                        Box {
                                          size 0.03 0.055 0.04
                                        }
                                      ]
                                    }
                                  ]
                                }
                                physics Physics {
                                  density -1
                                  mass 0.427481
                                  centerOfMass [
                                    -0.019483 -0.018098 -0.025696
                                  ]
                                  inertiaMatrix [
                                    0.000194261 0.000412323 0.000487688
                                    -2.04803e-05 -3.71621e-06 -3.98084e-06
                                  ]
                                }
                                linearVelocity 1.0549980921226546e-05 1.5238416973543816e-05 -2.756077947148864e-06
                                angularVelocity 9.569067182831836e-05 4.3574040415872654e-06 -3.935275529970452e-05
                              }
                            }
                          ]
                          name "tibia_2"
                          boundingObject Group {
                            children [
                              Pose {
                                translation 0 -0.067 -0.0015
                                children [
                                  Box {
                                    size 0.03 0.165 0.003
                                  }
                                ]
                              }
                              Pose {
                                translation 0 -0.067 0.0535
                                children [
                                  Box {
                                    size 0.03 0.165 0.003
                                  }
                                ]
                              }
                            ]
                          }
                          physics Physics {
                            density -1
                            mass 0.088844
                            centerOfMass [
                              -0.003422 -0.064607 0.026
                            ]
                            inertiaMatrix [
                              0.000245247 7.67255e-05 0.000187463
                              6.12719e-06 -1.44286e-11 3.8066e-11
                            ]
                          }
                          linearVelocity 7.172116680579351e-06 1.011624093109074e-05 -1.4646272302788558e-06
                          angularVelocity 9.565305291892272e-05 4.630215731726104e-06 -4.2009531910353515e-05
                        }
                      }
                    ]
                    name "left_knee_1"
                    boundingObject Group {
                      children [
                        Pose {
                          translation 0 -0.0825 0.026
                          rotation -0.5773496025226482 0.5773496025226482 0.5773516025212713 2.094399
                          children [
                            Box {
                              size 0.047 0.0275 0.006
                            }
                          ]
                        }
                        Pose {
                          translation 0 -0.0395 -0.0015
                          children [
                            Box {
                              size 0.04 0.09 0.003
                            }
                          ]
                        }
                        Pose {
                          translation 0 -0.0395 0.0535
                          children [
                            Box {
                              size 0.04 0.09 0.003
                            }
                          ]
                        }
                        Pose {
                          translation 0 -0.125 0.026
                          rotation -1 0 0 3.14159
                          children [
                            Box {
                              size 0.03 0.055 0.04
                            }
                          ]
                        }
                      ]
                    }
                    physics Physics {
                      density -1
                      mass 0.269758
                      centerOfMass [
                        -5.7e-05 -0.098034 0.025527
                      ]
                      inertiaMatrix [
                        0.000503557 0.000109916 0.000438656
                        1.64719e-06 -5.01987e-07 -5.37384e-06
                      ]
                    }
                    linearVelocity 3.5451777345084284e-06 3.859727128192921e-07 -1.4792413703837374e-06
                    angularVelocity 9.572347355033076e-05 5.475842681294445e-06 -4.464514763376706e-05
                  }
                }
              ]
              name "mx106_block_2"
              boundingObject Group {
                children [
                  Pose {
                    translation 0 -0.015 -0.026
                    children [
                      Box {
                        size 0.03 0.055 0.04
                      }
                    ]
                  }
                  Pose {
                    translation 0 -0.015 0.0234
                    rotation 0 1 0 1.5708
                    children [
                      Box {
                        size 0.03 0.055 0.04
                      }
                    ]
                  }
                ]
              }
              physics Physics {
                density -1
                mass 0.427481
                centerOfMass [
                  0.000175 -0.018098 0.003812
                ]
                inertiaMatrix [
                  0.000480875 0.000406226 0.000203698
                  1.44566e-05 -4.949e-07 -3.86323e-05
                ]
              }
              linearVelocity -1.2073615361324763e-06 -6.576864418469663e-06 -3.516362353254437e-06
              angularVelocity 9.58379904735162e-05 6.905592565930829e-06 -4.726990305892344e-05
            }
          }
        ]
        name "u_block_2"
        boundingObject Group {
          children [
            Pose {
              translation -0.00494 0 0.003
              children [
                Box {
                  size 0.05 0.03 0.006
                }
              ]
            }
            Pose {
              translation 0.0219 0 0.023
              rotation 0.5773496025226483 -0.5773516025212714 -0.5773496025226483 2.094399
              children [
                Box {
                  size 0.027 0.042 0.003
                }
              ]
            }
            Pose {
              translation -0.03144 0 0.023
              rotation 0.5773496025226483 0.5773516025212714 0.5773496025226483 2.094399
              children [
                Box {
                  size 0.025 0.044 0.003
                }
              ]
            }
          ]
        }
        physics Physics {
          density -1
          mass 0.03544
          centerOfMass [
            -0.00607 0 0.011765
          ]
          inertiaMatrix [
            6.0236e-06 2.4343e-05 2.1328e-05
            -2.05966e-08 7.97442e-07 -8.88603e-13
          ]
        }
        linearVelocity -6.694340210030839e-06 -1.029284905058657e-05 -1.1734957844910928e-06
        angularVelocity 7.77091237506128e-05 -9.50897210470181e-05 -5.2836325326949116e-05
      }
    }
    HingeJoint {
      jointParameters HingeJointParameters {
        position 0.2999996646402522
        axis 1 -4e-06 -4e-06
        anchor 0.0735 -0.032127 0.1609
      }
      device [
        RotationalMotor {
          name "left_shoulder_pitch"
          maxVelocity 6
        }
        PositionSensor {
          name "left_shoulder_pitch_sensor"
        }
      ]
      endPoint Solid {
        translation 0.07350013244215049 -0.03212411400143719 0.16088573816790333
        rotation -0.4465184582103336 0.775397558774399 -0.4465197558050136 1.8224813594503297
        children [
          Pose {
            translation 0 0 0.003
            children [
              Shape {
                appearance USE u_base_64_material
                geometry Box {
                  size 0.047 0.0275 0.006
                }
              }
            ]
          }
          HingeJoint {
            jointParameters HingeJointParameters {
              position -0.09999991376353039
              axis 1 3e-06 4e-06
              anchor 0.0225 0.03 0.035
            }
            device [
              RotationalMotor {
                name "left_shoulder_roll"
                maxVelocity 6
              }
              PositionSensor {
                name "left_shoulder_roll_sensor"
              }
            ]
            endPoint Solid {
              translation 0.0225 0.03 0.035
              rotation -0.706662935076346 -0.035363601165594095 -0.7066660540183636 3.212287013245064
              children [
                Pose {
                  translation 0 -0.015 -0.0235
                  children [
                    Shape {
                      appearance USE mx64_material
                      geometry Box {
                        size 0.029 0.05 0.04
                      }
                    }
                  ]
                }
                Pose {
                  translation 0 -0.092 -0.039174
                  rotation 0 -1 0 1.5708
                  children [
                    Shape {
                      appearance DEF humerus_plate_material PBRAppearance {
                        baseColor 0.301961 0.301961 0.301961
                        roughness 1
                        metalness 0
                      }
                      geometry Box {
                        size 0.003 0.07 0.03
                      }
                    }
                  ]
                }
                Pose {
                  translation 0 -0.054 -0.023174
                  rotation 0 -1 0 1.5708
                  children [
                    Shape {
                      appearance USE humerus_plate_material
                      geometry Box {
                        size 0.03 0.003 0.03
                      }
                    }
                  ]
                }
                HingeJoint {
                  jointParameters HingeJointParameters {
                    position -1.4999998196243745
                    axis 1 0 -4e-06
                    anchor 0.0235 -0.112 -0.001674
                  }
                  device [
                    RotationalMotor {
                      name "left_elbow"
                      maxVelocity 6
                    }
                    PositionSensor {
                      name "left_elbow_sensor"
                    }
                  ]
                  endPoint Solid {
                    translation 0.0235 -0.112 -0.001674
                    rotation -0.5632364166594696 0.6045926092081685 -0.5632339796562874 2.0540167507566536
                    children [
                      Pose {
                        translation 0 -0.015 -0.0235
                        children [
                          Shape {
                            appearance USE mx64_material
                            geometry Box {
                              size 0.029 0.05 0.04
                            }
                          }
                        ]
                      }
                      Pose {
                        translation 0.018 -0.0985 -0.0235
                        rotation -1e-06 -1 1e-06 3.141593
                        children [
                          Shape {
                            appearance DEF radius_plate_material PBRAppearance {
                              baseColor 0.301961 0.301961 0.301961
                              roughness 1
                              metalness 0
                            }
                            geometry Box {
                              size 0.003 0.085 0.03
                            }
                          }
                        ]
                      }
                      Pose {
                        translation 0.0075 -0.141 -0.0235
                        rotation -1e-06 -1 1e-06 3.141593
                        children [
                          Shape {
                            appearance USE radius_plate_material
                            geometry Cylinder {
                              height 0.03
                              radius 0.012
                            }
                          }
                        ]
                      }
                    ]
                    name "left_radius_1"
                    boundingObject Group {
                      children [
                        Pose {
                          translation 0 -0.015 -0.0235
                          children [
                            Box {
                              size 0.029 0.05 0.04
                            }
                          ]
                        }
                        Pose {
                          translation 0.018 -0.0985 -0.0235
                          rotation -1e-06 -1 1e-06 3.141593
                          children [
                            Box {
                              size 0.003 0.085 0.03
                            }
                          ]
                        }
                        Pose {
                          translation 0.0075 -0.141 -0.0235
                          rotation -1e-06 -1 1e-06 3.141593
                          children [
                            Cylinder {
                              height 0.03
                              radius 0.012
                            }
                          ]
                        }
                      ]
                    }
                    physics Physics {
                      density -1
                      mass 0.20688
                      centerOfMass [
                        0.002534 -0.03704 -0.023878
                      ]
                      inertiaMatrix [
                        0.00037903 5.36268e-05 0.00036378
                        3.04226e-05 4.20803e-07 -4.7904e-07
                      ]
                    }
                    linearVelocity -1.421911768251488e-05 -2.0568392164247545e-05 -6.269127033301216e-06
                    angularVelocity 7.770602718746863e-05 -0.00010060746219872128 0.00018652786349192816
                  }
                }
              ]
              name "left_humerus_1"
              boundingObject Group {
                children [
                  Pose {
                    translation 0 -0.015 -0.0235
                    children [
                      Box {
                        size 0.029 0.05 0.04
                      }
                    ]
                  }
                  Pose {
                    translation 0 -0.092 -0.039174
                    rotation 0 -1 0 1.5708
                    children [
                      Box {
                        size 0.003 0.07 0.03
                      }
                    ]
                  }
                  Pose {
                    translation 0 -0.054 -0.023174
                    rotation 0 -1 0 1.5708
                    children [
                      Box {
                        size 0.03 0.003 0.03
                      }
                    ]
                  }
                ]
              }
              physics Physics {
                density -1
                mass 0.214223
                centerOfMass [
                  -0.000853 -0.03764 -0.024852
                ]
                inertiaMatrix [
                  0.000347701 6.51166e-05 0.000333302
                  -1.37313e-05 2.97277e-06 -8.64098e-06
                ]
              }
              linearVelocity -2.1569328064727246e-05 -2.9987760585000532e-05 -8.339152866491762e-06
              angularVelocity 7.77126220129377e-05 -0.00010060847745815062 0.00018652827108159778
            }
          }
        ]
        name "u_shoulder_1"
        boundingObject Pose {
          translation 0 0 0.003
          children [
            Box {
              size 0.047 0.0275 0.006
            }
          ]
        }
        physics Physics {
          density -1
          mass 0.042898
          centerOfMass [
            0 0.00486 0.016783
          ]
          inertiaMatrix [
            1.57991e-05 2.84983e-05 2.50037e-05
            1.59248e-20 -7.27391e-21 -3.76137e-06
          ]
        }
        linearVelocity -3.23724581469769e-05 -3.0615504845603626e-05 -4.1815067455019635e-06
        angularVelocity 7.771166481533519e-05 -0.0001006091359879434 0.00018652863424103826
      }
    }
    HingeJoint {
      jointParameters HingeJointParameters {
        position -1.3499996076418441
        axis 1 4e-06 4e-06
        anchor -0.074087 -0.032127 0.1609
      }
      device [
        RotationalMotor {
          name "right_shoulder_pitch"
          maxVelocity 6
        }
        PositionSensor {
          name "right_shoulder_pitch_sensor"
        }
      ]
      endPoint Solid {
        translation -0.07408686755585012 -0.03212411399578933 0.1608857381719593
        rotation 0.7071086440579263 -0.0008247962858622237 -0.7071044372719264 3.1399386353598
        children [
          Pose {
            translation 0 0 0.003
            children [
              Shape {
                appearance USE u_base_64_material
                geometry Box {
                  size 0.047 0.0275 0.01
                }
              }
            ]
          }
          HingeJoint {
            jointParameters HingeJointParameters {
              position -1.5499993887093795
              axis -1 -3e-06 4e-06
              anchor -0.0225 0.03 0.035
            }
            device [
              RotationalMotor {
                name "right_shoulder_roll"
                maxVelocity 6
              }
              PositionSensor {
                name "right_shoulder_roll_sensor"
              }
            ]
            endPoint Solid {
              translation -0.0225 0.03 0.035
              rotation 0.581309068982324 0.5693455925483751 -0.5813134804601071 4.1767425357693835
              children [
                Pose {
                  translation 0 -0.092 -0.04
                  rotation 0 -1 0 1.5708
                  children [
                    Shape {
                      appearance USE humerus_plate_material
                      geometry Box {
                        size 0.003 0.07 0.03
                      }
                    }
                  ]
                }
                Pose {
                  translation 0 -0.054 -0.024
                  rotation 0 -1 0 1.5708
                  children [
                    Shape {
                      appearance USE humerus_plate_material
                      geometry Box {
                        size 0.03 0.003 0.03
                      }
                    }
                  ]
                }
                Pose {
                  translation 0 -0.015 -0.0235
                  children [
                    Shape {
                      appearance USE mx64_material
                      geometry Box {
                        size 0.029 0.05 0.04
                      }
                    }
                  ]
                }
                HingeJoint {
                  jointParameters HingeJointParameters {
                    position -1.9909877018061024
                    axis 1 0 4e-06
                    anchor -0.0235 -0.112 -0.0025
                  }
                  device [
                    RotationalMotor {
                      name "right_elbow"
                      maxVelocity 6
                    }
                    PositionSensor {
                      name "right_elbow_sensor"
                    }
                  ]
                  endPoint Solid {
                    translation -0.0235 -0.112 -0.0025
                    rotation -0.6427564881287596 -0.4168114310211913 0.6427537070592829 2.3517663366793227
                    children [
                      Pose {
                        translation -0.018 -0.0985 -0.0235
                        children [
                          Shape {
                            appearance USE radius_plate_material
                            geometry Box {
                              size 0.003 0.085 0.03
                            }
                          }
                        ]
                      }
                      Pose {
                        translation -0.0075 -0.141 -0.0235
                        children [
                          Shape {
                            appearance USE radius_plate_material
                            geometry Cylinder {
                              height 0.03
                              radius 0.012
                            }
                          }
                        ]
                      }
                      Pose {
                        translation 0 -0.015 -0.0235
                        children [
                          Shape {
                            appearance USE mx64_material
                            geometry Box {
                              size 0.029 0.05 0.04
                            }
                          }
                        ]
                      }
                    ]
                    name "right_radius_1"
                    boundingObject Group {
                      children [
                        Pose {
                          translation -0.018 -0.0985 -0.0235
                          children [
                            Box {
                              size 0.003 0.085 0.03
                            }
                          ]
                        }
                        Pose {
                          translation -0.0075 -0.141 -0.0235
                          children [
                            Cylinder {
                              height 0.03
                              radius 0.012
                            }
                          ]
                        }
                        Pose {
                          translation 0 -0.015 -0.0235
                          children [
                            Box {
                              size 0.029 0.05 0.04
                            }
                          ]
                        }
                      ]
                    }
                    physics Physics {
                      density -1
                      mass 0.20688
                      centerOfMass [
                        -0.002335 -0.03704 -0.023635
                      ]
                      inertiaMatrix [
                        0.000379056 5.38522e-05 0.00036398
                        -3.24125e-05 7.54143e-07 -9.99715e-09
                      ]
                    }
                    linearVelocity -3.474524409152484e-05 2.007556166545411e-05 2.437653216259045e-05
                    angularVelocity 7.771762981150384e-05 -0.00010037832676162505 0.00017927211192499587
                  }
                }
              ]
              name "right_humerus_1"
              boundingObject Group {
                children [
                  Pose {
                    translation 0 -0.092 -0.04
                    rotation 0 -1 0 1.5708
                    children [
                      Box {
                        size 0.003 0.07 0.03
                      }
                    ]
                  }
                  Pose {
                    translation 0 -0.054 -0.024
                    rotation 0 -1 0 1.5708
                    children [
                      Box {
                        size 0.03 0.003 0.03
                      }
                    ]
                  }
                  Pose {
                    translation 0 -0.015 -0.0235
                    children [
                      Box {
                        size 0.029 0.05 0.04
                      }
                    ]
                  }
                ]
              }
              physics Physics {
                density -1
                mass 0.214223
                centerOfMass [
                  0.001044 -0.03764 -0.025366
                ]
                inertiaMatrix [
                  0.000347788 6.5125e-05 0.000333224
                  1.17167e-05 -1.66771e-06 -1.16648e-05
                ]
              }
              linearVelocity -3.116127415282652e-05 1.3684737754133812e-05 1.9295050420527058e-05
              angularVelocity 7.771794554979198e-05 -0.00010037781701040875 0.0001792721075242148
            }
          }
        ]
        name "u_shoulder_2"
        boundingObject Pose {
          translation 0 0 0.003
          children [
            Box {
              size 0.047 0.0275 0.006
            }
          ]
        }
        physics Physics {
          density -1
          mass 0.042898
          centerOfMass [
            0 0.00486 0.016783
          ]
          inertiaMatrix [
            1.57991e-05 2.84983e-05 2.50037e-05
            6.77626e-21 -1.35525e-20 -3.76137e-06
          ]
        }
        linearVelocity -2.819227195207236e-05 2.6389449758403224e-06 1.1990967110951823e-05
        angularVelocity 7.770733699868625e-05 -0.00010060789003941887 0.00018652994985647793
      }
    }
    HingeJoint {
      jointParameters HingeJointParameters {
        position 2.0764645310760514e-06
        axis 0 0 1
        anchor 0 -0.037127 0.1858
      }
      device [
        RotationalMotor {
          name "head_yaw"
          maxVelocity 6
        }
        PositionSensor {
          name "head_yaw_sensor"
        }
      ]
      endPoint Solid {
        translation 7.548030590108336e-08 -0.03712535525212562 0.18579187213107107
        rotation -1.7137864336139506e-09 -4.975562997108685e-08 -0.9999999999999989 3.1415899762478903
        children [
          Pose {
            translation 0 0 0.003
            children [
              Shape {
                appearance USE u_base_64_material
                geometry Box {
                  size 0.047 0.0275 0.006
                }
              }
            ]
          }
          Pose {
            translation -0.025 0 0.023
            rotation 0.5773496025226483 0.5773516025212714 0.5773496025226483 2.094399
            children [
              Shape {
                appearance USE u_side_small_material
                geometry Box {
                  size 0.025 0.044 0.003
                }
              }
            ]
          }
          Pose {
            translation 0.025 0 0.023
            rotation 0.5773496025226483 -0.5773516025212714 -0.5773496025226483 2.094399
            children [
              Shape {
                appearance USE u_side_small_material
                geometry Box {
                  size 0.025 0.044 0.003
                }
              }
            ]
          }
          HingeJoint {
            jointParameters HingeJointParameters {
              position 1.7967030291200175e-07
              axis -1 -4e-06 -4e-06
              anchor -0.0235 0 0.04
            }
            device [
              RotationalMotor {
                name "head_pitch"
                maxVelocity 6
              }
              PositionSensor {
                name "head_pitch_sensor"
              }
            ]
            endPoint Solid {
              translation -0.0235 0 0.04
              rotation -0.5773496371005103 -0.5773515333662561 0.577349637100035 2.0943991037325773
              children [
                Pose {
                  translation -0.0375 -0.0698 -0.005
                  rotation -1 0 0 3.14159
                  children [
                    Shape {
                      appearance DEF head_plate_material PBRAppearance {
                        baseColor 0.701961 0.682353 0.623529
                        roughness 1
                        metalness 0
                      }
                      geometry Box {
                        size 0.008 0.05 0.003
                      }
                    }
                  ]
                }
                Pose {
                  translation 0 -0.0698 -0.005
                  rotation -1 0 0 3.14159
                  children [
                    Shape {
                      appearance USE head_plate_material
                      geometry Box {
                        size 0.008 0.05 0.003
                      }
                    }
                  ]
                }
                Pose {
                  translation 0.0375 -0.0698 -0.005
                  rotation -1 0 0 3.14159
                  children [
                    Shape {
                      appearance USE head_plate_material
                      geometry Box {
                        size 0.008 0.05 0.003
                      }
                    }
                  ]
                }
                Pose {
                  translation 0 -0.0468 -0.005
                  rotation -1 0 0 3.14159
                  children [
                    Shape {
                      appearance USE head_plate_material
                      geometry Box {
                        size 0.083 0.008 0.003
                      }
                    }
                  ]
                }
                Pose {
                  translation 0 -0.0698 -0.005
                  rotation -1 0 0 3.14159
                  children [
                    Shape {
                      appearance USE head_plate_material
                      geometry Box {
                        size 0.083 0.008 0.003
                      }
                    }
                  ]
                }
                Pose {
                  translation 0 -0.0928 -0.005
                  rotation -1 0 0 3.14159
                  children [
                    Shape {
                      appearance USE head_plate_material
                      geometry Box {
                        size 0.083 0.008 0.003
                      }
                    }
                  ]
                }
                Pose {
                  translation 0.004968 -0.06905 -0.0235
                  rotation 0.5773496025226482 -0.5773496025226482 0.5773516025212713 2.094399
                  children [
                    Shape {
                      appearance DEF ptgrey_camera_material PBRAppearance {
                        baseColor 0.4 0.4 0.4
                        roughness 1
                        metalness 0
                      }
                      geometry Box {
                        size 0.03 0.03 0.028
                      }
                    }
                  ]
                }
                Pose {
                  translation -0.0375 -0.0698 -0.042
                  rotation -1 0 0 3.14159
                  children [
                    Shape {
                      appearance USE head_plate_material
                      geometry Box {
                        size 0.008 0.05 0.003
                      }
                    }
                  ]
                }
                Pose {
                  translation 0 -0.0698 -0.042
                  rotation -1 0 0 3.14159
                  children [
                    Shape {
                      appearance USE head_plate_material
                      geometry Box {
                        size 0.008 0.05 0.003
                      }
                    }
                  ]
                }
                Pose {
                  translation 0.0375 -0.0698 -0.042
                  rotation -1 0 0 3.14159
                  children [
                    Shape {
                      appearance USE head_plate_material
                      geometry Box {
                        size 0.008 0.05 0.003
                      }
                    }
                  ]
                }
                Pose {
                  translation 0 -0.0468 -0.042
                  rotation -1 0 0 3.14159
                  children [
                    Shape {
                      appearance USE head_plate_material
                      geometry Box {
                        size 0.083 0.008 0.003
                      }
                    }
                  ]
                }
                Pose {
                  translation 0 -0.0698 -0.042
                  rotation -1 0 0 3.14159
                  children [
                    Shape {
                      appearance USE head_plate_material
                      geometry Box {
                        size 0.083 0.008 0.003
                      }
                    }
                  ]
                }
                Pose {
                  translation 0 -0.0928 -0.042
                  rotation -1 0 0 3.14159
                  children [
                    Shape {
                      appearance USE head_plate_material
                      geometry Box {
                        size 0.083 0.008 0.003
                      }
                    }
                  ]
                }
                Pose {
                  translation 0 -0.015 -0.0235
                  children [
                    Shape {
                      appearance USE mx64_material
                      geometry Box {
                        size 0.029 0.05 0.04
                      }
                    }
                  ]
                }
              ]
              name "head_1"
              boundingObject Group {
                children [
                  Pose {
                    translation -0.0375 -0.0698 -0.005
                    rotation -1 0 0 3.14159
                    children [
                      Box {
                        size 0.008 0.05 0.003
                      }
                    ]
                  }
                  Pose {
                    translation 0 -0.0698 -0.005
                    rotation -1 0 0 3.14159
                    children [
                      Box {
                        size 0.008 0.05 0.003
                      }
                    ]
                  }
                  Pose {
                    translation 0.0375 -0.0698 -0.005
                    rotation -1 0 0 3.14159
                    children [
                      Box {
                        size 0.008 0.05 0.003
                      }
                    ]
                  }
                  Pose {
                    translation 0 -0.0468 -0.005
                    rotation -1 0 0 3.14159
                    children [
                      Box {
                        size 0.083 0.008 0.003
                      }
                    ]
                  }
                  Pose {
                    translation 0 -0.0698 -0.005
                    rotation -1 0 0 3.14159
                    children [
                      Box {
                        size 0.083 0.008 0.003
                      }
                    ]
                  }
                  Pose {
                    translation 0 -0.0928 -0.005
                    rotation -1 0 0 3.14159
                    children [
                      Box {
                        size 0.083 0.008 0.003
                      }
                    ]
                  }
                  Pose {
                    translation 0.004968 -0.06905 -0.0235
                    rotation 0.5773496025226482 -0.5773496025226482 0.5773516025212713 2.094399
                    children [
                      Box {
                        size 0.03 0.03 0.028
                      }
                    ]
                  }
                  Pose {
                    translation -0.0375 -0.0698 -0.042
                    rotation -1 0 0 3.14159
                    children [
                      Box {
                        size 0.008 0.05 0.003
                      }
                    ]
                  }
                  Pose {
                    translation 0 -0.0698 -0.042
                    rotation -1 0 0 3.14159
                    children [
                      Box {
                        size 0.008 0.05 0.003
                      }
                    ]
                  }
                  Pose {
                    translation 0.0375 -0.0698 -0.042
                    rotation -1 0 0 3.14159
                    children [
                      Box {
                        size 0.008 0.05 0.003
                      }
                    ]
                  }
                  Pose {
                    translation 0 -0.0468 -0.042
                    rotation -1 0 0 3.14159
                    children [
                      Box {
                        size 0.083 0.008 0.003
                      }
                    ]
                  }
                  Pose {
                    translation 0 -0.0698 -0.042
                    rotation -1 0 0 3.14159
                    children [
                      Box {
                        size 0.083 0.008 0.003
                      }
                    ]
                  }
                  Pose {
                    translation 0 -0.0928 -0.042
                    rotation -1 0 0 3.14159
                    children [
                      Box {
                        size 0.083 0.008 0.003
                      }
                    ]
                  }
                  Pose {
                    translation 0 -0.015 -0.0235
                    children [
                      Box {
                        size 0.029 0.05 0.04
                      }
                    ]
                  }
                ]
              }
              physics Physics {
                density -1
                mass 0.228227
                centerOfMass [
                  0.001274 -0.034352 -0.023721
                ]
                inertiaMatrix [
                  0.000236902 8.77015e-05 0.000235668
                  9.17476e-06 5.76668e-07 -3.39163e-07
                ]
              }
              linearVelocity -4.08512706557265e-05 -2.1683735555601283e-05 4.06771394525607e-06
              angularVelocity 7.603595998633229e-05 -0.0001003121941490355 0.00018653611086479603
            }
          }
        ]
        name "u_neck_1"
        boundingObject Group {
          children [
            Pose {
              translation 0 0 0.003
              children [
                Box {
                  size 0.047 0.0275 0.006
                }
              ]
            }
            Pose {
              translation -0.025 0 0.023
              rotation 0.5773496025226483 0.5773516025212714 0.5773496025226483 2.094399
              children [
                Box {
                  size 0.025 0.044 0.003
                }
              ]
            }
            Pose {
              translation 0.025 0 0.023
              rotation 0.5773496025226483 -0.5773516025212714 -0.5773496025226483 2.094399
              children [
                Box {
                  size 0.025 0.044 0.003
                }
              ]
            }
          ]
        }
        physics Physics {
          density -1
          mass 0.036209
          centerOfMass [
            0 0 0.012892
          ]
          inertiaMatrix [
            6.41955e-06 2.38199e-05 2.02973e-05
            4.27371e-12 3.64701e-13 4.49501e-20
          ]
        }
        linearVelocity -3.4788505206402117e-05 -1.7040344772545938e-05 4.120098317673127e-06
        angularVelocity 7.771067156249438e-05 -0.00010060950308652979 0.00018652904315068333
      }
    }
  ]
  name "Onshape"
  boundingObject Group {
    children [
      Pose {
        translation -0.031 -0.054127 0.0909
        children [
          Cylinder {
            height 0.086
            radius 0.004
          }
        ]
      }
      Pose {
        translation -0.046375 -0.026254 0.02
        rotation 1e-06 -1 -1e-06 3.141593
        children [
          Box {
            size 0.029 0.05 0.04
          }
        ]
      }
      Pose {
        translation 0.05 -0.017127 0.1609
        rotation -0.7071052811840065 -1.0000003976552372e-06 -0.7071082811851994 3.141591
        children [
          Box {
            size 0.029 0.05 0.04
          }
        ]
      }
      Pose {
        translation 0.046375 -0.026254 0.02
        rotation 1e-06 -1 -1e-06 3.141593
        children [
          Box {
            size 0.029 0.05 0.04
          }
        ]
      }
      Pose {
        translation 0 0.071323 0.1899
        rotation 0.5773496025226482 0.5773496025226482 -0.5773516025212713 2.094399
        children [
          Box {
            size 0.01 0.13 0.003
          }
        ]
      }
      Pose {
        translation -0.06 0.071323 0.1649
        rotation 0.5773496025226482 0.5773496025226482 -0.5773516025212713 2.094399
        children [
          Box {
            size 0.04 0.01 0.003
          }
        ]
      }
      Pose {
        translation 0.06 0.071323 0.1649
        rotation 0.5773496025226482 0.5773496025226482 -0.5773516025212713 2.094399
        children [
          Box {
            size 0.04 0.01 0.003
          }
        ]
      }
      Pose {
        translation 0.0625 0.037873 0.0909
        rotation -1 0 0 3.14159
        children [
          Cylinder {
            height 0.086
            radius 0.004
          }
        ]
      }
      Pose {
        translation -0.050587 -0.017127 0.1609
        rotation 0.7071052811840065 1.0000003976552372e-06 -0.7071082811851994 3.141591
        children [
          Box {
            size 0.029 0.05 0.04
          }
        ]
      }
      Pose {
        translation 0 -0.019127 0.1354
        rotation 1e-06 -1 -1e-06 3.141593
        children [
          Box {
            size 0.13 0.08 0.003
          }
        ]
      }
      Pose {
        translation 0 0.010373 0.0469
        children [
          Box {
            size 0.13 0.08 0.003
          }
        ]
      }
      Pose {
        translation -0.0625 0.037873 0.0909
        children [
          Cylinder {
            height 0.086
            radius 0.004
          }
        ]
      }
      Pose {
        translation 0 0.035873 0.10615
        rotation 1.0000003976552372e-06 -0.7071082811851994 -0.7071052811840065 3.141591
        children [
          Box {
            size 0.11 0.11 0.033
          }
        ]
      }
      Pose {
        translation 0 0.031123 0.0015
        children [
          Box {
            size 0.13 0.044 0.003
          }
        ]
      }
      Pose {
        translation -0.03 -0.007877 0.0015
        children [
          Box {
            size 0.01 0.035 0.003
          }
        ]
      }
      Pose {
        translation 0.03 -0.007877 0.0015
        children [
          Box {
            size 0.01 0.035 0.003
          }
        ]
      }
      Pose {
        translation 0 0.059373 0.1384
        rotation -0.7071052811840065 0.7071082811851994 -1.0000003976552372e-06 3.141591
        children [
          Box {
            size 0.01 0.135 0.003
          }
        ]
      }
      Pose {
        translation 0 -0.022127 0.1623
        rotation 0 0 -1 3.14159
        children [
          Box {
            size 0.029 0.05 0.04
          }
        ]
      }
      Pose {
        translation 0.031 -0.054127 0.0914
        children [
          Cylinder {
            height 0.086
            radius 0.004
          }
        ]
      }
    ]
  }
  physics Physics {
  }
  linearVelocity -1.665910536331922e-05 -1.0977676903321742e-05 -1.0853854311107318e-07
  angularVelocity 7.771117055048205e-05 -0.00010060928742015845 0.00018652905987361909
}
